Workbook

Sheet 抖音订单-按支付日期-原表
A1: 主订单编号 | B1: 子订单编号 | C1: 选购商品 | D1: 商品规格 | E1: 商品数量 | F1: 商品ID | G1: 商家编码 | H1: 商品单价 | I1: 订单应付金额 | J1: 运费 | K1: 优惠总金额 | L1: 平台优惠 | M1: 商家优惠 | N1: 达人优惠 | O1: 商家改价 | P1: 支付优惠 | Q1: 红包抵扣 | R1: 支付方式 | S1: 手续费 | T1: 收件人 | U1: 收件人手机号 | V1: 省 | W1: 市 | X1: 区 | Y1: 街道 | Z1: 详细地址 | AA1: 是否修改过地址 | AB1: 买家留言 | AC1: 订单提交时间 | AD1: 旗帜颜色 | AE1: 商家备注 | AF1: 订单完成时间 | AG1: 支付完成时间 | AH1: APP渠道 | AI1: 流量来源 | AJ1: 订单状态 | AK1: 承诺发货时间 | AL1: 订单类型 | AM1: 鲁班落地页ID | AN1: 达人ID | AO1: 达人昵称 | AP1: 所属门店ID | AQ1: 售后状态 | AR1: 取消原因 | AS1: 预约发货时间 | AT1: 仓库ID | AU1: 仓库名称 | AV1: 序列号 | AW1: 是否安心购 | AX1: 广告渠道 | AY1: 流量类型 | AZ1: 流量体裁 | BA1: 流量渠道 | BB1: 发货主体 | BC1: 发货主体明细 | BD1: 发货时间 | BE1: 降价类优惠 | BF1: 平台实际承担优惠金额 | BG1: 商家实际承担优惠金额 | BH1: 达人实际承担优惠金额 | BI1: 预计送达时间 | BJ1: 是否平台仓自流转 | BK1: 车型 | BL1: 商品69码 | BM1: 发货SN码 | BN1: 发货IMEI码1 | BO1: 发货IMEI码2 | BP1: 预约送达时间 | BQ1: 建议发货时间（起） | BR1: 建议发货时间（止） | BS1: 物流SN码 | BT1: 物流IMEI码1 | BU1: 物流IMEI码2
A2: 6921014879971867995 | B2: 6921014879971867995 | C2: 【老板周】复古风格 秋冬新款立体麻花织纹针织毛衣 | D2: 灰色;L(120-135斤);15天内发货 | E2: 1 | F2: 3772185880568135686 | G2: Z2418-灰色-L | H2: 329 | I2: 329 | J2: 0 | K2: 0 | L2: - | M2: - | N2: - | O2: 0 | P2: 0 | Q2: 0 | R2: 抖音月付 | S2: 0 | T2: *** | U2: *** | V2: 安徽省 | W2: 宿州市 | X2: 埇桥区 | Y2: 西关街道 | Z2: *** | AA2: 否 | AC2: 2025-08-31 22:51:27 | AD2: 灰色 | AE2: (收)[Z2418-灰色-L]*[1]# | AF2: 2025-09-22 10:48:28 | AG2: 2025-08-31 22:51:31 | AH2: 抖音 | AI2: 精选联盟 | AJ2: 已完成 | AK2: 2025-09-15 22:51:31 | AL2: 普通订单 | AM2: 0 | AN2: 2353393836764088 | AO2: 老板周 | AP2: - | AQ2: 退款成功 | AS2: - | AT2: - | AU2: - | AW2: 否 | AX2: 无 | AY2: 其他 | AZ2: 直播 | BA2: 商城推荐 | BB2: - | BC2: - | BD2: 2025-09-15 10:48:28 | BE2: 0 | BF2: 0 | BG2: 0 | BH2: 0 | BJ2: 否 | BP2: - | BQ2: - | BR2: -
A3: 6945703385201317436 | B3: 6945703385201317436 | C3: 【老板周】日系极简 春季新品圆领简约设计感无袖马甲 | D3: 黑色;M(100-120斤);15天内发货 | E3: 1 | F3: 3767004410471907465 | G3: Z1640-黑色-M | H3: 289 | I3: 289 | J3: 0 | K3: 0 | L3: - | M3: - | N3: - | O3: 0 | P3: 0 | Q3: 0 | R3: 支付宝 | S3: 0 | T3: *** | U3: *** | V3: 广东省 | W3: 深圳市 | X3: 龙华区 | Y3: 龙华街道 | Z3: *** | AA3: 否 | AC3: 2025-08-31 22:28:56 | AD3: 灰色 | AF3: 2025-09-18 23:58:12 | AG3: 2025-08-31 22:29:01 | AH3: 抖音 | AI3: 精选联盟 | AJ3: 已完成 | AK3: 2025-09-15 22:29:02 | AL3: 普通订单 | AM3: 0 | AN3: 2353393836764088 | AO3: 老板周 | AP3: - | AQ3: - | AS3: - | AT3: - | AU3: - | AW3: 否 | AX3: 无 | AY3: 其他 | AZ3: 直播 | BA3: 关注来源 | BB3: - | BC3: - | BD3: 2025-09-11 23:58:12 | BE3: 0 | BF3: 0 | BG3: 0 | BH3: 0 | BJ3: 否 | BP3: - | BQ3: - | BR3: -
A4: 6945727588250948678 | B4: 6945727588250948678 | C4: 【老板周】日系极简 春季新品圆领简约设计感无袖马甲 | D4: 黑色;L(120-135斤);15天内发货 | E4: 1 | F4: 3767004410471907465 | G4: Z1640-黑色-L | H4: 289 | I4: 289 | J4: 0 | K4: 0 | L4: - | M4: - | N4: - | O4: 0 | P4: 0 | Q4: 0 | R4: 抖音支付 | S4: 0 | T4: *** | U4: *** | V4: 山东省 | W4: 德州市 | X4: 德城区 | Y4: - | Z4: *** | AA4: 否 | AC4: 2025-08-31 22:26:00 | AD4: 灰色 | AG4: 2025-08-31 22:26:05 | AH4: 抖音 | AI4: 精选联盟 | AJ4: 已关闭 | AK4: 2025-09-15 22:26:05 | AL4: 普通订单 | AM4: 0 | AN4: 2353393836764088 | AO4: 老板周 | AP4: - | AQ4: 退款成功 | AS4: - | AT4: - | AU4: - | AW4: 否 | AX4: 无 | AY4: 其他 | AZ4: 直播 | BA4: 直播推荐 | BB4: - | BC4: - | BE4: 0 | BF4: 0 | BG4: 0 | BH4: 0 | BJ4: 否 | BP4: - | BQ4: - | BR4: -
A5: 6945714505452361238 | B5: 6945714505452361238 | C5: 【老板周】日系极简 春季新品圆领简约设计感无袖马甲 | D5: 黑色;S(80-100斤);15天内发货 | E5: 1 | F5: 3767004410471907465 | G5: Z1640-黑色-S | H5: 289 | I5: 286 | J5: 0 | K5: 4 | L5: 平台晚发即赔券-3.00 | M5: - | N5: - | O5: 0 | P5: 1 | Q5: 0 | R5: 抖音支付 | S5: 0 | T5: *** | U5: *** | V5: 河南省 | W5: 平顶山市 | X5: 湛河区 | Y5: 九里山街道 | Z5: *** | AA5: 否 | AC5: 2025-08-31 22:01:43 | AD5: 灰色 | AG5: 2025-08-31 22:01:46 | AH5: 抖音 | AI5: 精选联盟 | AJ5: 已关闭 | AK5: 2025-09-15 22:01:47 | AL5: 普通订单 | AM5: 0 | AN5: 2353393836764088 | AO5: 老板周 | AP5: - | AQ5: 退款成功 | AS5: - | AT5: - | AU5: - | AW5: 否 | AX5: 无 | AY5: 其他 | AZ5: 商品卡 | BA5: 橱窗 | BB5: - | BC5: - | BE5: 0 | BF5: 3 | BG5: 0 | BH5: 0 | BJ5: 否 | BP5: - | BQ5: - | BR5: -
A6: 6945700999501124814 | B6: 6945700999501124814 | C6: 【老板周】极简设计 秋冬毛绒感圆领套头舒适针织毛衣 | D6: 红色;M(100-135斤);15天内发货 | E6: 1 | F6: 3772189127454359773 | G6: Z2425-红色-M | H6: 289 | I6: 289 | J6: 0 | K6: 0 | L6: - | M6: - | N6: - | O6: 0 | P6: 0 | Q6: 0 | R6: 抖音支付 | S6: 0 | T6: *** | U6: *** | V6: 湖南省 | W6: 常德市 | X6: 武陵区 | Y6: 穿紫河街道 | Z6: *** | AA6: 否 | AC6: 2025-08-31 20:25:26 | AD6: 灰色 | AG6: 2025-08-31 20:25:28 | AH6: 抖音 | AI6: 精选联盟 | AJ6: 已关闭 | AK6: 2025-09-15 20:25:28 | AL6: 普通订单 | AM6: 0 | AN6: 2353393836764088 | AO6: 老板周 | AP6: - | AQ6: 退款成功 | AS6: - | AT6: - | AU6: - | AW6: 否 | AX6: 直播 | AY6: 广告 | AZ6: 直播 | BA6: 商城推荐 | BB6: - | BC6: - | BE6: 0 | BF6: 0 | BG6: 0 | BH6: 0 | BJ6: 否 | BP6: - | BQ6: - | BR6: -
A7: 6921014170429783498 | B7: 6921014170429783498 | C7: 【老板周】日系极简 春季新品圆领简约设计感无袖马甲 | D7: 黑色;M(100-120斤);15天内发货 | E7: 1 | F7: 3767004410471907465 | G7: Z1640-黑色-M | H7: 289 | I7: 289 | J7: 0 | K7: 0 | L7: - | M7: - | N7: - | O7: 0 | P7: 0 | Q7: 0 | R7: 支付宝 | S7: 0 | T7: *** | U7: *** | V7: 上海市 | W7: 上海市 | X7: 浦东新区 | Y7: - | Z7: *** | AA7: 否 | AC7: 2025-08-31 19:29:31 | AD7: 灰色 | AF7: 2025-09-18 23:58:12 | AG7: 2025-08-31 19:29:36 | AH7: 抖音 | AI7: 精选联盟 | AJ7: 已完成 | AK7: 2025-09-15 19:29:36 | AL7: 普通订单 | AM7: 0 | AN7: 2353393836764088 | AO7: 老板周 | AP7: - | AQ7: - | AS7: - | AT7: - | AU7: - | AW7: 否 | AX7: 无 | AY7: 其他 | AZ7: 直播 | BA7: 直播推荐 | BB7: - | BC7: - | BD7: 2025-09-11 23:58:12 | BE7: 0 | BF7: 0 | BG7: 0 | BH7: 0 | BJ7: 否 | BP7: - | BQ7: - | BR7: -
A8: 6945712098356630732 | B8: 6945712098356630732 | C8: 【老板周】日系极简 春季新品圆领简约设计感无袖马甲 | D8: 黑色;M(100-120斤);15天内发货 | E8: 1 | F8: 3767004410471907465 | G8: Z1640-黑色-M | H8: 289 | I8: 289 | J8: 0 | K8: 0 | L8: - | M8: - | N8: - | O8: 0 | P8: 0 | Q8: 0 | R8: 抖音月付 | S8: 0 | T8: *** | U8: *** | V8: 山西省 | W8: 太原市 | X8: 晋源区 | Y8: 义井街道 | Z8: *** | AA8: 否 | AC8: 2025-08-31 19:13:06 | AD8: 灰色 | AF8: 2025-09-18 23:58:12 | AG8: 2025-08-31 19:13:08 | AH8: 抖音 | AI8: 精选联盟 | AJ8: 已完成 | AK8: 2025-09-15 19:13:08 | AL8: 普通订单 | AM8: 0 | AN8: 2353393836764088 | AO8: 老板周 | AP8: - | AQ8: 退款成功 | AS8: - | AT8: - | AU8: - | AW8: 否 | AX8: 无 | AY8: 其他 | AZ8: 直播 | BA8: 直播推荐 | BB8: - | BC8: - | BD8: 2025-09-11 23:58:12 | BE8: 0 | BF8: 0 | BG8: 0 | BH8: 0 | BJ8: 否 | BP8: - | BQ8: - | BR8: -
A9: 6921016389061410674 | B9: 6921016389061410674 | C9: 【老板周】极简设计 秋冬毛绒感圆领套头舒适针织毛衣 | D9: 红色;S(80-100斤);15天内发货 | E9: 1 | F9: 3772189127454359773 | G9: Z2425-红色-S | H9: 289 | I9: 284 | J9: 0 | K9: 5 | L9: 平台晚发即赔券-5.00 | M9: - | N9: - | O9: 0 | P9: 0 | Q9: 0 | R9: 抖音月付 | S9: 0 | T9: *** | U9: *** | V9: 重庆市 | W9: 重庆市 | X9: 九龙坡区 | Y9: 中梁山街道 | Z9: *** | AA9: 否 | AC9: 2025-08-31 18:07:41 | AD9: 灰色 | AG9: 2025-08-31 18:07:42 | AH9: 头条lite-抖音电商 | AI9: 精选联盟 | AJ9: 已关闭 | AK9: 2025-09-15 18:07:43 | AL9: 普通订单 | AM9: 0 | AN9: 2353393836764088 | AO9: 老板周 | AP9: - | AQ9: 退款成功 | AS9: - | AT9: - | AU9: - | AW9: 否 | AX9: 直播 | AY9: 广告 | AZ9: 直播 | BA9: 头条西瓜 | BB9: - | BC9: - | BE9: 0 | BF9: 5 | BG9: 0 | BH9: 0 | BJ9: 否 | BP9: - | BQ9: - | BR9: -
A10: 6945711936320509468 | B10: 6945711936320509468 | C10: 【老板周】极简设计 秋冬毛绒感圆领套头舒适针织毛衣 | D10: 蓝色;S(80-100斤);15天内发货 | E10: 1 | F10: 3772189127454359773 | G10: Z2425-蓝色-S | H10: 289 | I10: 289 | J10: 0 | K10: 0 | L10: - | M10: - | N10: - | O10: 0 | P10: 0 | Q10: 0 | R10: 抖音支付 | S10: 0 | T10: *** | U10: *** | V10: 贵州省 | W10: 贵阳市 | X10: 乌当区 | Y10: 新创路街道 | Z10: *** | AA10: 否 | AC10: 2025-08-31 18:05:55 | AD10: 灰色 | AH10: 抖音 | AI10: 精选联盟 | AJ10: 已关闭 | AK10: 2025-09-15 18:05:55 | AL10: 普通订单 | AM10: 0 | AN10: 2353393836764088 | AO10: 老板周 | AP10: - | AQ10: - | AR10: 你已取消订单：暂时不需要这个商品 | AS10: - | AT10: - | AU10: - | AW10: 否 | AX10: 无 | AY10: 其他 | AZ10: 直播 | BA10: 直播推荐 | BB10: - | BC10: - | BE10: 0 | BF10: 0 | BG10: 0 | BH10: 0 | BJ10: 否 | BP10: - | BQ10: - | BR10: -
A11: 6921016313814548201 | B11: 6921016313814548201 | C11: 【老板周】极简设计 秋冬毛绒感圆领套头舒适针织毛衣 | D11: 红色;M(100-135斤);15天内发货 | E11: 1 | F11: 3772189127454359773 | G11: Z2425-红色-M | H11: 289 | I11: 267 | J11: 0 | K11: 22 | L11: 平台全额返现满减券-22.00 | M11: - | N11: - | O11: 0 | P11: 0 | Q11: 0 | R11: 抖音月付 | S11: 0 | T11: *** | U11: *** | V11: 广东省 | W11: 阳江市 | X11: 江城区 | Y11: 城北街道 | Z11: *** | AA11: 否 | AC11: 2025-08-31 18:05:31 | AD11: 蓝色 | AE11: YT2532916536267(收） Z2425-红色-M*1# | AG11: 2025-08-31 18:05:36 | AH11: 抖音 | AI11: 精选联盟 | AJ11: 已关闭 | AK11: 2025-09-15 18:05:36 | AL11: 普通订单 | AM11: 0 | AN11: 2353393836764088 | AO11: 老板周 | AP11: - | AQ11: 退款成功 | AS11: - | AT11: - | AU11: - | AW11: 否 | AX11: 无 | AY11: 其他 | AZ11: 直播 | BA11: 商城推荐 | BB11: - | BC11: - | BD11: 2025-09-09 23:55:16 | BE11: 0 | BF11: 22 | BG11: 0 | BH11: 0 | BJ11: 否 | BP11: - | BQ11: - | BR11: -
A12: 6945707477692061056 | B12: 6945707477692061056 | C12: 【老板周】简约松弛 秋冬纯色弧形下摆宽松百搭上衣 | D12: 白色;S(80-100斤);15天内发货 | E12: 1 | F12: 3771440658552848740 | G12: Z2311-白色-S | H12: 229 | I12: 229 | J12: 0 | K12: 0 | L12: - | M12: - | N12: - | O12: 0 | P12: 0 | Q12: 0 | R12: 抖音支付 | S12: 0 | T12: *** | U12: *** | V12: 湖南省 | W12: 常德市 | X12: 武陵区 | Y12: 府坪街道 | Z12: *** | AA12: 否 | AC12: 2025-08-31 18:01:07 | AD12: 蓝色 | AE12: 73571847180415(收） Z2311-白色-S*1# | AG12: 2025-08-31 18:01:08 | AH12: 抖音 | AI12: 小店自卖 | AJ12: 已关闭 | AK12: 2025-09-15 18:01:09 | AL12: 普通订单 | AM12: 0 | AN12: 0 | AP12: - | AQ12: 退款成功 | AS12: - | AT12: - | AU12: - | AW12: 否 | AX12: 无 | AY12: 其他 | AZ12: 商品卡 | BA12: 搜索 | BB12: - | BC12: - | BD12: 2025-09-07 16:39:45 | BE12: 0 | BF12: 0 | BG12: 0 | BH12: 0 | BJ12: 否 | BP12: - | BQ12: - | BR12: -
A13: 6945694166426850837 | B13: 6945694166426850837 | C13: 【老板周】复古风格 秋冬新款立体麻花织纹针织毛衣 | D13: 灰色;L(120-135斤);15天内发货 | E13: 1 | F13: 3772185880568135686 | G13: Z2418-灰色-L | H13: 329 | I13: 329 | J13: 0 | K13: 0 | L13: - | M13: - | N13: - | O13: 0 | P13: 0 | Q13: 0 | R13: 支付宝 | S13: 0 | T13: *** | U13: *** | V13: 辽宁省 | W13: 本溪市 | X13: 明山区 | Y13: 北地街道 | Z13: *** | AA13: 否 | AC13: 2025-08-31 17:51:10 | AD13: 灰色 | AG13: 2025-08-31 17:51:20 | AH13: 抖音极速版 | AI13: 精选联盟 | AJ13: 已关闭 | AK13: 2025-09-15 17:51:20 | AL13: 普通订单 | AM13: 0 | AN13: 2353393836764088 | AO13: 老板周 | AP13: - | AQ13: 退款成功 | AS13: - | AT13: - | AU13: - | AW13: 否 | AX13: 无 | AY13: 其他 | AZ13: 直播 | BA13: 商城推荐 | BB13: - | BC13: - | BE13: 0 | BF13: 0 | BG13: 0 | BH13: 0 | BJ13: 否 | BP13: - | BQ13: - | BR13: -
A14: 6945716113981314698 | B14: 6945716113981314698 | C14: 【老板周】复古风格 秋冬新款立体麻花织纹针织毛衣 | D14: 灰色;S(80-100斤);15天内发货 | E14: 1 | F14: 3772185880568135686 | G14: Z2418-灰色-S | H14: 329 | I14: 329 | J14: 0 | K14: 0 | L14: - | M14: - | N14: - | O14: 0 | P14: 0 | Q14: 0 | R14: 抖音月付 | S14: 0 | T14: *** | U14: *** | V14: 山西省 | W14: 吕梁市 | X14: 交城县 | Y14: 天宁镇 | Z14: *** | AA14: 否 | AC14: 2025-08-31 17:50:43 | AD14: 灰色 | AG14: 2025-08-31 17:50:44 | AH14: 抖音 | AI14: 精选联盟 | AJ14: 已关闭 | AK14: 2025-09-15 17:50:44 | AL14: 普通订单 | AM14: 0 | AN14: 2353393836764088 | AO14: 老板周 | AP14: - | AQ14: 退款成功 | AS14: - | AT14: - | AU14: - | AW14: 否 | AX14: 无 | AY14: 其他 | AZ14: 直播 | BA14: 直播推荐 | BB14: - | BC14: - | BE14: 0 | BF14: 0 | BG14: 0 | BH14: 0 | BJ14: 否 | BP14: - | BQ14: - | BR14: -
A15: 6921011676079357340 | B15: 6921011676079357340 | C15: 【老板周】复古风格 秋冬新款立体麻花织纹针织毛衣 | D15: 灰色;S(80-100斤);15天内发货 | E15: 1 | F15: 3772185880568135686 | G15: Z2418-灰色-S | H15: 329 | I15: 329 | J15: 0 | K15: 0 | L15: - | M15: - | N15: - | O15: 0 | P15: 0 | Q15: 0 | R15: 抖音月付 | S15: 0 | T15: *** | U15: *** | V15: 河北省 | W15: 沧州市 | X15: 黄骅市 | Y15: - | Z15: *** | AA15: 否 | AC15: 2025-08-31 17:46:12 | AD15: 灰色 | AG15: 2025-08-31 17:46:16 | AH15: 抖音 | AI15: 精选联盟 | AJ15: 已关闭 | AK15: 2025-09-15 17:46:16 | AL15: 普通订单 | AM15: 0 | AN15: 2353393836764088 | AO15: 老板周 | AP15: - | AQ15: 退款成功 | AS15: - | AT15: - | AU15: - | AW15: 否 | AX15: 无 | AY15: 其他 | AZ15: 直播 | BA15: 个人主页&店铺&橱窗进入直播间 | BB15: - | BC15: - | BE15: 0 | BF15: 0 | BG15: 0 | BH15: 0 | BJ15: 否 | BP15: - | BQ15: - | BR15: -
A16: 6945711886863766847 | B16: 6945711886863766847 | C16: 【老板周】复古风格 秋冬新款立体麻花织纹针织毛衣 | D16: 灰色;M(100-120斤);15天内发货 | E16: 1 | F16: 3772185880568135686 | G16: Z2418-灰色-M | H16: 329 | I16: 329 | J16: 0 | K16: 0 | L16: - | M16: - | N16: - | O16: 0 | P16: 0 | Q16: 0 | R16: 支付宝 | S16: 0 | T16: *** | U16: *** | V16: 湖南省 | W16: 张家界市 | X16: 永定区 | Y16: 崇文街道 | Z16: *** | AA16: 否 | AC16: 2025-08-31 17:39:51 | AD16: 灰色 | AG16: 2025-08-31 17:39:57 | AH16: 红果短剧-抖音电商 | AI16: 精选联盟 | AJ16: 已关闭 | AK16: 2025-09-15 17:39:58 | AL16: 普通订单 | AM16: 0 | AN16: 2353393836764088 | AO16: 老板周 | AP16: - | AQ16: 退款成功 | AS16: - | AT16: - | AU16: - | AW16: 否 | AX16: 直播 | AY16: 广告 | AZ16: 直播 | BA16: 其他 | BB16: - | BC16: - | BE16: 0 | BF16: 0 | BG16: 0 | BH16: 0 | BJ16: 否 | BP16: - | BQ16: - | BR16: -
A17: 6921009635296968526 | B17: 6921009635296968526 | C17: 【老板周】复古风格 秋冬新款立体麻花织纹针织毛衣 | D17: 灰色;M(100-120斤);15天内发货 | E17: 1 | F17: 3772185880568135686 | G17: Z2418-灰色-M | H17: 329 | I17: 329 | J17: 0 | K17: 0 | L17: - | M17: - | N17: - | O17: 0 | P17: 0 | Q17: 0 | R17: 抖音支付 | S17: 0 | T17: *** | U17: *** | V17: 天津市 | W17: 天津市 | X17: 滨海新区 | Y17: - | Z17: *** | AA17: 否 | AC17: 2025-08-31 17:39:47 | AD17: 灰色 | AG17: 2025-08-31 17:39:48 | AH17: 抖音 | AI17: 精选联盟 | AJ17: 已关闭 | AK17: 2025-09-15 17:39:48 | AL17: 普通订单 | AM17: 0 | AN17: 2353393836764088 | AO17: 老板周 | AP17: - | AQ17: 退款成功 | AS17: - | AT17: - | AU17: - | AW17: 否 | AX17: 无 | AY17: 其他 | AZ17: 直播 | BA17: 个人主页&店铺&橱窗进入直播间 | BB17: - | BC17: - | BE17: 0 | BF17: 0 | BG17: 0 | BH17: 0 | BJ17: 否 | BP17: - | BQ17: - | BR17: -
A18: 6921016365371785140 | B18: 6921016365371785140 | C18: 【老板周】复古风格 秋冬新款立体麻花织纹针织毛衣 | D18: 灰色;M(100-120斤);15天内发货 | E18: 1 | F18: 3772185880568135686 | G18: Z2418-灰色-M | H18: 329 | I18: 329 | J18: 0 | K18: 0 | L18: - | M18: - | N18: - | O18: 0 | P18: 0 | Q18: 0 | R18: 支付宝 | S18: 0 | T18: *** | U18: *** | V18: 河北省 | W18: 石家庄市 | X18: 赵县 | Y18: 赵州镇 | Z18: *** | AA18: 否 | AC18: 2025-08-31 17:39:46 | AD18: 蓝色 | AE18: JT5414067073138(收） Z2418-灰色-M*1# | AG18: 2025-08-31 17:39:54 | AH18: 抖音 | AI18: 精选联盟 | AJ18: 已关闭 | AK18: 2025-09-15 17:39:54 | AL18: 普通订单 | AM18: 0 | AN18: 2353393836764088 | AO18: 老板周 | AP18: - | AQ18: 退款成功 | AS18: - | AT18: - | AU18: - | AW18: 否 | AX18: 无 | AY18: 其他 | AZ18: 直播 | BA18: 直播推荐 | BB18: - | BC18: - | BD18: 2025-09-15 10:48:28 | BE18: 0 | BF18: 0 | BG18: 0 | BH18: 0 | BJ18: 否 | BP18: - | BQ18: - | BR18: -
A19: 6921009588551319487 | B19: 6921009588551319487 | C19: 【老板周】复古风格 秋冬新款立体麻花织纹针织毛衣 | D19: 灰色;S(80-100斤);15天内发货 | E19: 1 | F19: 3772185880568135686 | G19: Z2418-灰色-S | H19: 329 | I19: 329 | J19: 0 | K19: 0 | L19: - | M19: - | N19: - | O19: 0 | P19: 0 | Q19: 0 | R19: 抖音支付 | S19: 0 | T19: *** | U19: *** | V19: 江苏省 | W19: 苏州市 | X19: 虎丘区 | Y19: 东渚街道 | Z19: *** | AA19: 否 | AC19: 2025-08-31 17:39:43 | AD19: 灰色 | AG19: 2025-08-31 17:39:46 | AH19: 抖音 | AI19: 精选联盟 | AJ19: 已关闭 | AK19: 2025-09-15 17:39:46 | AL19: 普通订单 | AM19: 0 | AN19: 2353393836764088 | AO19: 老板周 | AP19: - | AQ19: 退款成功 | AS19: - | AT19: - | AU19: - | AW19: 否 | AX19: 无 | AY19: 其他 | AZ19: 直播 | BA19: 关注来源 | BB19: - | BC19: - | BE19: 0 | BF19: 0 | BG19: 0 | BH19: 0 | BJ19: 否 | BP19: - | BQ19: - | BR19: -
A20: 6921018615091854571 | B20: 6921018615091854571 | C20: 【老板周】复古风格 秋冬新款立体麻花织纹针织毛衣 | D20: 灰色;L(120-135斤);15天内发货 | E20: 1 | F20: 3772185880568135686 | G20: Z2418-灰色-L | H20: 329 | I20: 329 | J20: 0 | K20: 0 | L20: - | M20: - | N20: - | O20: 0 | P20: 0 | Q20: 0 | R20: 抖音支付 | S20: 0 | T20: *** | U20: *** | V20: 河北省 | W20: 邢台市 | X20: 信都区 | Y20: 泉西街道 | Z20: *** | AA20: 否 | AC20: 2025-08-31 17:33:32 | AD20: 灰色 | AG20: 2025-08-31 17:33:35 | AH20: 抖音 | AI20: 精选联盟 | AJ20: 已关闭 | AK20: 2025-09-15 17:33:35 | AL20: 普通订单 | AM20: 0 | AN20: 2353393836764088 | AO20: 老板周 | AP20: - | AQ20: 退款成功 | AS20: - | AT20: - | AU20: - | AW20: 否 | AX20: 无 | AY20: 其他 | AZ20: 直播 | BA20: 直播推荐 | BB20: - | BC20: - | BE20: 0 | BF20: 0 | BG20: 0 | BH20: 0 | BJ20: 否 | BP20: - | BQ20: - | BR20: -
A21: 6945702914926777790 | B21: 6945702914926777790 | C21: 【老板周】复古风格 秋冬新款立体麻花织纹针织毛衣 | D21: 灰色;M(100-120斤);15天内发货 | E21: 1 | F21: 3772185880568135686 | G21: Z2418-灰色-M | H21: 329 | I21: 329 | J21: 0 | K21: 0 | L21: - | M21: - | N21: - | O21: 0 | P21: 0 | Q21: 0 | R21: 抖音支付 | S21: 0 | T21: *** | U21: *** | V21: 山西省 | W21: 大同市 | X21: 云冈区 | Y21: 新平旺街道 | Z21: *** | AA21: 否 | AC21: 2025-08-31 17:33:15 | AD21: 灰色 | AF21: 2025-09-21 10:50:13 | AG21: 2025-08-31 17:33:16 | AH21: 抖音极速版 | AI21: 精选联盟 | AJ21: 已完成 | AK21: 2025-09-15 17:33:17 | AL21: 普通订单 | AM21: 0 | AN21: 2353393836764088 | AO21: 老板周 | AP21: - | AQ21: - | AS21: - | AT21: - | AU21: - | AW21: 否 | AX21: 直播 | AY21: 广告 | AZ21: 直播 | BA21: 直播推荐 | BB21: - | BC21: - | BD21: 2025-09-15 10:48:28 | BE21: 0 | BF21: 0 | BG21: 0 | BH21: 0 | BJ21: 否 | BP21: - | BQ21: - | BR21: -
A22: 6945716202524317053 | B22: 6945716202524317053 | C22: 【老板周】复古风格 秋冬新款立体麻花织纹针织毛衣 | D22: 灰色;M(100-120斤);15天内发货 | E22: 1 | F22: 3772185880568135686 | G22: Z2418-灰色-M | H22: 329 | I22: 329 | J22: 0 | K22: 0 | L22: - | M22: - | N22: - | O22: 0 | P22: 0 | Q22: 0 | R22: 抖音月付 | S22: 0 | T22: *** | U22: *** | V22: 重庆市 | W22: 重庆市 | X22: 梁平区 | Y22: 双桂街道 | Z22: *** | AA22: 否 | AC22: 2025-08-31 17:32:47 | AD22: 蓝色 | AE22: SF3282428122123(收） Z2418-灰色-M*1# | AG22: 2025-08-31 17:32:49 | AH22: 抖音商城版 | AI22: 精选联盟 | AJ22: 已关闭 | AK22: 2025-09-15 17:32:50 | AL22: 普通订单 | AM22: 0 | AN22: 2353393836764088 | AO22: 老板周 | AP22: - | AQ22: 退款成功 | AS22: - | AT22: - | AU22: - | AW22: 否 | AX22: 无 | AY22: 其他 | AZ22: 直播 | BA22: 商城推荐 | BB22: - | BC22: - | BD22: 2025-09-14 23:53:25 | BE22: 0 | BF22: 0 | BG22: 0 | BH22: 0 | BJ22: 否 | BP22: - | BQ22: - | BR22: -
A23: 6921018667371494935 | B23: 6921018667371494935 | C23: 【老板周】复古风格 秋冬新款立体麻花织纹针织毛衣 | D23: 灰色;S(80-100斤);15天内发货 | E23: 1 | F23: 3772185880568135686 | G23: Z2418-灰色-S | H23: 329 | I23: 329 | J23: 0 | K23: 0 | L23: - | M23: - | N23: - | O23: 0 | P23: 0 | Q23: 0 | R23: 支付宝 | S23: 0 | T23: *** | U23: *** | V23: 浙江省 | W23: 丽水市 | X23: 莲都区 | Y23: 岩泉街道 | Z23: *** | AA23: 否 | AC23: 2025-08-31 17:32:37 | AD23: 蓝色 | AE23: 拦截;76740677006606(收） Z2418-灰色-S*1# | AG23: 2025-08-31 17:32:50 | AH23: 抖音 | AI23: 精选联盟 | AJ23: 已关闭 | AK23: 2025-09-15 17:32:50 | AL23: 普通订单 | AM23: 0 | AN23: 2353393836764088 | AO23: 老板周 | AP23: - | AQ23: 退款成功 | AS23: - | AT23: - | AU23: - | AW23: 否 | AX23: 直播 | AY23: 广告 | AZ23: 直播 | BA23: 商城推荐 | BB23: - | BC23: - | BD23: 2025-09-15 10:48:28 | BE23: 0 | BF23: 0 | BG23: 0 | BH23: 0 | BJ23: 否 | BP23: - | BQ23: - | BR23: -
A24: 6945696235709732402 | B24: 6945696235709732402 | C24: 【老板周】复古风格 秋冬新款立体麻花织纹针织毛衣 | D24: 灰色;S(80-100斤);15天内发货 | E24: 1 | F24: 3772185880568135686 | G24: Z2418-灰色-S | H24: 329 | I24: 329 | J24: 0 | K24: 2.05 | L24: - | M24: - | N24: - | O24: 0 | P24: 2.05 | Q24: 0 | R24: 抖音支付 | S24: 0 | T24: *** | U24: *** | V24: 浙江省 | W24: 丽水市 | X24: 青田县 | Y24: 瓯南街道 | Z24: *** | AA24: 否 | AC24: 2025-08-31 17:32:36 | AD24: 灰色 | AF24: 2025-09-22 10:48:28 | AG24: 2025-08-31 17:32:40 | AH24: 抖音 | AI24: 精选联盟 | AJ24: 已完成 | AK24: 2025-09-15 17:32:40 | AL24: 普通订单 | AM24: 0 | AN24: 2353393836764088 | AO24: 老板周 | AP24: - | AQ24: - | AS24: - | AT24: - | AU24: - | AW24: 否 | AX24: 无 | AY24: 其他 | AZ24: 直播 | BA24: 个人主页&店铺&橱窗进入直播间 | BB24: - | BC24: - | BD24: 2025-09-15 10:48:28 | BE24: 0 | BF24: 0 | BG24: 0 | BH24: 0 | BJ24: 否 | BP24: - | BQ24: - | BR24: -
A25: 6921009624776736703 | B25: 6921009624776736703 | C25: 【老板周】复古风格 秋冬新款立体麻花织纹针织毛衣 | D25: 灰色;M(100-120斤);15天内发货 | E25: 1 | F25: 3772185880568135686 | G25: Z2418-灰色-M | H25: 329 | I25: 329 | J25: 0 | K25: 0 | L25: - | M25: - | N25: - | O25: 0 | P25: 0 | Q25: 0 | R25: 抖音支付 | S25: 0 | T25: *** | U25: *** | V25: 江苏省 | W25: 苏州市 | X25: 虎丘区 | Y25: 东渚街道 | Z25: *** | AA25: 否 | AC25: 2025-08-31 17:32:33 | AD25: 灰色 | AG25: 2025-08-31 17:32:38 | AH25: 抖音 | AI25: 精选联盟 | AJ25: 已关闭 | AK25: 2025-09-15 17:32:39 | AL25: 普通订单 | AM25: 0 | AN25: 2353393836764088 | AO25: 老板周 | AP25: - | AQ25: 退款成功 | AS25: - | AT25: - | AU25: - | AW25: 否 | AX25: 无 | AY25: 其他 | AZ25: 直播 | BA25: 关注来源 | BB25: - | BC25: - | BE25: 0 | BF25: 0 | BG25: 0 | BH25: 0 | BJ25: 否 | BP25: - | BQ25: - | BR25: -
A26: 6921013958667763428 | B26: 6921013958667763428 | C26: 【老板周】复古风格 秋冬新款立体麻花织纹针织毛衣 | D26: 灰色;S(80-100斤);15天内发货 | E26: 1 | F26: 3772185880568135686 | G26: Z2418-灰色-S | H26: 329 | I26: 329 | J26: 0 | K26: 0 | L26: - | M26: - | N26: - | O26: 0 | P26: 0 | Q26: 0 | R26: 支付宝 | S26: 0 | T26: *** | U26: *** | V26: 贵州省 | W26: 贵阳市 | X26: 南明区 | Y26: 中曹司街道 | Z26: *** | AA26: 否 | AC26: 2025-08-31 17:32:31 | AD26: 灰色 | AG26: 2025-08-31 17:32:38 | AH26: 抖音 | AI26: 精选联盟 | AJ26: 已关闭 | AK26: 2025-09-15 17:32:38 | AL26: 普通订单 | AM26: 0 | AN26: 2353393836764088 | AO26: 老板周 | AP26: - | AQ26: 退款成功 | AS26: - | AT26: - | AU26: - | AW26: 否 | AX26: 无 | AY26: 其他 | AZ26: 直播 | BA26: 直播推荐 | BB26: - | BC26: - | BE26: 0 | BF26: 0 | BG26: 0 | BH26: 0 | BJ26: 否 | BP26: - | BQ26: - | BR26: -
A27: 6945698443959669805 | B27: 6945698443959669805 | C27: 【老板周】日系极简 春季新品圆领简约设计感无袖马甲 | D27: 黑色;L(120-135斤);15天内发货 | E27: 1 | F27: 3767004410471907465 | G27: Z1640-黑色-L | H27: 289 | I27: 314 | J27: 25 | K27: 0 | L27: - | M27: - | N27: - | O27: 0 | P27: 0 | Q27: 0 | R27: 抖音月付 | S27: 0 | T27: *** | U27: *** | V27: 陕西省 | W27: 咸阳市 | X27: 渭城区 | Y27: 周陵街道 | Z27: *** | AA27: 否 | AC27: 2025-08-31 16:17:00 | AD27: 灰色 | AF27: 2025-09-19 16:35:27 | AG27: 2025-08-31 16:17:05 | AH27: 抖音 | AI27: 精选联盟 | AJ27: 已完成 | AK27: 2025-09-15 16:17:05 | AL27: 普通订单 | AM27: 0 | AN27: 2353393836764088 | AO27: 老板周 | AP27: - | AQ27: - | AS27: - | AT27: - | AU27: - | AW27: 否 | AX27: 无 | AY27: 其他 | AZ27: 直播 | BA27: 直播推荐 | BB27: - | BC27: - | BD27: 2025-09-12 16:35:27 | BE27: 0 | BF27: 0 | BG27: 0 | BH27: 0 | BJ27: 否 | BP27: - | BQ27: - | BR27: -
A28: 6945649067193472893 | B28: 6945649067193472893 | C28: 【老板周】日系极简 春季新品圆领简约设计感无袖马甲 | D28: 黑色;S(80-100斤);15天内发货 | E28: 1 | F28: 3767004410471907465 | G28: Z1640-黑色-S | H28: 289 | I28: 254.06 | J28: 0 | K28: 35.86 | L28: 平台七夕消费券-34.94 | M28: - | N28: - | O28: 0 | P28: 0.92 | Q28: 0 | R28: 抖音支付 | S28: 0 | T28: *** | U28: *** | V28: 辽宁省 | W28: 大连市 | X28: 中山区 | Y28: - | Z28: *** | AA28: 否 | AC28: 2025-08-29 20:47:38 | AD28: 灰色 | AE28: (收)[Z1640-黑色-S]*[1]# | AF28: 2025-09-18 23:58:12 | AG28: 2025-08-29 20:47:40 | AH28: 抖音 | AI28: 精选联盟 | AJ28: 已完成 | AK28: 2025-09-13 20:47:41 | AL28: 普通订单 | AM28: 0 | AN28: 2353393836764088 | AO28: 老板周 | AP28: - | AQ28: 退款成功 | AS28: - | AT28: - | AU28: - | AW28: 否 | AX28: 无 | AY28: 其他 | AZ28: 直播 | BA28: 搜索 | BB28: - | BC28: - | BD28: 2025-09-11 23:58:12 | BE28: 0 | BF28: 34.94 | BG28: 0 | BH28: 0 | BJ28: 否 | BP28: - | BQ28: - | BR28: -
A29: 6920964153135168659 | B29: 6920964153135168659 | C29: 【老板周】小众休闲 压褶松紧腰宽松百搭裤裙 | D29: 藏蓝色;M(95-110斤);15天内发货 | E29: 1 | F29: 3770653191356678342 | G29: Z575-藏蓝色-M | H29: 299 | I29: 299 | J29: 0 | K29: 0 | L29: - | M29: - | N29: - | O29: 0 | P29: 0 | Q29: 0 | R29: 抖音支付 | S29: 0 | T29: *** | U29: *** | V29: 内蒙古自治区 | W29: 呼和浩特市 | X29: 新城区 | Y29: 成吉思汗大街街道 | Z29: *** | AA29: 否 | AC29: 2025-08-28 22:10:07 | AD29: 灰色 | AH29: 抖音 | AI29: 小店自卖 | AJ29: 已关闭 | AK29: 2025-09-12 22:10:07 | AL29: 普通订单 | AM29: 0 | AN29: 0 | AP29: - | AQ29: - | AR29: 用户超时未支付自动取消 | AS29: - | AT29: - | AU29: - | AW29: 否 | AX29: 无 | AY29: 其他 | AZ29: 商品卡 | BA29: 店铺页面 | BB29: - | BC29: - | BE29: 0 | BF29: 0 | BG29: 0 | BH29: 0 | BJ29: 否 | BP29: - | BQ29: - | BR29: -
A30: 6920966085271780499 | B30: 6920966085271780499 | C30: 【老板周】小众休闲 压褶松紧腰宽松百搭裤裙 | D30: 藏蓝色;M(95-110斤);15天内发货 | E30: 1 | F30: 3770653191356678342 | G30: Z575-藏蓝色-M | H30: 299 | I30: 299 | J30: 0 | K30: 0 | L30: - | M30: - | N30: - | O30: 0 | P30: 0 | Q30: 0 | R30: 抖音支付 | S30: 0 | T30: *** | U30: *** | V30: 内蒙古自治区 | W30: 呼和浩特市 | X30: 新城区 | Y30: 成吉思汗大街街道 | Z30: *** | AA30: 否 | AC30: 2025-08-28 22:09:25 | AD30: 灰色 | AH30: 抖音 | AI30: 小店自卖 | AJ30: 已关闭 | AK30: 2025-09-12 22:09:25 | AL30: 普通订单 | AM30: 0 | AN30: 0 | AP30: - | AQ30: - | AR30: 用户超时未支付自动取消 | AS30: - | AT30: - | AU30: - | AW30: 否 | AX30: 无 | AY30: 其他 | AZ30: 商品卡 | BA30: 店铺页面 | BB30: - | BC30: - | BE30: 0 | BF30: 0 | BG30: 0 | BH30: 0 | BJ30: 否 | BP30: - | BQ30: - | BR30: -
A31: 6945610806981695196 | B31: 6945610806981695196 | C31: 【老板周】日系极简 春季新品圆领简约设计感无袖马甲 | D31: 黑色;M(100-120斤);15天内发货 | E31: 1 | F31: 3767004410471907465 | G31: Z1640-黑色-M | H31: 289 | I31: 260.12 | J31: 0 | K31: 28.88 | L31: 平台七夕消费券-28.88 | M31: - | N31: - | O31: 0 | P31: 0 | Q31: 0 | R31: 抖音月付 | S31: 0 | T31: *** | U31: *** | V31: 河北省 | W31: 邢台市 | X31: 信都区 | Y31: 达活泉街道 | Z31: *** | AA31: 否 | AC31: 2025-08-28 11:04:59 | AD31: 红色 | AE31: SF3234099112861(收） Z1640-黑色-M*1#;换货(6298912)#;换货76743232979811 收到退款 不换货了 | AF31: 2025-09-14 23:31:58 | AG31: 2025-08-28 11:05:06 | AH31: 抖音 | AI31: 精选联盟 | AJ31: 已完成 | AK31: 2025-09-12 11:05:07 | AL31: 普通订单 | AM31: 0 | AN31: 2353393836764088 | AO31: 老板周 | AP31: - | AQ31: 退款成功 | AS31: - | AT31: - | AU31: - | AW31: 否 | AX31: 无 | AY31: 其他 | AZ31: 商品卡 | BA31: 橱窗 | BB31: - | BC31: - | BD31: 2025-09-07 23:31:58 | BE31: 0 | BF31: 28.88 | BG31: 0 | BH31: 0 | BJ31: 否 | BP31: - | BQ31: - | BR31: -
A32: 6920952081164304100 | B32: 6920952081164304100 | C32: 【老板周】日系极简 春季新品圆领简约设计感无袖马甲 | D32: 黑色;M(100-120斤);15天内发货 | E32: 1 | F32: 3767004410471907465 | G32: Z1640-黑色-M | H32: 289 | I32: 289 | J32: 0 | K32: 0 | L32: - | M32: - | N32: - | O32: 0 | P32: 0 | Q32: 0 | R32: 抖音支付 | S32: 0 | T32: *** | U32: *** | V32: 山东省 | W32: 菏泽市 | X32: 牡丹区 | Y32: 牡丹街道 | Z32: *** | AA32: 否 | AC32: 2025-08-28 00:21:12 | AD32: 灰色 | AG32: 2025-08-28 00:21:13 | AH32: 抖音 | AI32: 小店自卖 | AJ32: 已关闭 | AK32: 2025-09-12 00:21:13 | AL32: 普通订单 | AM32: 0 | AN32: 0 | AP32: - | AQ32: 退款成功 | AS32: - | AT32: - | AU32: - | AW32: 否 | AX32: 无 | AY32: 其他 | AZ32: 商品卡 | BA32: 搜索 | BB32: - | BC32: - | BE32: 0 | BF32: 0 | BG32: 0 | BH32: 0 | BJ32: 否 | BP32: - | BQ32: - | BR32: -
A33: 6945587885982618859 | B33: 6945587885982618859 | C33: 【老板周】日系极简 春季新品圆领简约设计感无袖马甲 | D33: 黑色;M(100-120斤);15天内发货 | E33: 1 | F33: 3767004410471907465 | G33: Z1640-黑色-M | H33: 289 | I33: 278 | J33: 0 | K33: 11 | L33: 平台专属限时优惠券-11.00 | M33: - | N33: - | O33: 0 | P33: 0 | Q33: 0 | R33: 抖音支付 | S33: 0 | T33: *** | U33: *** | V33: 山东省 | W33: 青岛市 | X33: 市北区 | Y33: 河西街道 | Z33: *** | AA33: 否 | AC33: 2025-08-27 22:38:33 | AD33: 灰色 | AG33: 2025-08-27 22:38:44 | AH33: 抖音商城版 | AI33: 精选联盟 | AJ33: 已关闭 | AK33: 2025-09-11 22:38:44 | AL33: 普通订单 | AM33: 0 | AN33: 2353393836764088 | AO33: 老板周 | AP33: - | AQ33: 退款成功 | AS33: - | AT33: - | AU33: - | AW33: 否 | AX33: 直播 | AY33: 广告 | AZ33: 直播 | BA33: 商城推荐 | BB33: - | BC33: - | BE33: 0 | BF33: 11 | BG33: 0 | BH33: 0 | BJ33: 否 | BP33: - | BQ33: - | BR33: -
A34: 6945598979942323318 | B34: 6945598979942323318 | C34: 【老板周】日系极简 春季新品圆领简约设计感无袖马甲 | D34: 黑色;M(100-120斤);15天内发货 | E34: 1 | F34: 3767004410471907465 | G34: Z1640-黑色-M | H34: 289 | I34: 289 | J34: 0 | K34: 0 | L34: - | M34: - | N34: - | O34: 0 | P34: 0 | Q34: 0 | R34: 抖音支付 | S34: 0 | T34: *** | U34: *** | V34: 天津市 | W34: 天津市 | X34: 武清区 | Y34: 东蒲洼街道 | Z34: *** | AA34: 否 | AC34: 2025-08-27 22:12:00 | AD34: 灰色 | AF34: 2025-09-14 23:31:58 | AG34: 2025-08-27 22:12:06 | AH34: 头条lite-抖音电商 | AI34: 精选联盟 | AJ34: 已完成 | AK34: 2025-09-11 22:12:06 | AL34: 普通订单 | AM34: 0 | AN34: 2353393836764088 | AO34: 老板周 | AP34: - | AQ34: - | AS34: - | AT34: - | AU34: - | AW34: 否 | AX34: 无 | AY34: 其他 | AZ34: 直播 | BA34: 头条西瓜 | BB34: - | BC34: - | BD34: 2025-09-07 23:31:58 | BE34: 0 | BF34: 0 | BG34: 0 | BH34: 0 | BJ34: 否 | BP34: - | BQ34: - | BR34: -
A35: 6945583048360597411 | B35: 6945583048360597411 | C35: 【老板周】日系极简 春季新品圆领简约设计感无袖马甲 | D35: 黑色;M(100-120斤);15天内发货 | E35: 1 | F35: 3767004410471907465 | G35: Z1640-黑色-M | H35: 289 | I35: 289 | J35: 0 | K35: 0 | L35: - | M35: - | N35: - | O35: 0 | P35: 0 | Q35: 0 | R35: 抖音月付 | S35: 0 | T35: *** | U35: *** | V35: 山东省 | W35: 日照市 | X35: 莒县 | Y35: 城阳街道 | Z35: *** | AA35: 否 | AC35: 2025-08-27 20:47:29 | AD35: 蓝色 | AE35: 73572507159291(收） Z1640-黑色-M*1# | AG35: 2025-08-27 20:47:31 | AH35: 抖音 | AI35: 精选联盟 | AJ35: 已关闭 | AK35: 2025-09-11 20:47:32 | AL35: 普通订单 | AM35: 0 | AN35: 2353393836764088 | AO35: 老板周 | AP35: - | AQ35: 退款成功 | AS35: - | AT35: - | AU35: - | AW35: 否 | AX35: 无 | AY35: 其他 | AZ35: 直播 | BA35: 直播推荐 | BB35: - | BC35: - | BD35: 2025-09-07 23:31:58 | BE35: 0 | BF35: 0 | BG35: 0 | BH35: 0 | BJ35: 否 | BP35: - | BQ35: - | BR35: -
A36: 6945609733810165452 | B36: 6945609733810165452 | C36: 【老板周】日系极简 春季新品圆领简约设计感无袖马甲 | D36: 黑色;M(100-120斤);15天内发货 | E36: 1 | F36: 3767004410471907465 | G36: Z1640-黑色-M | H36: 289 | I36: 289 | J36: 0 | K36: 0 | L36: - | M36: - | N36: - | O36: 0 | P36: 0 | Q36: 0 | R36: 支付宝 | S36: 0 | T36: *** | U36: *** | V36: 山西省 | W36: 太原市 | X36: 杏花岭区 | Y36: 中涧河镇 | Z36: *** | AA36: 否 | AC36: 2025-08-27 19:52:03 | AD36: 灰色 | AH36: 番茄小说-抖音电商 | AI36: 精选联盟 | AJ36: 已关闭 | AK36: 2025-09-11 19:52:03 | AL36: 普通订单 | AM36: 0 | AN36: 2353393836764088 | AO36: 老板周 | AP36: - | AQ36: - | AR36: 用户超时未支付自动取消 | AS36: - | AT36: - | AU36: - | AW36: 否 | AX36: 直播 | AY36: 广告 | AZ36: 直播 | BA36: 其他 | BB36: - | BC36: - | BE36: 0 | BF36: 0 | BG36: 0 | BH36: 0 | BJ36: 否 | BP36: - | BQ36: - | BR36: -
A37: 6945592088900211946 | B37: 6945592088900211946 | C37: 【老板周】日系极简 春季新品圆领简约设计感无袖马甲 | D37: 黑色;M(100-120斤);15天内发货 | E37: 1 | F37: 3767004410471907465 | G37: Z1640-黑色-M | H37: 289 | I37: 289 | J37: 0 | K37: 0 | L37: - | M37: - | N37: - | O37: 0 | P37: 0 | Q37: 0 | R37: 抖音支付 | S37: 0 | T37: *** | U37: *** | V37: 江苏省 | W37: 常州市 | X37: 钟楼区 | Y37: 南大街道 | Z37: *** | AA37: 否 | AC37: 2025-08-27 18:21:49 | AD37: 蓝色 | AE37: SF3232586273829(收） Z1640-黑色-M*1# | AG37: 2025-08-27 18:21:55 | AH37: 抖音 | AI37: 精选联盟 | AJ37: 已关闭 | AK37: 2025-09-11 18:21:55 | AL37: 普通订单 | AM37: 0 | AN37: 2353393836764088 | AO37: 老板周 | AP37: - | AQ37: 退款成功 | AS37: - | AT37: - | AU37: - | AW37: 否 | AX37: 直播 | AY37: 广告 | AZ37: 直播 | BA37: 搜索 | BB37: - | BC37: - | BD37: 2025-09-07 23:31:58 | BE37: 0 | BF37: 0 | BG37: 0 | BH37: 0 | BJ37: 否 | BP37: - | BQ37: - | BR37: -
A38: 6945600734649980653 | B38: 6945600734649980653 | C38: 【老板周】日系极简 春季新品圆领简约设计感无袖马甲 | D38: 黑色;M(100-120斤);15天内发货 | E38: 1 | F38: 3767004410471907465 | G38: Z1640-黑色-M | H38: 289 | I38: 289 | J38: 0 | K38: 0 | L38: - | M38: - | N38: - | O38: 0 | P38: 0 | Q38: 0 | R38: 抖音支付 | S38: 0 | T38: *** | U38: *** | V38: 浙江省 | W38: 杭州市 | X38: 临平区 | Y38: 乔司街道 | Z38: *** | AA38: 否 | AC38: 2025-08-27 17:46:07 | AD38: 蓝色 | AE38: 78939136440697(收） Z1640-黑色-S*1# | AG38: 2025-08-27 17:46:08 | AH38: 抖音 | AI38: 精选联盟 | AJ38: 已关闭 | AK38: 2025-09-11 17:46:09 | AL38: 普通订单 | AM38: 0 | AN38: 2353393836764088 | AO38: 老板周 | AP38: - | AQ38: 退款成功 | AS38: - | AT38: - | AU38: - | AW38: 否 | AX38: 无 | AY38: 其他 | AZ38: 直播 | BA38: 短视频引流直播间 | BB38: - | BC38: - | BD38: 2025-09-07 23:31:58 | BE38: 0 | BF38: 0 | BG38: 0 | BH38: 0 | BJ38: 否 | BP38: - | BQ38: - | BR38: -
A39: 6945589601420317825 | B39: 6945589601420317825 | C39: 【老板周】日系极简 春季新品圆领简约设计感无袖马甲 | D39: 黑色;M(100-120斤);15天内发货 | E39: 1 | F39: 3767004410471907465 | G39: Z1640-黑色-M | H39: 289 | I39: 289 | J39: 0 | K39: 0 | L39: - | M39: - | N39: - | O39: 0 | P39: 0 | Q39: 0 | R39: 抖音支付 | S39: 0 | T39: *** | U39: *** | V39: 江苏省 | W39: 南通市 | X39: 崇川区 | Y39: 观音山街道 | Z39: *** | AA39: 否 | AC39: 2025-08-27 17:31:54 | AD39: 红色 | AE39: SF3232813766922(收） Z1640-黑色-M*1#;换货(6280100)#;换货76742192082926 | AF39: 2025-09-14 23:31:58 | AG39: 2025-08-27 17:31:55 | AH39: 抖音 | AI39: 精选联盟 | AJ39: 已完成 | AK39: 2025-09-11 17:31:56 | AL39: 普通订单 | AM39: 0 | AN39: 2353393836764088 | AO39: 老板周 | AP39: - | AQ39: 换货成功 | AS39: - | AT39: - | AU39: - | AW39: 否 | AX39: 无 | AY39: 其他 | AZ39: 直播 | BA39: 直播推荐 | BB39: - | BC39: - | BD39: 2025-09-07 23:31:58 | BE39: 0 | BF39: 0 | BG39: 0 | BH39: 0 | BJ39: 否 | BP39: - | BQ39: - | BR39: -
A40: 6920950993200905666 | B40: 6920950993200905666 | C40: 【老板周】日系极简 春季新品圆领简约设计感无袖马甲 | D40: 黑色;M(100-120斤);15天内发货 | E40: 8 | F40: 3767004410471907465 | G40: Z1640-黑色-M | H40: 289 | I40: 2312 | J40: 0 | K40: 0 | L40: - | M40: - | N40: - | O40: 0 | P40: 0 | Q40: 0 | R40: 支付宝 | S40: 0 | T40: *** | U40: *** | V40: 山东省 | W40: 济宁市 | X40: 微山县 | Y40: - | Z40: *** | AA40: 否 | AC40: 2025-08-27 17:23:35 | AD40: 灰色 | AH40: 头条lite-抖音电商 | AI40: 精选联盟 | AJ40: 已关闭 | AK40: 2025-09-11 17:23:35 | AL40: 普通订单 | AM40: 0 | AN40: 2353393836764088 | AO40: 老板周 | AP40: - | AQ40: - | AR40: 用户超时未支付自动取消 | AS40: - | AT40: - | AU40: - | AW40: 否 | AX40: 直播 | AY40: 广告 | AZ40: 直播 | BA40: 头条西瓜 | BB40: - | BC40: - | BE40: 0 | BF40: 0 | BG40: 0 | BH40: 0 | BJ40: 否 | BP40: - | BQ40: - | BR40: -
...

Sheet 抖音订单-按支付日期-ABF列，要先手动清除空格
A1: 主订单编号 | B1: 子订单编号 | C1: 选购商品 | D1: 商品规格 | E1: 商品数量 | F1: 商品ID | G1: 商家编码 | H1: 商品单价 | I1: 订单应付金额 | J1: 运费 | K1: 优惠总金额 | L1: 平台优惠 | M1: 商家优惠 | N1: 达人优惠 | O1: 商家改价 | P1: 支付优惠 | Q1: 红包抵扣 | R1: 支付方式 | S1: 手续费 | T1: 收件人 | U1: 收件人手机号 | V1: 省 | W1: 市 | X1: 区 | Y1: 街道 | Z1: 详细地址 | AA1: 是否修改过地址 | AB1: 买家留言 | AC1: 订单提交时间 | AD1: 旗帜颜色 | AE1: 商家备注 | AF1: 订单完成时间 | AG1: 支付完成时间 | AH1: APP渠道 | AI1: 流量来源 | AJ1: 订单状态 | AK1: 承诺发货时间 | AL1: 订单类型 | AM1: 鲁班落地页ID | AN1: 达人ID | AO1: 达人昵称 | AP1: 所属门店ID | AQ1: 售后状态 | AR1: 取消原因 | AS1: 预约发货时间 | AT1: 仓库ID | AU1: 仓库名称 | AV1: 序列号 | AW1: 是否安心购 | AX1: 广告渠道 | AY1: 流量类型 | AZ1: 流量体裁 | BA1: 流量渠道 | BB1: 发货主体 | BC1: 发货主体明细 | BD1: 发货时间 | BE1: 降价类优惠 | BF1: 平台实际承担优惠金额 | BG1: 商家实际承担优惠金额 | BH1: 达人实际承担优惠金额 | BI1: 预计送达时间 | BJ1: 是否平台仓自流转 | BK1: 车型 | BL1: 商品69码 | BM1: 发货SN码 | BN1: 发货IMEI码1 | BO1: 发货IMEI码2 | BP1: 预约送达时间 | BQ1: 建议发货时间（起） | BR1: 建议发货时间（止） | BS1: 物流SN码 | BT1: 物流IMEI码1 | BU1: 物流IMEI码2
A2: 6921014879971867995 | B2: 6921014879971867995 | C2: 【老板周】复古风格 秋冬新款立体麻花织纹针织毛衣 | D2: 灰色;L(120-135斤);15天内发货 | E2: 1 | F2: 3772185880568135686 | G2: Z2418-灰色-L | H2: 329 | I2: 329 | J2: 0 | K2: 0 | L2: - | M2: - | N2: - | O2: 0 | P2: 0 | Q2: 0 | R2: 抖音月付 | S2: 0 | T2: *** | U2: *** | V2: 安徽省 | W2: 宿州市 | X2: 埇桥区 | Y2: 西关街道 | Z2: *** | AA2: 否 | AC2: 2025-08-31 22:51:27 | AD2: 灰色 | AE2: (收)[Z2418-灰色-L]*[1]# | AF2: 2025-09-22 10:48:28 | AG2: 2025-08-31 22:51:31 | AH2: 抖音 | AI2: 精选联盟 | AJ2: 已完成 | AK2: 2025-09-15 22:51:31 | AL2: 普通订单 | AM2: 0 | AN2: 2353393836764088 | AO2: 老板周 | AP2: - | AQ2: 退款成功 | AS2: - | AT2: - | AU2: - | AW2: 否 | AX2: 无 | AY2: 其他 | AZ2: 直播 | BA2: 商城推荐 | BB2: - | BC2: - | BD2: 2025-09-15 10:48:28 | BE2: 0 | BF2: 0 | BG2: 0 | BH2: 0 | BJ2: 否 | BP2: - | BQ2: - | BR2: -
A3: 6945703385201317436 | B3: 6945703385201317436 | C3: 【老板周】日系极简 春季新品圆领简约设计感无袖马甲 | D3: 黑色;M(100-120斤);15天内发货 | E3: 1 | F3: 3767004410471907465 | G3: Z1640-黑色-M | H3: 289 | I3: 289 | J3: 0 | K3: 0 | L3: - | M3: - | N3: - | O3: 0 | P3: 0 | Q3: 0 | R3: 支付宝 | S3: 0 | T3: *** | U3: *** | V3: 广东省 | W3: 深圳市 | X3: 龙华区 | Y3: 龙华街道 | Z3: *** | AA3: 否 | AC3: 2025-08-31 22:28:56 | AD3: 灰色 | AF3: 2025-09-18 23:58:12 | AG3: 2025-08-31 22:29:01 | AH3: 抖音 | AI3: 精选联盟 | AJ3: 已完成 | AK3: 2025-09-15 22:29:02 | AL3: 普通订单 | AM3: 0 | AN3: 2353393836764088 | AO3: 老板周 | AP3: - | AQ3: - | AS3: - | AT3: - | AU3: - | AW3: 否 | AX3: 无 | AY3: 其他 | AZ3: 直播 | BA3: 关注来源 | BB3: - | BC3: - | BD3: 2025-09-11 23:58:12 | BE3: 0 | BF3: 0 | BG3: 0 | BH3: 0 | BJ3: 否 | BP3: - | BQ3: - | BR3: -
A4: 6945727588250948678 | B4: 6945727588250948678 | C4: 【老板周】日系极简 春季新品圆领简约设计感无袖马甲 | D4: 黑色;L(120-135斤);15天内发货 | E4: 1 | F4: 3767004410471907465 | G4: Z1640-黑色-L | H4: 289 | I4: 289 | J4: 0 | K4: 0 | L4: - | M4: - | N4: - | O4: 0 | P4: 0 | Q4: 0 | R4: 抖音支付 | S4: 0 | T4: *** | U4: *** | V4: 山东省 | W4: 德州市 | X4: 德城区 | Y4: - | Z4: *** | AA4: 否 | AC4: 2025-08-31 22:26:00 | AD4: 灰色 | AG4: 2025-08-31 22:26:05 | AH4: 抖音 | AI4: 精选联盟 | AJ4: 已关闭 | AK4: 2025-09-15 22:26:05 | AL4: 普通订单 | AM4: 0 | AN4: 2353393836764088 | AO4: 老板周 | AP4: - | AQ4: 退款成功 | AS4: - | AT4: - | AU4: - | AW4: 否 | AX4: 无 | AY4: 其他 | AZ4: 直播 | BA4: 直播推荐 | BB4: - | BC4: - | BE4: 0 | BF4: 0 | BG4: 0 | BH4: 0 | BJ4: 否 | BP4: - | BQ4: - | BR4: -
A5: 6945714505452361238 | B5: 6945714505452361238 | C5: 【老板周】日系极简 春季新品圆领简约设计感无袖马甲 | D5: 黑色;S(80-100斤);15天内发货 | E5: 1 | F5: 3767004410471907465 | G5: Z1640-黑色-S | H5: 289 | I5: 286 | J5: 0 | K5: 4 | L5: 平台晚发即赔券-3.00 | M5: - | N5: - | O5: 0 | P5: 1 | Q5: 0 | R5: 抖音支付 | S5: 0 | T5: *** | U5: *** | V5: 河南省 | W5: 平顶山市 | X5: 湛河区 | Y5: 九里山街道 | Z5: *** | AA5: 否 | AC5: 2025-08-31 22:01:43 | AD5: 灰色 | AG5: 2025-08-31 22:01:46 | AH5: 抖音 | AI5: 精选联盟 | AJ5: 已关闭 | AK5: 2025-09-15 22:01:47 | AL5: 普通订单 | AM5: 0 | AN5: 2353393836764088 | AO5: 老板周 | AP5: - | AQ5: 退款成功 | AS5: - | AT5: - | AU5: - | AW5: 否 | AX5: 无 | AY5: 其他 | AZ5: 商品卡 | BA5: 橱窗 | BB5: - | BC5: - | BE5: 0 | BF5: 3 | BG5: 0 | BH5: 0 | BJ5: 否 | BP5: - | BQ5: - | BR5: -
A6: 6945700999501124814 | B6: 6945700999501124814 | C6: 【老板周】极简设计 秋冬毛绒感圆领套头舒适针织毛衣 | D6: 红色;M(100-135斤);15天内发货 | E6: 1 | F6: 3772189127454359773 | G6: Z2425-红色-M | H6: 289 | I6: 289 | J6: 0 | K6: 0 | L6: - | M6: - | N6: - | O6: 0 | P6: 0 | Q6: 0 | R6: 抖音支付 | S6: 0 | T6: *** | U6: *** | V6: 湖南省 | W6: 常德市 | X6: 武陵区 | Y6: 穿紫河街道 | Z6: *** | AA6: 否 | AC6: 2025-08-31 20:25:26 | AD6: 灰色 | AG6: 2025-08-31 20:25:28 | AH6: 抖音 | AI6: 精选联盟 | AJ6: 已关闭 | AK6: 2025-09-15 20:25:28 | AL6: 普通订单 | AM6: 0 | AN6: 2353393836764088 | AO6: 老板周 | AP6: - | AQ6: 退款成功 | AS6: - | AT6: - | AU6: - | AW6: 否 | AX6: 直播 | AY6: 广告 | AZ6: 直播 | BA6: 商城推荐 | BB6: - | BC6: - | BE6: 0 | BF6: 0 | BG6: 0 | BH6: 0 | BJ6: 否 | BP6: - | BQ6: - | BR6: -
A7: 6921014170429783498 | B7: 6921014170429783498 | C7: 【老板周】日系极简 春季新品圆领简约设计感无袖马甲 | D7: 黑色;M(100-120斤);15天内发货 | E7: 1 | F7: 3767004410471907465 | G7: Z1640-黑色-M | H7: 289 | I7: 289 | J7: 0 | K7: 0 | L7: - | M7: - | N7: - | O7: 0 | P7: 0 | Q7: 0 | R7: 支付宝 | S7: 0 | T7: *** | U7: *** | V7: 上海市 | W7: 上海市 | X7: 浦东新区 | Y7: - | Z7: *** | AA7: 否 | AC7: 2025-08-31 19:29:31 | AD7: 灰色 | AF7: 2025-09-18 23:58:12 | AG7: 2025-08-31 19:29:36 | AH7: 抖音 | AI7: 精选联盟 | AJ7: 已完成 | AK7: 2025-09-15 19:29:36 | AL7: 普通订单 | AM7: 0 | AN7: 2353393836764088 | AO7: 老板周 | AP7: - | AQ7: - | AS7: - | AT7: - | AU7: - | AW7: 否 | AX7: 无 | AY7: 其他 | AZ7: 直播 | BA7: 直播推荐 | BB7: - | BC7: - | BD7: 2025-09-11 23:58:12 | BE7: 0 | BF7: 0 | BG7: 0 | BH7: 0 | BJ7: 否 | BP7: - | BQ7: - | BR7: -
A8: 6945712098356630732 | B8: 6945712098356630732 | C8: 【老板周】日系极简 春季新品圆领简约设计感无袖马甲 | D8: 黑色;M(100-120斤);15天内发货 | E8: 1 | F8: 3767004410471907465 | G8: Z1640-黑色-M | H8: 289 | I8: 289 | J8: 0 | K8: 0 | L8: - | M8: - | N8: - | O8: 0 | P8: 0 | Q8: 0 | R8: 抖音月付 | S8: 0 | T8: *** | U8: *** | V8: 山西省 | W8: 太原市 | X8: 晋源区 | Y8: 义井街道 | Z8: *** | AA8: 否 | AC8: 2025-08-31 19:13:06 | AD8: 灰色 | AF8: 2025-09-18 23:58:12 | AG8: 2025-08-31 19:13:08 | AH8: 抖音 | AI8: 精选联盟 | AJ8: 已完成 | AK8: 2025-09-15 19:13:08 | AL8: 普通订单 | AM8: 0 | AN8: 2353393836764088 | AO8: 老板周 | AP8: - | AQ8: 退款成功 | AS8: - | AT8: - | AU8: - | AW8: 否 | AX8: 无 | AY8: 其他 | AZ8: 直播 | BA8: 直播推荐 | BB8: - | BC8: - | BD8: 2025-09-11 23:58:12 | BE8: 0 | BF8: 0 | BG8: 0 | BH8: 0 | BJ8: 否 | BP8: - | BQ8: - | BR8: -
A9: 6921016389061410674 | B9: 6921016389061410674 | C9: 【老板周】极简设计 秋冬毛绒感圆领套头舒适针织毛衣 | D9: 红色;S(80-100斤);15天内发货 | E9: 1 | F9: 3772189127454359773 | G9: Z2425-红色-S | H9: 289 | I9: 284 | J9: 0 | K9: 5 | L9: 平台晚发即赔券-5.00 | M9: - | N9: - | O9: 0 | P9: 0 | Q9: 0 | R9: 抖音月付 | S9: 0 | T9: *** | U9: *** | V9: 重庆市 | W9: 重庆市 | X9: 九龙坡区 | Y9: 中梁山街道 | Z9: *** | AA9: 否 | AC9: 2025-08-31 18:07:41 | AD9: 灰色 | AG9: 2025-08-31 18:07:42 | AH9: 头条lite-抖音电商 | AI9: 精选联盟 | AJ9: 已关闭 | AK9: 2025-09-15 18:07:43 | AL9: 普通订单 | AM9: 0 | AN9: 2353393836764088 | AO9: 老板周 | AP9: - | AQ9: 退款成功 | AS9: - | AT9: - | AU9: - | AW9: 否 | AX9: 直播 | AY9: 广告 | AZ9: 直播 | BA9: 头条西瓜 | BB9: - | BC9: - | BE9: 0 | BF9: 5 | BG9: 0 | BH9: 0 | BJ9: 否 | BP9: - | BQ9: - | BR9: -
A10: 6945711936320509468 | B10: 6945711936320509468 | C10: 【老板周】极简设计 秋冬毛绒感圆领套头舒适针织毛衣 | D10: 蓝色;S(80-100斤);15天内发货 | E10: 1 | F10: 3772189127454359773 | G10: Z2425-蓝色-S | H10: 289 | I10: 289 | J10: 0 | K10: 0 | L10: - | M10: - | N10: - | O10: 0 | P10: 0 | Q10: 0 | R10: 抖音支付 | S10: 0 | T10: *** | U10: *** | V10: 贵州省 | W10: 贵阳市 | X10: 乌当区 | Y10: 新创路街道 | Z10: *** | AA10: 否 | AC10: 2025-08-31 18:05:55 | AD10: 灰色 | AH10: 抖音 | AI10: 精选联盟 | AJ10: 已关闭 | AK10: 2025-09-15 18:05:55 | AL10: 普通订单 | AM10: 0 | AN10: 2353393836764088 | AO10: 老板周 | AP10: - | AQ10: - | AR10: 你已取消订单：暂时不需要这个商品 | AS10: - | AT10: - | AU10: - | AW10: 否 | AX10: 无 | AY10: 其他 | AZ10: 直播 | BA10: 直播推荐 | BB10: - | BC10: - | BE10: 0 | BF10: 0 | BG10: 0 | BH10: 0 | BJ10: 否 | BP10: - | BQ10: - | BR10: -
A11: 6921016313814548201 | B11: 6921016313814548201 | C11: 【老板周】极简设计 秋冬毛绒感圆领套头舒适针织毛衣 | D11: 红色;M(100-135斤);15天内发货 | E11: 1 | F11: 3772189127454359773 | G11: Z2425-红色-M | H11: 289 | I11: 267 | J11: 0 | K11: 22 | L11: 平台全额返现满减券-22.00 | M11: - | N11: - | O11: 0 | P11: 0 | Q11: 0 | R11: 抖音月付 | S11: 0 | T11: *** | U11: *** | V11: 广东省 | W11: 阳江市 | X11: 江城区 | Y11: 城北街道 | Z11: *** | AA11: 否 | AC11: 2025-08-31 18:05:31 | AD11: 蓝色 | AE11: YT2532916536267(收） Z2425-红色-M*1# | AG11: 2025-08-31 18:05:36 | AH11: 抖音 | AI11: 精选联盟 | AJ11: 已关闭 | AK11: 2025-09-15 18:05:36 | AL11: 普通订单 | AM11: 0 | AN11: 2353393836764088 | AO11: 老板周 | AP11: - | AQ11: 退款成功 | AS11: - | AT11: - | AU11: - | AW11: 否 | AX11: 无 | AY11: 其他 | AZ11: 直播 | BA11: 商城推荐 | BB11: - | BC11: - | BD11: 2025-09-09 23:55:16 | BE11: 0 | BF11: 22 | BG11: 0 | BH11: 0 | BJ11: 否 | BP11: - | BQ11: - | BR11: -
A12: 6945707477692061056 | B12: 6945707477692061056 | C12: 【老板周】简约松弛 秋冬纯色弧形下摆宽松百搭上衣 | D12: 白色;S(80-100斤);15天内发货 | E12: 1 | F12: 3771440658552848740 | G12: Z2311-白色-S | H12: 229 | I12: 229 | J12: 0 | K12: 0 | L12: - | M12: - | N12: - | O12: 0 | P12: 0 | Q12: 0 | R12: 抖音支付 | S12: 0 | T12: *** | U12: *** | V12: 湖南省 | W12: 常德市 | X12: 武陵区 | Y12: 府坪街道 | Z12: *** | AA12: 否 | AC12: 2025-08-31 18:01:07 | AD12: 蓝色 | AE12: 73571847180415(收） Z2311-白色-S*1# | AG12: 2025-08-31 18:01:08 | AH12: 抖音 | AI12: 小店自卖 | AJ12: 已关闭 | AK12: 2025-09-15 18:01:09 | AL12: 普通订单 | AM12: 0 | AN12: 0 | AP12: - | AQ12: 退款成功 | AS12: - | AT12: - | AU12: - | AW12: 否 | AX12: 无 | AY12: 其他 | AZ12: 商品卡 | BA12: 搜索 | BB12: - | BC12: - | BD12: 2025-09-07 16:39:45 | BE12: 0 | BF12: 0 | BG12: 0 | BH12: 0 | BJ12: 否 | BP12: - | BQ12: - | BR12: -
A13: 6945694166426850837 | B13: 6945694166426850837 | C13: 【老板周】复古风格 秋冬新款立体麻花织纹针织毛衣 | D13: 灰色;L(120-135斤);15天内发货 | E13: 1 | F13: 3772185880568135686 | G13: Z2418-灰色-L | H13: 329 | I13: 329 | J13: 0 | K13: 0 | L13: - | M13: - | N13: - | O13: 0 | P13: 0 | Q13: 0 | R13: 支付宝 | S13: 0 | T13: *** | U13: *** | V13: 辽宁省 | W13: 本溪市 | X13: 明山区 | Y13: 北地街道 | Z13: *** | AA13: 否 | AC13: 2025-08-31 17:51:10 | AD13: 灰色 | AG13: 2025-08-31 17:51:20 | AH13: 抖音极速版 | AI13: 精选联盟 | AJ13: 已关闭 | AK13: 2025-09-15 17:51:20 | AL13: 普通订单 | AM13: 0 | AN13: 2353393836764088 | AO13: 老板周 | AP13: - | AQ13: 退款成功 | AS13: - | AT13: - | AU13: - | AW13: 否 | AX13: 无 | AY13: 其他 | AZ13: 直播 | BA13: 商城推荐 | BB13: - | BC13: - | BE13: 0 | BF13: 0 | BG13: 0 | BH13: 0 | BJ13: 否 | BP13: - | BQ13: - | BR13: -
A14: 6945716113981314698 | B14: 6945716113981314698 | C14: 【老板周】复古风格 秋冬新款立体麻花织纹针织毛衣 | D14: 灰色;S(80-100斤);15天内发货 | E14: 1 | F14: 3772185880568135686 | G14: Z2418-灰色-S | H14: 329 | I14: 329 | J14: 0 | K14: 0 | L14: - | M14: - | N14: - | O14: 0 | P14: 0 | Q14: 0 | R14: 抖音月付 | S14: 0 | T14: *** | U14: *** | V14: 山西省 | W14: 吕梁市 | X14: 交城县 | Y14: 天宁镇 | Z14: *** | AA14: 否 | AC14: 2025-08-31 17:50:43 | AD14: 灰色 | AG14: 2025-08-31 17:50:44 | AH14: 抖音 | AI14: 精选联盟 | AJ14: 已关闭 | AK14: 2025-09-15 17:50:44 | AL14: 普通订单 | AM14: 0 | AN14: 2353393836764088 | AO14: 老板周 | AP14: - | AQ14: 退款成功 | AS14: - | AT14: - | AU14: - | AW14: 否 | AX14: 无 | AY14: 其他 | AZ14: 直播 | BA14: 直播推荐 | BB14: - | BC14: - | BE14: 0 | BF14: 0 | BG14: 0 | BH14: 0 | BJ14: 否 | BP14: - | BQ14: - | BR14: -
A15: 6921011676079357340 | B15: 6921011676079357340 | C15: 【老板周】复古风格 秋冬新款立体麻花织纹针织毛衣 | D15: 灰色;S(80-100斤);15天内发货 | E15: 1 | F15: 3772185880568135686 | G15: Z2418-灰色-S | H15: 329 | I15: 329 | J15: 0 | K15: 0 | L15: - | M15: - | N15: - | O15: 0 | P15: 0 | Q15: 0 | R15: 抖音月付 | S15: 0 | T15: *** | U15: *** | V15: 河北省 | W15: 沧州市 | X15: 黄骅市 | Y15: - | Z15: *** | AA15: 否 | AC15: 2025-08-31 17:46:12 | AD15: 灰色 | AG15: 2025-08-31 17:46:16 | AH15: 抖音 | AI15: 精选联盟 | AJ15: 已关闭 | AK15: 2025-09-15 17:46:16 | AL15: 普通订单 | AM15: 0 | AN15: 2353393836764088 | AO15: 老板周 | AP15: - | AQ15: 退款成功 | AS15: - | AT15: - | AU15: - | AW15: 否 | AX15: 无 | AY15: 其他 | AZ15: 直播 | BA15: 个人主页&店铺&橱窗进入直播间 | BB15: - | BC15: - | BE15: 0 | BF15: 0 | BG15: 0 | BH15: 0 | BJ15: 否 | BP15: - | BQ15: - | BR15: -
A16: 6945711886863766847 | B16: 6945711886863766847 | C16: 【老板周】复古风格 秋冬新款立体麻花织纹针织毛衣 | D16: 灰色;M(100-120斤);15天内发货 | E16: 1 | F16: 3772185880568135686 | G16: Z2418-灰色-M | H16: 329 | I16: 329 | J16: 0 | K16: 0 | L16: - | M16: - | N16: - | O16: 0 | P16: 0 | Q16: 0 | R16: 支付宝 | S16: 0 | T16: *** | U16: *** | V16: 湖南省 | W16: 张家界市 | X16: 永定区 | Y16: 崇文街道 | Z16: *** | AA16: 否 | AC16: 2025-08-31 17:39:51 | AD16: 灰色 | AG16: 2025-08-31 17:39:57 | AH16: 红果短剧-抖音电商 | AI16: 精选联盟 | AJ16: 已关闭 | AK16: 2025-09-15 17:39:58 | AL16: 普通订单 | AM16: 0 | AN16: 2353393836764088 | AO16: 老板周 | AP16: - | AQ16: 退款成功 | AS16: - | AT16: - | AU16: - | AW16: 否 | AX16: 直播 | AY16: 广告 | AZ16: 直播 | BA16: 其他 | BB16: - | BC16: - | BE16: 0 | BF16: 0 | BG16: 0 | BH16: 0 | BJ16: 否 | BP16: - | BQ16: - | BR16: -
A17: 6921009635296968526 | B17: 6921009635296968526 | C17: 【老板周】复古风格 秋冬新款立体麻花织纹针织毛衣 | D17: 灰色;M(100-120斤);15天内发货 | E17: 1 | F17: 3772185880568135686 | G17: Z2418-灰色-M | H17: 329 | I17: 329 | J17: 0 | K17: 0 | L17: - | M17: - | N17: - | O17: 0 | P17: 0 | Q17: 0 | R17: 抖音支付 | S17: 0 | T17: *** | U17: *** | V17: 天津市 | W17: 天津市 | X17: 滨海新区 | Y17: - | Z17: *** | AA17: 否 | AC17: 2025-08-31 17:39:47 | AD17: 灰色 | AG17: 2025-08-31 17:39:48 | AH17: 抖音 | AI17: 精选联盟 | AJ17: 已关闭 | AK17: 2025-09-15 17:39:48 | AL17: 普通订单 | AM17: 0 | AN17: 2353393836764088 | AO17: 老板周 | AP17: - | AQ17: 退款成功 | AS17: - | AT17: - | AU17: - | AW17: 否 | AX17: 无 | AY17: 其他 | AZ17: 直播 | BA17: 个人主页&店铺&橱窗进入直播间 | BB17: - | BC17: - | BE17: 0 | BF17: 0 | BG17: 0 | BH17: 0 | BJ17: 否 | BP17: - | BQ17: - | BR17: -
A18: 6921016365371785140 | B18: 6921016365371785140 | C18: 【老板周】复古风格 秋冬新款立体麻花织纹针织毛衣 | D18: 灰色;M(100-120斤);15天内发货 | E18: 1 | F18: 3772185880568135686 | G18: Z2418-灰色-M | H18: 329 | I18: 329 | J18: 0 | K18: 0 | L18: - | M18: - | N18: - | O18: 0 | P18: 0 | Q18: 0 | R18: 支付宝 | S18: 0 | T18: *** | U18: *** | V18: 河北省 | W18: 石家庄市 | X18: 赵县 | Y18: 赵州镇 | Z18: *** | AA18: 否 | AC18: 2025-08-31 17:39:46 | AD18: 蓝色 | AE18: JT5414067073138(收） Z2418-灰色-M*1# | AG18: 2025-08-31 17:39:54 | AH18: 抖音 | AI18: 精选联盟 | AJ18: 已关闭 | AK18: 2025-09-15 17:39:54 | AL18: 普通订单 | AM18: 0 | AN18: 2353393836764088 | AO18: 老板周 | AP18: - | AQ18: 退款成功 | AS18: - | AT18: - | AU18: - | AW18: 否 | AX18: 无 | AY18: 其他 | AZ18: 直播 | BA18: 直播推荐 | BB18: - | BC18: - | BD18: 2025-09-15 10:48:28 | BE18: 0 | BF18: 0 | BG18: 0 | BH18: 0 | BJ18: 否 | BP18: - | BQ18: - | BR18: -
A19: 6921009588551319487 | B19: 6921009588551319487 | C19: 【老板周】复古风格 秋冬新款立体麻花织纹针织毛衣 | D19: 灰色;S(80-100斤);15天内发货 | E19: 1 | F19: 3772185880568135686 | G19: Z2418-灰色-S | H19: 329 | I19: 329 | J19: 0 | K19: 0 | L19: - | M19: - | N19: - | O19: 0 | P19: 0 | Q19: 0 | R19: 抖音支付 | S19: 0 | T19: *** | U19: *** | V19: 江苏省 | W19: 苏州市 | X19: 虎丘区 | Y19: 东渚街道 | Z19: *** | AA19: 否 | AC19: 2025-08-31 17:39:43 | AD19: 灰色 | AG19: 2025-08-31 17:39:46 | AH19: 抖音 | AI19: 精选联盟 | AJ19: 已关闭 | AK19: 2025-09-15 17:39:46 | AL19: 普通订单 | AM19: 0 | AN19: 2353393836764088 | AO19: 老板周 | AP19: - | AQ19: 退款成功 | AS19: - | AT19: - | AU19: - | AW19: 否 | AX19: 无 | AY19: 其他 | AZ19: 直播 | BA19: 关注来源 | BB19: - | BC19: - | BE19: 0 | BF19: 0 | BG19: 0 | BH19: 0 | BJ19: 否 | BP19: - | BQ19: - | BR19: -
A20: 6921018615091854571 | B20: 6921018615091854571 | C20: 【老板周】复古风格 秋冬新款立体麻花织纹针织毛衣 | D20: 灰色;L(120-135斤);15天内发货 | E20: 1 | F20: 3772185880568135686 | G20: Z2418-灰色-L | H20: 329 | I20: 329 | J20: 0 | K20: 0 | L20: - | M20: - | N20: - | O20: 0 | P20: 0 | Q20: 0 | R20: 抖音支付 | S20: 0 | T20: *** | U20: *** | V20: 河北省 | W20: 邢台市 | X20: 信都区 | Y20: 泉西街道 | Z20: *** | AA20: 否 | AC20: 2025-08-31 17:33:32 | AD20: 灰色 | AG20: 2025-08-31 17:33:35 | AH20: 抖音 | AI20: 精选联盟 | AJ20: 已关闭 | AK20: 2025-09-15 17:33:35 | AL20: 普通订单 | AM20: 0 | AN20: 2353393836764088 | AO20: 老板周 | AP20: - | AQ20: 退款成功 | AS20: - | AT20: - | AU20: - | AW20: 否 | AX20: 无 | AY20: 其他 | AZ20: 直播 | BA20: 直播推荐 | BB20: - | BC20: - | BE20: 0 | BF20: 0 | BG20: 0 | BH20: 0 | BJ20: 否 | BP20: - | BQ20: - | BR20: -
A21: 6945702914926777790 | B21: 6945702914926777790 | C21: 【老板周】复古风格 秋冬新款立体麻花织纹针织毛衣 | D21: 灰色;M(100-120斤);15天内发货 | E21: 1 | F21: 3772185880568135686 | G21: Z2418-灰色-M | H21: 329 | I21: 329 | J21: 0 | K21: 0 | L21: - | M21: - | N21: - | O21: 0 | P21: 0 | Q21: 0 | R21: 抖音支付 | S21: 0 | T21: *** | U21: *** | V21: 山西省 | W21: 大同市 | X21: 云冈区 | Y21: 新平旺街道 | Z21: *** | AA21: 否 | AC21: 2025-08-31 17:33:15 | AD21: 灰色 | AF21: 2025-09-21 10:50:13 | AG21: 2025-08-31 17:33:16 | AH21: 抖音极速版 | AI21: 精选联盟 | AJ21: 已完成 | AK21: 2025-09-15 17:33:17 | AL21: 普通订单 | AM21: 0 | AN21: 2353393836764088 | AO21: 老板周 | AP21: - | AQ21: - | AS21: - | AT21: - | AU21: - | AW21: 否 | AX21: 直播 | AY21: 广告 | AZ21: 直播 | BA21: 直播推荐 | BB21: - | BC21: - | BD21: 2025-09-15 10:48:28 | BE21: 0 | BF21: 0 | BG21: 0 | BH21: 0 | BJ21: 否 | BP21: - | BQ21: - | BR21: -
A22: 6945716202524317053 | B22: 6945716202524317053 | C22: 【老板周】复古风格 秋冬新款立体麻花织纹针织毛衣 | D22: 灰色;M(100-120斤);15天内发货 | E22: 1 | F22: 3772185880568135686 | G22: Z2418-灰色-M | H22: 329 | I22: 329 | J22: 0 | K22: 0 | L22: - | M22: - | N22: - | O22: 0 | P22: 0 | Q22: 0 | R22: 抖音月付 | S22: 0 | T22: *** | U22: *** | V22: 重庆市 | W22: 重庆市 | X22: 梁平区 | Y22: 双桂街道 | Z22: *** | AA22: 否 | AC22: 2025-08-31 17:32:47 | AD22: 蓝色 | AE22: SF3282428122123(收） Z2418-灰色-M*1# | AG22: 2025-08-31 17:32:49 | AH22: 抖音商城版 | AI22: 精选联盟 | AJ22: 已关闭 | AK22: 2025-09-15 17:32:50 | AL22: 普通订单 | AM22: 0 | AN22: 2353393836764088 | AO22: 老板周 | AP22: - | AQ22: 退款成功 | AS22: - | AT22: - | AU22: - | AW22: 否 | AX22: 无 | AY22: 其他 | AZ22: 直播 | BA22: 商城推荐 | BB22: - | BC22: - | BD22: 2025-09-14 23:53:25 | BE22: 0 | BF22: 0 | BG22: 0 | BH22: 0 | BJ22: 否 | BP22: - | BQ22: - | BR22: -
A23: 6921018667371494935 | B23: 6921018667371494935 | C23: 【老板周】复古风格 秋冬新款立体麻花织纹针织毛衣 | D23: 灰色;S(80-100斤);15天内发货 | E23: 1 | F23: 3772185880568135686 | G23: Z2418-灰色-S | H23: 329 | I23: 329 | J23: 0 | K23: 0 | L23: - | M23: - | N23: - | O23: 0 | P23: 0 | Q23: 0 | R23: 支付宝 | S23: 0 | T23: *** | U23: *** | V23: 浙江省 | W23: 丽水市 | X23: 莲都区 | Y23: 岩泉街道 | Z23: *** | AA23: 否 | AC23: 2025-08-31 17:32:37 | AD23: 蓝色 | AE23: 拦截;76740677006606(收） Z2418-灰色-S*1# | AG23: 2025-08-31 17:32:50 | AH23: 抖音 | AI23: 精选联盟 | AJ23: 已关闭 | AK23: 2025-09-15 17:32:50 | AL23: 普通订单 | AM23: 0 | AN23: 2353393836764088 | AO23: 老板周 | AP23: - | AQ23: 退款成功 | AS23: - | AT23: - | AU23: - | AW23: 否 | AX23: 直播 | AY23: 广告 | AZ23: 直播 | BA23: 商城推荐 | BB23: - | BC23: - | BD23: 2025-09-15 10:48:28 | BE23: 0 | BF23: 0 | BG23: 0 | BH23: 0 | BJ23: 否 | BP23: - | BQ23: - | BR23: -
A24: 6945696235709732402 | B24: 6945696235709732402 | C24: 【老板周】复古风格 秋冬新款立体麻花织纹针织毛衣 | D24: 灰色;S(80-100斤);15天内发货 | E24: 1 | F24: 3772185880568135686 | G24: Z2418-灰色-S | H24: 329 | I24: 329 | J24: 0 | K24: 2.05 | L24: - | M24: - | N24: - | O24: 0 | P24: 2.05 | Q24: 0 | R24: 抖音支付 | S24: 0 | T24: *** | U24: *** | V24: 浙江省 | W24: 丽水市 | X24: 青田县 | Y24: 瓯南街道 | Z24: *** | AA24: 否 | AC24: 2025-08-31 17:32:36 | AD24: 灰色 | AF24: 2025-09-22 10:48:28 | AG24: 2025-08-31 17:32:40 | AH24: 抖音 | AI24: 精选联盟 | AJ24: 已完成 | AK24: 2025-09-15 17:32:40 | AL24: 普通订单 | AM24: 0 | AN24: 2353393836764088 | AO24: 老板周 | AP24: - | AQ24: - | AS24: - | AT24: - | AU24: - | AW24: 否 | AX24: 无 | AY24: 其他 | AZ24: 直播 | BA24: 个人主页&店铺&橱窗进入直播间 | BB24: - | BC24: - | BD24: 2025-09-15 10:48:28 | BE24: 0 | BF24: 0 | BG24: 0 | BH24: 0 | BJ24: 否 | BP24: - | BQ24: - | BR24: -
A25: 6921009624776736703 | B25: 6921009624776736703 | C25: 【老板周】复古风格 秋冬新款立体麻花织纹针织毛衣 | D25: 灰色;M(100-120斤);15天内发货 | E25: 1 | F25: 3772185880568135686 | G25: Z2418-灰色-M | H25: 329 | I25: 329 | J25: 0 | K25: 0 | L25: - | M25: - | N25: - | O25: 0 | P25: 0 | Q25: 0 | R25: 抖音支付 | S25: 0 | T25: *** | U25: *** | V25: 江苏省 | W25: 苏州市 | X25: 虎丘区 | Y25: 东渚街道 | Z25: *** | AA25: 否 | AC25: 2025-08-31 17:32:33 | AD25: 灰色 | AG25: 2025-08-31 17:32:38 | AH25: 抖音 | AI25: 精选联盟 | AJ25: 已关闭 | AK25: 2025-09-15 17:32:39 | AL25: 普通订单 | AM25: 0 | AN25: 2353393836764088 | AO25: 老板周 | AP25: - | AQ25: 退款成功 | AS25: - | AT25: - | AU25: - | AW25: 否 | AX25: 无 | AY25: 其他 | AZ25: 直播 | BA25: 关注来源 | BB25: - | BC25: - | BE25: 0 | BF25: 0 | BG25: 0 | BH25: 0 | BJ25: 否 | BP25: - | BQ25: - | BR25: -
A26: 6921013958667763428 | B26: 6921013958667763428 | C26: 【老板周】复古风格 秋冬新款立体麻花织纹针织毛衣 | D26: 灰色;S(80-100斤);15天内发货 | E26: 1 | F26: 3772185880568135686 | G26: Z2418-灰色-S | H26: 329 | I26: 329 | J26: 0 | K26: 0 | L26: - | M26: - | N26: - | O26: 0 | P26: 0 | Q26: 0 | R26: 支付宝 | S26: 0 | T26: *** | U26: *** | V26: 贵州省 | W26: 贵阳市 | X26: 南明区 | Y26: 中曹司街道 | Z26: *** | AA26: 否 | AC26: 2025-08-31 17:32:31 | AD26: 灰色 | AG26: 2025-08-31 17:32:38 | AH26: 抖音 | AI26: 精选联盟 | AJ26: 已关闭 | AK26: 2025-09-15 17:32:38 | AL26: 普通订单 | AM26: 0 | AN26: 2353393836764088 | AO26: 老板周 | AP26: - | AQ26: 退款成功 | AS26: - | AT26: - | AU26: - | AW26: 否 | AX26: 无 | AY26: 其他 | AZ26: 直播 | BA26: 直播推荐 | BB26: - | BC26: - | BE26: 0 | BF26: 0 | BG26: 0 | BH26: 0 | BJ26: 否 | BP26: - | BQ26: - | BR26: -
A27: 6945698443959669805 | B27: 6945698443959669805 | C27: 【老板周】日系极简 春季新品圆领简约设计感无袖马甲 | D27: 黑色;L(120-135斤);15天内发货 | E27: 1 | F27: 3767004410471907465 | G27: Z1640-黑色-L | H27: 289 | I27: 314 | J27: 25 | K27: 0 | L27: - | M27: - | N27: - | O27: 0 | P27: 0 | Q27: 0 | R27: 抖音月付 | S27: 0 | T27: *** | U27: *** | V27: 陕西省 | W27: 咸阳市 | X27: 渭城区 | Y27: 周陵街道 | Z27: *** | AA27: 否 | AC27: 2025-08-31 16:17:00 | AD27: 灰色 | AF27: 2025-09-19 16:35:27 | AG27: 2025-08-31 16:17:05 | AH27: 抖音 | AI27: 精选联盟 | AJ27: 已完成 | AK27: 2025-09-15 16:17:05 | AL27: 普通订单 | AM27: 0 | AN27: 2353393836764088 | AO27: 老板周 | AP27: - | AQ27: - | AS27: - | AT27: - | AU27: - | AW27: 否 | AX27: 无 | AY27: 其他 | AZ27: 直播 | BA27: 直播推荐 | BB27: - | BC27: - | BD27: 2025-09-12 16:35:27 | BE27: 0 | BF27: 0 | BG27: 0 | BH27: 0 | BJ27: 否 | BP27: - | BQ27: - | BR27: -
A28: 6945649067193472893 | B28: 6945649067193472893 | C28: 【老板周】日系极简 春季新品圆领简约设计感无袖马甲 | D28: 黑色;S(80-100斤);15天内发货 | E28: 1 | F28: 3767004410471907465 | G28: Z1640-黑色-S | H28: 289 | I28: 254.06 | J28: 0 | K28: 35.86 | L28: 平台七夕消费券-34.94 | M28: - | N28: - | O28: 0 | P28: 0.92 | Q28: 0 | R28: 抖音支付 | S28: 0 | T28: *** | U28: *** | V28: 辽宁省 | W28: 大连市 | X28: 中山区 | Y28: - | Z28: *** | AA28: 否 | AC28: 2025-08-29 20:47:38 | AD28: 灰色 | AE28: (收)[Z1640-黑色-S]*[1]# | AF28: 2025-09-18 23:58:12 | AG28: 2025-08-29 20:47:40 | AH28: 抖音 | AI28: 精选联盟 | AJ28: 已完成 | AK28: 2025-09-13 20:47:41 | AL28: 普通订单 | AM28: 0 | AN28: 2353393836764088 | AO28: 老板周 | AP28: - | AQ28: 退款成功 | AS28: - | AT28: - | AU28: - | AW28: 否 | AX28: 无 | AY28: 其他 | AZ28: 直播 | BA28: 搜索 | BB28: - | BC28: - | BD28: 2025-09-11 23:58:12 | BE28: 0 | BF28: 34.94 | BG28: 0 | BH28: 0 | BJ28: 否 | BP28: - | BQ28: - | BR28: -
A29: 6920964153135168659 | B29: 6920964153135168659 | C29: 【老板周】小众休闲 压褶松紧腰宽松百搭裤裙 | D29: 藏蓝色;M(95-110斤);15天内发货 | E29: 1 | F29: 3770653191356678342 | G29: Z575-藏蓝色-M | H29: 299 | I29: 299 | J29: 0 | K29: 0 | L29: - | M29: - | N29: - | O29: 0 | P29: 0 | Q29: 0 | R29: 抖音支付 | S29: 0 | T29: *** | U29: *** | V29: 内蒙古自治区 | W29: 呼和浩特市 | X29: 新城区 | Y29: 成吉思汗大街街道 | Z29: *** | AA29: 否 | AC29: 2025-08-28 22:10:07 | AD29: 灰色 | AH29: 抖音 | AI29: 小店自卖 | AJ29: 已关闭 | AK29: 2025-09-12 22:10:07 | AL29: 普通订单 | AM29: 0 | AN29: 0 | AP29: - | AQ29: - | AR29: 用户超时未支付自动取消 | AS29: - | AT29: - | AU29: - | AW29: 否 | AX29: 无 | AY29: 其他 | AZ29: 商品卡 | BA29: 店铺页面 | BB29: - | BC29: - | BE29: 0 | BF29: 0 | BG29: 0 | BH29: 0 | BJ29: 否 | BP29: - | BQ29: - | BR29: -
A30: 6920966085271780499 | B30: 6920966085271780499 | C30: 【老板周】小众休闲 压褶松紧腰宽松百搭裤裙 | D30: 藏蓝色;M(95-110斤);15天内发货 | E30: 1 | F30: 3770653191356678342 | G30: Z575-藏蓝色-M | H30: 299 | I30: 299 | J30: 0 | K30: 0 | L30: - | M30: - | N30: - | O30: 0 | P30: 0 | Q30: 0 | R30: 抖音支付 | S30: 0 | T30: *** | U30: *** | V30: 内蒙古自治区 | W30: 呼和浩特市 | X30: 新城区 | Y30: 成吉思汗大街街道 | Z30: *** | AA30: 否 | AC30: 2025-08-28 22:09:25 | AD30: 灰色 | AH30: 抖音 | AI30: 小店自卖 | AJ30: 已关闭 | AK30: 2025-09-12 22:09:25 | AL30: 普通订单 | AM30: 0 | AN30: 0 | AP30: - | AQ30: - | AR30: 用户超时未支付自动取消 | AS30: - | AT30: - | AU30: - | AW30: 否 | AX30: 无 | AY30: 其他 | AZ30: 商品卡 | BA30: 店铺页面 | BB30: - | BC30: - | BE30: 0 | BF30: 0 | BG30: 0 | BH30: 0 | BJ30: 否 | BP30: - | BQ30: - | BR30: -
A31: 6945610806981695196 | B31: 6945610806981695196 | C31: 【老板周】日系极简 春季新品圆领简约设计感无袖马甲 | D31: 黑色;M(100-120斤);15天内发货 | E31: 1 | F31: 3767004410471907465 | G31: Z1640-黑色-M | H31: 289 | I31: 260.12 | J31: 0 | K31: 28.88 | L31: 平台七夕消费券-28.88 | M31: - | N31: - | O31: 0 | P31: 0 | Q31: 0 | R31: 抖音月付 | S31: 0 | T31: *** | U31: *** | V31: 河北省 | W31: 邢台市 | X31: 信都区 | Y31: 达活泉街道 | Z31: *** | AA31: 否 | AC31: 2025-08-28 11:04:59 | AD31: 红色 | AE31: SF3234099112861(收） Z1640-黑色-M*1#;换货(6298912)#;换货76743232979811 收到退款 不换货了 | AF31: 2025-09-14 23:31:58 | AG31: 2025-08-28 11:05:06 | AH31: 抖音 | AI31: 精选联盟 | AJ31: 已完成 | AK31: 2025-09-12 11:05:07 | AL31: 普通订单 | AM31: 0 | AN31: 2353393836764088 | AO31: 老板周 | AP31: - | AQ31: 退款成功 | AS31: - | AT31: - | AU31: - | AW31: 否 | AX31: 无 | AY31: 其他 | AZ31: 商品卡 | BA31: 橱窗 | BB31: - | BC31: - | BD31: 2025-09-07 23:31:58 | BE31: 0 | BF31: 28.88 | BG31: 0 | BH31: 0 | BJ31: 否 | BP31: - | BQ31: - | BR31: -
A32: 6920952081164304100 | B32: 6920952081164304100 | C32: 【老板周】日系极简 春季新品圆领简约设计感无袖马甲 | D32: 黑色;M(100-120斤);15天内发货 | E32: 1 | F32: 3767004410471907465 | G32: Z1640-黑色-M | H32: 289 | I32: 289 | J32: 0 | K32: 0 | L32: - | M32: - | N32: - | O32: 0 | P32: 0 | Q32: 0 | R32: 抖音支付 | S32: 0 | T32: *** | U32: *** | V32: 山东省 | W32: 菏泽市 | X32: 牡丹区 | Y32: 牡丹街道 | Z32: *** | AA32: 否 | AC32: 2025-08-28 00:21:12 | AD32: 灰色 | AG32: 2025-08-28 00:21:13 | AH32: 抖音 | AI32: 小店自卖 | AJ32: 已关闭 | AK32: 2025-09-12 00:21:13 | AL32: 普通订单 | AM32: 0 | AN32: 0 | AP32: - | AQ32: 退款成功 | AS32: - | AT32: - | AU32: - | AW32: 否 | AX32: 无 | AY32: 其他 | AZ32: 商品卡 | BA32: 搜索 | BB32: - | BC32: - | BE32: 0 | BF32: 0 | BG32: 0 | BH32: 0 | BJ32: 否 | BP32: - | BQ32: - | BR32: -
A33: 6945587885982618859 | B33: 6945587885982618859 | C33: 【老板周】日系极简 春季新品圆领简约设计感无袖马甲 | D33: 黑色;M(100-120斤);15天内发货 | E33: 1 | F33: 3767004410471907465 | G33: Z1640-黑色-M | H33: 289 | I33: 278 | J33: 0 | K33: 11 | L33: 平台专属限时优惠券-11.00 | M33: - | N33: - | O33: 0 | P33: 0 | Q33: 0 | R33: 抖音支付 | S33: 0 | T33: *** | U33: *** | V33: 山东省 | W33: 青岛市 | X33: 市北区 | Y33: 河西街道 | Z33: *** | AA33: 否 | AC33: 2025-08-27 22:38:33 | AD33: 灰色 | AG33: 2025-08-27 22:38:44 | AH33: 抖音商城版 | AI33: 精选联盟 | AJ33: 已关闭 | AK33: 2025-09-11 22:38:44 | AL33: 普通订单 | AM33: 0 | AN33: 2353393836764088 | AO33: 老板周 | AP33: - | AQ33: 退款成功 | AS33: - | AT33: - | AU33: - | AW33: 否 | AX33: 直播 | AY33: 广告 | AZ33: 直播 | BA33: 商城推荐 | BB33: - | BC33: - | BE33: 0 | BF33: 11 | BG33: 0 | BH33: 0 | BJ33: 否 | BP33: - | BQ33: - | BR33: -
A34: 6945598979942323318 | B34: 6945598979942323318 | C34: 【老板周】日系极简 春季新品圆领简约设计感无袖马甲 | D34: 黑色;M(100-120斤);15天内发货 | E34: 1 | F34: 3767004410471907465 | G34: Z1640-黑色-M | H34: 289 | I34: 289 | J34: 0 | K34: 0 | L34: - | M34: - | N34: - | O34: 0 | P34: 0 | Q34: 0 | R34: 抖音支付 | S34: 0 | T34: *** | U34: *** | V34: 天津市 | W34: 天津市 | X34: 武清区 | Y34: 东蒲洼街道 | Z34: *** | AA34: 否 | AC34: 2025-08-27 22:12:00 | AD34: 灰色 | AF34: 2025-09-14 23:31:58 | AG34: 2025-08-27 22:12:06 | AH34: 头条lite-抖音电商 | AI34: 精选联盟 | AJ34: 已完成 | AK34: 2025-09-11 22:12:06 | AL34: 普通订单 | AM34: 0 | AN34: 2353393836764088 | AO34: 老板周 | AP34: - | AQ34: - | AS34: - | AT34: - | AU34: - | AW34: 否 | AX34: 无 | AY34: 其他 | AZ34: 直播 | BA34: 头条西瓜 | BB34: - | BC34: - | BD34: 2025-09-07 23:31:58 | BE34: 0 | BF34: 0 | BG34: 0 | BH34: 0 | BJ34: 否 | BP34: - | BQ34: - | BR34: -
A35: 6945583048360597411 | B35: 6945583048360597411 | C35: 【老板周】日系极简 春季新品圆领简约设计感无袖马甲 | D35: 黑色;M(100-120斤);15天内发货 | E35: 1 | F35: 3767004410471907465 | G35: Z1640-黑色-M | H35: 289 | I35: 289 | J35: 0 | K35: 0 | L35: - | M35: - | N35: - | O35: 0 | P35: 0 | Q35: 0 | R35: 抖音月付 | S35: 0 | T35: *** | U35: *** | V35: 山东省 | W35: 日照市 | X35: 莒县 | Y35: 城阳街道 | Z35: *** | AA35: 否 | AC35: 2025-08-27 20:47:29 | AD35: 蓝色 | AE35: 73572507159291(收） Z1640-黑色-M*1# | AG35: 2025-08-27 20:47:31 | AH35: 抖音 | AI35: 精选联盟 | AJ35: 已关闭 | AK35: 2025-09-11 20:47:32 | AL35: 普通订单 | AM35: 0 | AN35: 2353393836764088 | AO35: 老板周 | AP35: - | AQ35: 退款成功 | AS35: - | AT35: - | AU35: - | AW35: 否 | AX35: 无 | AY35: 其他 | AZ35: 直播 | BA35: 直播推荐 | BB35: - | BC35: - | BD35: 2025-09-07 23:31:58 | BE35: 0 | BF35: 0 | BG35: 0 | BH35: 0 | BJ35: 否 | BP35: - | BQ35: - | BR35: -
