Workbook

Sheet 订单明细
A1: 订单号 | B1: 订单状态 | C1: 售后状态 | D1: 订单类型 | E1: 订单标记 | F1: 收件人姓名 | G1: 收件人电话 | H1: 收件人地址 | I1: 省 | J1: 市 | K1: 区 | L1: 区域编码 | M1: 小红书编码 | N1: 条形码 | O1: 规格ID | P1: 达人ID | Q1: 达人名称 | R1: SKU名称 | S1: SKU规格 | T1: SKU件数 | U1: 是否为赠品 | V1: 发票/Invoice | W1: 商品总价(元) | X1: 用户应付金额(元) | Y1: 平台优惠(元) | Z1: 店铺优惠(元) | AA1: 支付渠道优惠(元) | AB1: SKU商家改价(元) | AC1: 商家应收金额(元)（支付金额） | AD1: 支付方式 | AE1: 支付渠道订单号 | AF1: 支付期数 | AG1: 利息费用 | AH1: 手续费承担方 | AI1: 支付时间 | AJ1: sku净重(kg) | AK1: 包裹总净重(kg) | AL1: 包裹总运费(元) | AM1: 快递公司 | AN1: 快递单号 | AO1: 大头笔/Paint Marker | AP1: 集包地/Express Extend 1 | AQ1: 三段码/Express Extend 2 | AR1: 订购人身份证姓名/ID Name | AS1: 订购人身份证号/ID Number | AT1: 收件人身份证姓名 | AU1: 收件人身份证号 | AV1: 订单创建时间 | AW1: 预售订单开始发货时间 | AX1: 预售订单截止发货时间 | AY1: 承诺发货时间 | AZ1: 订单发货时间 | BA1: 订单完成时间 | BB1: 发货仓库 | BC1: 确认收货类型 | BD1: 是否延迟收货 | BE1: 用户备注 | BF1: 包裹备注标记 | BG1: 包裹备注信息 | BH1: 异常原因 | BI1: 店铺名称 | BJ1: 用户编号 | BK1: 运费模版名称 | BL1: 物流方案名称 | BM1: 第三方机构订单号 | BN1: 国补模式 | BO1: 供应商id | BP1: 供应商名称 | BQ1: 商家编码 | BR1: 商品ID | BS1: 商品名称
A2: P771683143371443691 | B2: 已完成 | C2: 无售后 | D2: 预售订单 | F2: 陆* | G2: 199****2821 | H2: 上海 上海市 宝山区 *** | I2: 上海 | J2: 上海市 | K2: 宝山区 | L2: 310113111000 | M2: 6894ac11aa1e7b001555658f | N2: XHS-3IRER6T45U68 | O2: 6894ac11aa1e7b001555658e | R2: 【老板周】复古老钱 新品小众宽松时髦腰果花松紧腰休闲裤 花色 M（100-120斤） | S2: 花色 M（100-120斤） | T2: 1 | W2: 249.00 | X2: 249.00 | Y2: 0.00 | Z2: 0.00 | AB2: 0.00 | AC2: 249.00 | AD2: 微信 | AE2: 4350802247202508259221136879 | AI2: 2025-08-25 22:12:30 | AK2: 0.000 | AL2: 0.00 | AM2: 中通速递 | AN2: 73569586895536 | AV2: 2025-08-25 22:12:23 | AY2: 2025-09-09 22:12:30 | AZ2: 2025-08-25 22:56:08 | BA2: 2025-08-27 16:51:27 | BB2: 第三方平台卖家电子库存 | BC2: 用户确认收货 | BD2: 否 | BI2: LAO BAN ZHOU的店 | BJ2: 5661009c5e87e718219897ac | BK2: 公司店运费模版 | BL2: 小红书公司 | BQ2: Z2338-花色-M | BR2: 6894ac11aa1e7b001555658b | BS2: 【老板周】复古老钱 新品小众宽松时髦腰果花松紧腰休闲裤
A3: P771601056297099071 | B3: 已关闭 | C3: 售后完成 | D3: 预售订单 | F3: 史* | G3: 135****5235 | H3: 广东省 江门市 江海区 *** | I3: 广东省 | J3: 江门市 | K3: 江海区 | L3: 440704001 | M3: 6894b76bf735ce00153807e6 | N3: XHS-3I9QHHLHJ400 | O3: 6894b76bf735ce00153807e5 | R3: 【老板周】慵懒慵 秋冬新款复古撞色条纹松弛感毛衣 条纹 S（80-100斤） | S3: 条纹 S（80-100斤） | T3: 1 | W3: 289.00 | X3: 289.00 | Y3: 0.00 | Z3: 0.00 | AB3: 0.00 | AC3: 289.00 | AD3: 微信 | AE3: 4302302286202508243205233952 | AI3: 2025-08-24 23:24:26 | AK3: 0.000 | AL3: 0.00 | AM3: 中通速递 | AN3: 73569436349866 | AV3: 2025-08-24 23:24:16 | AY3: 2025-09-08 23:24:26 | AZ3: 2025-08-24 23:44:31 | BB3: 第三方平台卖家电子库存 | BD3: 否 | BF3: 蓝旗 | BG3: ;SF3230026344337(收） Z2271-条纹-S*1# | BI3: LAO BAN ZHOU的店 | BJ3: 67603dc70000000018015c4e | BK3: 公司店运费模版 | BL3: 小红书公司 | BQ3: Z2271-条纹-S | BR3: 6894b76bf735ce00153807e4 | BS3: 【老板周】慵懒慵 秋冬新款复古撞色条纹松弛感毛衣
A4: P771077302074017641 | B4: 已完成 | C4: 无售后 | D4: 预售订单 | E4: 物流异常 | F4: 周* | G4: 150****4975 | H4: 内蒙古自治区 鄂尔多斯市 康巴什区 *** | I4: 内蒙古自治区 | J4: 鄂尔多斯市 | K4: 康巴什区 | L4: 150603 | M4: 6896fe0c6d08080015500893 | N4: XHS-3EHYVMD8SZR4 | O4: 6896fe0c6d08080015500892 | P4: 650d6e9f000000001603a6ac | Q4: 老板周. | R4: 【老板周】夏季轻盈 新品圆领气质轻薄不规则透气上衣 黑色 M（80-100斤） | S4: 黑色 M（80-100斤） | T4: 1 | W4: 129.00 | X4: 129.00 | Y4: 0.00 | Z4: 0.00 | AB4: 0.00 | AC4: 129.00 | AD4: 微信 | AE4: 4337602246202508189619352845 | AI4: 2025-08-18 21:55:09 | AK4: 0.000 | AL4: 0.00 | AM4: 中通速递 | AN4: 73568731918406 | AV4: 2025-08-18 21:55:02 | AY4: 2025-09-02 21:55:09 | AZ4: 2025-08-19 22:18:12 | BA4: 2025-08-26 22:18:12 | BB4: 第三方平台卖家电子库存 | BC4: 系统自动收货 | BD4: 否 | BF4: 蓝旗 | BG4: 拦截;73568592691278(收） Z2183-米白色-M*1# | BI4: LAO BAN ZHOU的店 | BJ4: 5f8e45b90000000001001f97 | BK4: 公司店运费模版 | BL4: 小红书公司 | BQ4: Z2183-黑色-M | BR4: 6896fe0c6d08080015500891 | BS4: 【老板周】夏季轻盈 新品圆领气质轻薄不规则透气上衣
A5: P771077302074017641 | B5: 已完成 | C5: 售后完成 | D5: 预售订单 | E5: 物流异常 | F5: 周* | G5: 150****4975 | H5: 内蒙古自治区 鄂尔多斯市 康巴什区 *** | I5: 内蒙古自治区 | J5: 鄂尔多斯市 | K5: 康巴什区 | L5: 150603 | M5: 6896fe0c6d08080015500899 | N5: XHS-3EHYVMDNSDTS | O5: 6896fe0c6d08080015500898 | P5: 650d6e9f000000001603a6ac | Q5: 老板周. | R5: 【老板周】夏季轻盈 新品圆领气质轻薄不规则透气上衣 米白色 M（80-100斤） | S5: 米白色 M（80-100斤） | T5: 1 | W5: 129.00 | X5: 129.00 | Y5: 0.00 | Z5: 0.00 | AB5: 0.00 | AC5: 129.00 | AD5: 微信 | AE5: 4337602246202508189619352845 | AI5: 2025-08-18 21:55:09 | AK5: 0.000 | AL5: 0.00 | AM5: 中通速递 | AN5: 73568592691278 | AV5: 2025-08-18 21:55:02 | AY5: 2025-09-02 21:55:09 | AZ5: 2025-08-18 22:55:40 | BB5: 第三方平台卖家电子库存 | BD5: 否 | BF5: 蓝旗 | BG5: 拦截;73568592691278(收） Z2183-米白色-M*1# | BI5: LAO BAN ZHOU的店 | BJ5: 5f8e45b90000000001001f97 | BK5: 公司店运费模版 | BL5: 小红书公司 | BQ5: Z2183-米白色-M | BR5: 6896fe0c6d08080015500891 | BS5: 【老板周】夏季轻盈 新品圆领气质轻薄不规则透气上衣
A6: P770990197404134041 | B6: 已关闭 | C6: 售后完成 | D6: 预售订单 | F6: 陈** | G6: 138****3883 | H6: 上海 上海市 长宁区 *** | I6: 上海 | J6: 上海市 | K6: 长宁区 | L6: 310105011000 | M6: 68949ffbc34eef001610ef47 | N6: XHS-3HO32A90HCZK | O6: 68949ffbc34eef001610ef46 | P6: 650d6e9f000000001603a6ac | Q6: 老板周. | R6: 【老板周】夏季新款 小众轻盈空气感重工泡泡绉小飞袖上衣 黑色 M（100-120斤） | S6: 黑色 M（100-120斤） | T6: 1 | W6: 339.00 | X6: 339.00 | Y6: 0.00 | Z6: 0.00 | AB6: 0.00 | AC6: 339.00 | AD6: 微信 | AE6: 4307502582202508176171663706 | AI6: 2025-08-17 21:43:23 | AK6: 0.000 | AL6: 0.00 | AM6: 中通速递 | AN6: 73568587025232 | AV6: 2025-08-17 21:43:17 | AY6: 2025-09-01 21:43:23 | AZ6: 2025-08-18 21:23:31 | BA6: 2025-08-25 21:23:33 | BB6: 第三方平台卖家电子库存 | BC6: 系统自动收货 | BD6: 否 | BF6: 蓝旗 | BG6: ;SF3230107717291(收） Z2308-黑色-M*1# | BI6: LAO BAN ZHOU的店 | BJ6: 5ef987090000000001001e3d | BK6: 公司店运费模版 | BL6: 小红书公司 | BQ6: Z2308-黑色-M | BR6: 68949ffbc34eef001610ef43 | BS6: 【老板周】夏季新款 小众轻盈空气感重工泡泡绉小飞袖上衣
A7: P770990615215304131 | B7: 已关闭 | C7: 售后完成 | D7: 预售订单 | F7: 何* | G7: 189****1661 | H7: 湖南省 长沙市 雨花区 *** | I7: 湖南省 | J7: 长沙市 | K7: 雨花区 | L7: 430111 | M7: 6896e3fdd48cf90015433efb | N7: XHS-3G6Z6JI0FO5C | O7: 6896e3fdd48cf90015433efa | P7: 650d6e9f000000001603a6ac | Q7: 老板周. | R7: 【老板周】休闲腔调 夏季薄款圆领口袋设计百搭三角T恤 黄绿色 S（80-100斤） | S7: 黄绿色 S（80-100斤） | T7: 1 | W7: 269.00 | X7: 269.00 | Y7: 0.00 | Z7: 0.00 | AB7: 0.00 | AC7: 269.00 | AD7: 支付宝 | AE7: 2025081722001438351419440818 | AI7: 2025-08-17 21:50:20 | AK7: 0.000 | AL7: 0.00 | AM7: 中通速递 | AN7: 73568444482820 | AV7: 2025-08-17 21:50:15 | AY7: 2025-09-01 21:50:20 | AZ7: 2025-08-17 22:55:10 | BA7: 2025-08-24 22:55:11 | BB7: 第三方平台卖家电子库存 | BC7: 系统自动收货 | BD7: 否 | BF7: 蓝旗 | BG7: 肩膀勾线;SF3230325430957(收） Z2233-黄绿色-S*1# | BI7: LAO BAN ZHOU的店 | BJ7: 5bde6c50d9463d00012dd3b7 | BK7: 公司店运费模版 | BL7: 小红书公司 | BQ7: Z2233-黄绿色-S | BR7: 6896e3fdd48cf90015433eed | BS7: 【老板周】休闲腔调 夏季薄款圆领口袋设计百搭三角T恤
A8: P770986869946371481 | B8: 已关闭 | C8: 售后完成 | D8: 预售订单 | F8: 刘** | G8: 158****3237 | H8: 陕西省 西安市 新城区 *** | I8: 陕西省 | J8: 西安市 | K8: 新城区 | L8: 610102007 | M8: 689704bae53c1000157cfa9f | N8: XHS-3FAGCOT1V85C | O8: 689704bae53c1000157cfa9e | P8: 650d6e9f000000001603a6ac | Q8: 老板周. | R8: 【老板周】法式随性 夏季时髦叠门襟无袖设计感开叉马甲 黑色 M（100-120斤） | S8: 黑色 M（100-120斤） | T8: 1 | W8: 229.00 | X8: 229.00 | Y8: 0.00 | Z8: 0.00 | AB8: 0.00 | AC8: 229.00 | AD8: 微信 | AE8: 4306702271202508170222076938 | AI8: 2025-08-17 20:47:56 | AK8: 0.000 | AL8: 0.00 | AM8: 中通速递 | AN8: 73568441965438 | AV8: 2025-08-17 20:47:50 | AY8: 2025-09-01 20:47:56 | AZ8: 2025-08-17 21:32:26 | BA8: 2025-08-24 21:32:26 | BB8: 第三方平台卖家电子库存 | BC8: 系统自动收货 | BD8: 否 | BF8: 蓝旗 | BG8: ;SF3289318820600(收） Z2218-黑色-S*1 Z2218-黑色-M*1# | BI8: LAO BAN ZHOU的店 | BJ8: 5c793a590000000010012874 | BK8: 公司店运费模版 | BL8: 小红书公司 | BQ8: Z2218-黑色-M | BR8: 689704bae53c1000157cfa9b | BS8: 【老板周】法式随性 夏季时髦叠门襟无袖设计感开叉马甲
A9: P770986869946371481 | B9: 已关闭 | C9: 售后完成 | D9: 预售订单 | F9: 刘** | G9: 158****3237 | H9: 陕西省 西安市 新城区 *** | I9: 陕西省 | J9: 西安市 | K9: 新城区 | L9: 610102007 | M9: 689704bae53c1000157cfa9d | N9: XHS-3FAGCOSWVFGG | O9: 689704bae53c1000157cfa9c | P9: 650d6e9f000000001603a6ac | Q9: 老板周. | R9: 【老板周】法式随性 夏季时髦叠门襟无袖设计感开叉马甲 黑色 S（80-100斤） | S9: 黑色 S（80-100斤） | T9: 1 | W9: 229.00 | X9: 229.00 | Y9: 0.00 | Z9: 0.00 | AB9: 0.00 | AC9: 229.00 | AD9: 微信 | AE9: 4306702271202508170222076938 | AI9: 2025-08-17 20:47:56 | AK9: 0.000 | AL9: 0.00 | AM9: 中通速递 | AN9: 73568576683034 | AV9: 2025-08-17 20:47:50 | AY9: 2025-09-01 20:47:56 | AZ9: 2025-08-18 19:43:07 | BA9: 2025-08-25 19:43:08 | BB9: 第三方平台卖家电子库存 | BC9: 系统自动收货 | BD9: 否 | BF9: 蓝旗 | BG9: ;SF3289318820600(收） Z2218-黑色-S*1 Z2218-黑色-M*1# | BI9: LAO BAN ZHOU的店 | BJ9: 5c793a590000000010012874 | BK9: 公司店运费模版 | BL9: 小红书公司 | BQ9: Z2218-黑色-S | BR9: 689704bae53c1000157cfa9b | BS9: 【老板周】法式随性 夏季时髦叠门襟无袖设计感开叉马甲
A10: P770986580251454261 | B10: 已关闭 | C10: 售后完成 | D10: 预售订单 | F10: 王** | G10: 157****7660 | H10: 甘肃省 兰州市 安宁区 *** | I10: 甘肃省 | J10: 兰州市 | K10: 安宁区 | L10: 620105 | M10: 689704bae53c1000157cfa9d | N10: XHS-3FAGCOSWVFGG | O10: 689704bae53c1000157cfa9c | P10: 650d6e9f000000001603a6ac | Q10: 老板周. | R10: 【老板周】法式随性 夏季时髦叠门襟无袖设计感开叉马甲 黑色 S（80-100斤） | S10: 黑色 S（80-100斤） | T10: 1 | W10: 229.00 | X10: 229.00 | Y10: 0.00 | Z10: 0.00 | AB10: 0.00 | AC10: 229.00 | AD10: 微信 | AE10: 4336802247202508170250305747 | AI10: 2025-08-17 20:43:06 | AK10: 0.000 | AL10: 0.00 | AM10: 中通速递 | AN10: 73568556568537 | AV10: 2025-08-17 20:43:00 | AY10: 2025-09-01 20:43:06 | AZ10: 2025-08-18 17:29:30 | BA10: 2025-08-25 17:29:30 | BB10: 第三方平台卖家电子库存 | BC10: 系统自动收货 | BD10: 否 | BF10: 蓝旗 | BG10: ;JDX042496871681(收） Z2218-黑色-S*1# | BI10: LAO BAN ZHOU的店 | BJ10: 5a966dd7e8ac2b762a5a6e20 | BK10: 公司店运费模版 | BL10: 小红书公司 | BQ10: Z2218-黑色-S | BR10: 689704bae53c1000157cfa9b | BS10: 【老板周】法式随性 夏季时髦叠门襟无袖设计感开叉马甲
A11: P770984511919250241 | B11: 已关闭 | C11: 售后完成 | D11: 预售订单 | F11: 玉** | G11: 139****3111 | H11: 辽宁省 沈阳市 浑南区 *** | I11: 辽宁省 | J11: 沈阳市 | K11: 浑南区 | L11: 210112 | M11: 689704bae53c1000157cfaa1 | N11: XHS-3FAGCOT6V0U8 | O11: 689704bae53c1000157cfaa0 | P11: 650d6e9f000000001603a6ac | Q11: 老板周. | R11: 【老板周】法式随性 夏季时髦叠门襟无袖设计感开叉马甲 黑色 L（120-135斤） | S11: 黑色 L（120-135斤） | T11: 1 | W11: 229.00 | X11: 229.00 | Y11: 0.00 | Z11: 0.00 | AB11: 0.00 | AC11: 229.00 | AD11: 银联 | AE11: 432508172008322427418 | AI11: 2025-08-17 20:08:37 | AK11: 0.000 | AL11: 0.00 | AM11: 中通速递 | AN11: 73568436568058 | AV11: 2025-08-17 20:08:32 | AY11: 2025-09-01 20:08:37 | AZ11: 2025-08-17 20:35:14 | BA11: 2025-08-24 20:35:14 | BB11: 第三方平台卖家电子库存 | BC11: 系统自动收货 | BD11: 否 | BF11: 蓝旗 | BG11: ;73569281821300(收） Z2218-黑色-L*1# | BI11: LAO BAN ZHOU的店 | BJ11: 5abc9bade8ac2b23030f3e59 | BK11: 公司店运费模版 | BL11: 小红书公司 | BQ11: Z2218-黑色-L | BR11: 689704bae53c1000157cfa9b | BS11: 【老板周】法式随性 夏季时髦叠门襟无袖设计感开叉马甲
A12: P770983921263440451 | B12: 已完成 | C12: 售后完成 | D12: 预售订单 | F12: 王** | G12: 186****8688 | H12: 内蒙古自治区 呼伦贝尔市 海拉尔区 *** | I12: 内蒙古自治区 | J12: 呼伦贝尔市 | K12: 海拉尔区 | L12: 150702101000 | M12: 689704bae53c1000157cfaa1 | N12: XHS-3FAGCOT6V0U8 | O12: 689704bae53c1000157cfaa0 | P12: 650d6e9f000000001603a6ac | Q12: 老板周. | R12: 【老板周】法式随性 夏季时髦叠门襟无袖设计感开叉马甲 黑色 L（120-135斤） | S12: 黑色 L（120-135斤） | T12: 1 | W12: 229.00 | X12: 229.00 | Y12: 0.00 | Z12: 0.00 | AB12: 0.00 | AC12: 229.00 | AD12: 支付宝 | AE12: 2025081722001445001452299017 | AI12: 2025-08-17 19:58:48 | AK12: 0.000 | AL12: 0.00 | AM12: 中通速递 | AN12: 73568436950563 | AV12: 2025-08-17 19:58:41 | AY12: 2025-09-01 19:58:48 | AZ12: 2025-08-17 20:35:14 | BA12: 2025-08-24 20:35:14 | BB12: 第三方平台卖家电子库存 | BC12: 系统自动收货 | BD12: 否 | BF12: 蓝旗 | BG12: ;SF3280467567718(收） Z2218-黑色-L*1# | BI12: LAO BAN ZHOU的店 | BJ12: 5a2552fd4eacab6a98c94bb1 | BK12: 公司店运费模版 | BL12: 小红书公司 | BQ12: Z2218-黑色-L | BR12: 689704bae53c1000157cfa9b | BS12: 【老板周】法式随性 夏季时髦叠门襟无袖设计感开叉马甲
A13: P770822898182284051 | B13: 已关闭 | C13: 售后完成 | D13: 预售订单 | F13: 何 | G13: 135****0291 | H13: 湖南省 长沙市 岳麓区 *** | I13: 湖南省 | J13: 长沙市 | K13: 岳麓区 | L13: 430104005 | M13: 689dee3bbc668f00150ae4a2 | N13: XHS-3JY88WA16VWG | O13: 689dee3bbc668f00150ae4a1 | P13: 650d6e9f000000001603a6ac | Q13: 老板周. | R13: 【老板周】经典慵懒 秋季经典撞色条纹镂空针织上衣 黑白条纹 M（100-135斤） | S13: 黑白条纹 M（100-135斤） | T13: 1 | W13: 219.00 | X13: 219.00 | Y13: 0.00 | Z13: 0.00 | AB13: 0.00 | AC13: 219.00 | AD13: 支付宝 | AE13: 2025081522001457781456456422 | AI13: 2025-08-15 23:15:05 | AK13: 0.000 | AL13: 0.00 | AM13: 中通速递 | AN13: 73568875427704 | AV13: 2025-08-15 23:14:58 | AY13: 2025-08-30 23:15:05 | AZ13: 2025-08-21 00:20:35 | BB13: 第三方平台卖家电子库存 | BD13: 否 | BF13: 蓝旗 | BG13: ;SF3289575962710(收） Z2376-黑白条纹-M*1# | BI13: LAO BAN ZHOU的店 | BJ13: 5c1a271e000000000703e641 | BK13: 公司店运费模版 | BL13: 小红书公司 | BQ13: Z2376-黑白条纹-M | BR13: 689dee3bbc668f00150ae49e | BS13: 【老板周】经典慵懒 秋季经典撞色条纹镂空针织上衣
A14: P770821520016218311 | B14: 已完成 | C14: 无售后 | D14: 预售订单 | F14: 王* | G14: 138****7966 | H14: 福建省 三明市 沙县区 *** | I14: 福建省 | J14: 三明市 | K14: 沙县区 | L14: 350405 | M14: 689dee5baa1e7b00156ae7c1 | N14: XHS-3JY9LAG89YPS | O14: 689dee5baa1e7b00156ae7c0 | P14: 650d6e9f000000001603a6ac | Q14: 老板周. | R14: LAO BAN ZHOU 【老板周】极简主义 秋冬新款复古卷边前短后长针织上衣 灰色 S（80-100斤） | S14: 灰色 S（80-100斤） | T14: 1 | W14: 219.00 | X14: 219.00 | Y14: 0.00 | Z14: 0.00 | AB14: 0.00 | AC14: 219.00 | AD14: 微信先用后付 | AI14: 2025-08-15 22:52:00 | AK14: 0.000 | AL14: 0.00 | AM14: 中通速递 | AN14: 73569287102336 | AV14: 2025-08-15 22:52:00 | AY14: 2025-08-30 22:52:00 | AZ14: 2025-08-25 19:55:00 | BA14: 2025-08-27 17:10:53 | BB14: 第三方平台卖家电子库存 | BC14: 用户确认收货 | BD14: 否 | BI14: LAO BAN ZHOU的店 | BJ14: 573725d782ec392b7aac36a5 | BK14: 公司店运费模版 | BL14: 小红书公司 | BQ14: Z2365-灰色-S | BR14: 689dee5baa1e7b00156ae7bb | BS14: 【老板周】极简主义 秋冬新款复古卷边前短后长针织上衣
A15: P770818894631507761 | B15: 已完成 | C15: 无售后 | D15: 预售订单 | F15: 毛 | G15: 188****0712 | H15: 上海 上海市 杨浦区 *** | I15: 上海 | J15: 上海市 | K15: 杨浦区 | L15: 310110006 | M15: 689dee541ea4cb00155e6f97 | N15: XHS-3JY9BQCVPTDS | O15: 689dee541ea4cb00155e6f96 | P15: 650d6e9f000000001603a6ac | Q15: 老板周. | R15: LAO BAN ZHOU 【老板周】百搭气质 秋冬新款百搭造型感气质三角巾 藏青色 | S15: 藏青色 | T15: 1 | W15: 199.00 | X15: 199.00 | Y15: 0.00 | Z15: 0.00 | AB15: 0.00 | AC15: 199.00 | AD15: 支付宝免密 | AE15: 2025081522001459511443799810 | AI15: 2025-08-15 22:08:16 | AK15: 0.000 | AL15: 0.00 | AM15: 中通速递 | AN15: 73569428130248 | AV15: 2025-08-15 22:08:14 | AY15: 2025-08-30 22:08:16 | AZ15: 2025-08-24 21:27:21 | BA15: 2025-08-27 08:52:15 | BB15: 第三方平台卖家电子库存 | BC15: 用户确认收货 | BD15: 否 | BI15: LAO BAN ZHOU的店 | BJ15: 5aaaf92e4eacab0922af9f62 | BK15: 公司店运费模版 | BL15: 小红书公司 | BQ15: Z2380-藏青色 | BR15: 689dee541ea4cb00155e6f93 | BS15: 【老板周】百搭气质 秋冬新款百搭造型感气质三角巾
A16: P770818846205191671 | B16: 已完成 | C16: 无售后 | D16: 预售订单 | F16: 方* | G16: 199****7277 | H16: 山东省 日照市 东港区 *** | I16: 山东省 | J16: 日照市 | K16: 东港区 | L16: 371102008000 | M16: 6896fe48057f570015d29245 | N16: XHS-2Z0D3J1YAL8G | O16: 6896fe48057f570015d29244 | P16: 650d6e9f000000001603a6ac | Q16: 老板周. | R16: 【老板周】时髦撞色 春季新款假两件显瘦长袖打底T恤上衣 黑色 M（100-120斤） | S16: 黑色 M（100-120斤） | T16: 1 | W16: 199.00 | X16: 199.00 | Y16: 0.00 | Z16: 0.00 | AB16: 0.00 | AC16: 199.00 | AD16: 支付宝 | AE16: 2025081522001446921455566706 | AI16: 2025-08-15 22:07:36 | AK16: 0.000 | AL16: 0.00 | AM16: 中通速递 | AN16: 73569429601749 | AV16: 2025-08-15 22:07:26 | AY16: 2025-08-30 22:07:36 | AZ16: 2025-08-24 21:24:18 | BA16: 2025-08-27 16:15:17 | BB16: 第三方平台卖家电子库存 | BC16: 用户确认收货 | BD16: 否 | BI16: LAO BAN ZHOU的店 | BJ16: 5b219a89e8ac2b2d65a2a890 | BK16: 公司店运费模版 | BL16: 小红书公司 | BQ16: Z1576-黑色-M | BR16: 6896fe48057f570015d29241 | BS16: 【老板周】时髦撞色 春季新款假两件显瘦长袖打底T恤上衣
A17: P770817653033321541 | B17: 已关闭 | C17: 售后完成 | D17: 预售订单 | F17: 铁 | G17: 188****9286 | H17: 浙江省 绍兴市 诸暨市 *** | I17: 浙江省 | J17: 绍兴市 | K17: 诸暨市 | L17: 330681005000 | M17: 6896fe67c165480015b3eb01 | N17: XHS-2Z4TJTXW55OG | O17: 6896fe67c165480015b3eb00 | R17: 【老板周】舒适休闲 极简短版腰头抽绳设计宽松半身裙 黑色 S（80-100斤） | S17: 黑色 S（80-100斤） | T17: 1 | W17: 189.00 | X17: 189.00 | Y17: 0.00 | Z17: 0.00 | AB17: 0.00 | AC17: 189.00 | AD17: 支付宝 | AE17: 2025081522001420121433136963 | AI17: 2025-08-15 21:48:31 | AK17: 0.000 | AL17: 0.00 | AM17: 中通速递 | AN17: 73569255709053 | AV17: 2025-08-15 21:47:33 | AY17: 2025-08-30 21:48:31 | AZ17: 2025-08-23 17:27:48 | BB17: 第三方平台卖家电子库存 | BD17: 否 | BF17: 蓝旗 | BG17: ;78934215260877(收） Z1645-黑色-S*1# | BI17: LAO BAN ZHOU的店 | BJ17: 5b5c85dbe8ac2b5d1dc7f406 | BK17: 公司店运费模版 | BL17: 小红书公司 | BQ17: Z1645-黑色-S | BR17: 6896fe67c165480015b3eaff | BS17: 【老板周】舒适休闲 极简短版腰头抽绳设计宽松半身裙
A18: P770815073365177321 | B18: 已关闭 | C18: 售后完成 | D18: 预售订单 | F18: 朱** | G18: 133****6756 | H18: 江苏省 常州市 钟楼区 *** | I18: 江苏省 | J18: 常州市 | K18: 钟楼区 | L18: 320404002 | M18: 689dee45c34eef00157e1208 | N18: XHS-3JY8RM3UZL6O | O18: 689dee45c34eef00157e1207 | P18: 650d6e9f000000001603a6ac | Q18: 老板周. | R18: 【老板周】小众日系 秋冬叠穿时髦下摆不规则宽松马甲 灰色 S（80-100斤） | S18: 灰色 S（80-100斤） | T18: 1 | W18: 179.00 | X18: 179.00 | Y18: 0.00 | Z18: 0.00 | AB18: 0.00 | AC18: 179.00 | AD18: 微信 | AE18: 4347802469202508151936939245 | AI18: 2025-08-15 21:04:40 | AK18: 0.000 | AL18: 0.00 | AM18: 中通速递 | AN18: 73569144709848 | AV18: 2025-08-15 21:04:33 | AY18: 2025-08-30 21:04:40 | AZ18: 2025-08-22 21:16:10 | BB18: 第三方平台卖家电子库存 | BD18: 否 | BF18: 蓝旗 | BG18: ;JDX042510841197(收） Z2378-灰色-S*1# | BI18: LAO BAN ZHOU的店 | BJ18: 5ae3fc4211be1062fa142bc7 | BK18: 公司店运费模版 | BL18: 小红书公司 | BQ18: Z2378-灰色-S | BR18: 689dee45c34eef00157e11fa | BS18: 【老板周】小众日系 秋冬叠穿时髦下摆不规则宽松马甲
A19: P770813889954234671 | B19: 已关闭 | C19: 售后完成 | D19: 预售订单 | F19: 仇** | G19: 139****2227 | H19: 天津 天津市 滨海新区 *** | I19: 天津 | J19: 天津市 | K19: 滨海新区 | L19: 120116 | M19: 689dee5baa1e7b00156ae7bd | N19: XHS-3JY9LAG0S9OG | O19: 689dee5baa1e7b00156ae7bc | P19: 650d6e9f000000001603a6ac | Q19: 老板周. | R19: LAO BAN ZHOU 【老板周】极简主义 秋冬新款复古卷边前短后长针织上衣 黑色 S（80-100斤） | S19: 黑色 S（80-100斤） | T19: 1 | W19: 219.00 | X19: 219.00 | Y19: 0.00 | Z19: 0.00 | AB19: 0.00 | AC19: 219.00 | AD19: 支付宝 | AE19: 2025081522001400711430980476 | AI19: 2025-08-15 20:44:57 | AK19: 0.000 | AL19: 0.00 | AM19: 中通速递 | AN19: 73569144710903 | AV19: 2025-08-15 20:44:50 | AY19: 2025-08-30 20:44:57 | AZ19: 2025-08-22 21:11:54 | BB19: 第三方平台卖家电子库存 | BD19: 否 | BF19: 蓝旗 | BG19: ;JDX042517220056(收） Z2365-黑色-S*1# | BI19: LAO BAN ZHOU的店 | BJ19: 5dac2bc6000000000100347a | BK19: 公司店运费模版 | BL19: 小红书公司 | BQ19: Z2365-黑色-S | BR19: 689dee5baa1e7b00156ae7bb | BS19: 【老板周】极简主义 秋冬新款复古卷边前短后长针织上衣
A20: P770811839659457301 | B20: 已完成 | C20: 无售后 | D20: 预售订单 | F20: 赵** | G20: 138****7478 | H20: 广东省 佛山市 顺德区 *** | I20: 广东省 | J20: 佛山市 | K20: 顺德区 | L20: 440606006000 | M20: 689dee541ea4cb00155e6f97 | N20: XHS-3JY9BQCVPTDS | O20: 689dee541ea4cb00155e6f96 | P20: 650d6e9f000000001603a6ac | Q20: 老板周. | R20: LAO BAN ZHOU 【老板周】百搭气质 秋冬新款百搭造型感气质三角巾 藏青色 | S20: 藏青色 | T20: 1 | W20: 199.00 | X20: 199.00 | Y20: 0.00 | Z20: 0.00 | AB20: 0.00 | AC20: 199.00 | AD20: 微信 | AE20: 4350102250202508157176301480 | AI20: 2025-08-15 20:10:46 | AK20: 0.000 | AL20: 0.00 | AM20: 中通速递 | AN20: 73569424315508 | AV20: 2025-08-15 20:10:39 | AY20: 2025-08-30 20:10:46 | AZ20: 2025-08-24 20:19:50 | BA20: 2025-08-26 22:28:56 | BB20: 第三方平台卖家电子库存 | BC20: 用户确认收货 | BD20: 否 | BI20: LAO BAN ZHOU的店 | BJ20: 6290506300000000210294b2 | BK20: 公司店运费模版 | BL20: 小红书公司 | BQ20: Z2380-藏青色 | BR20: 689dee541ea4cb00155e6f93 | BS20: 【老板周】百搭气质 秋冬新款百搭造型感气质三角巾
A21: P770809432946213601 | B21: 已关闭 | C21: 售后完成 | D21: 预售订单 | F21: 王* | G21: 180****1869 | H21: 安徽省 合肥市 蜀山区 *** | I21: 安徽省 | J21: 合肥市 | K21: 蜀山区 | L21: 340104 | M21: 689dee5baa1e7b00156ae7c3 | N21: XHS-3JY9LAGFRNR4 | O21: 689dee5baa1e7b00156ae7c2 | P21: 650d6e9f000000001603a6ac | Q21: 老板周. | R21: LAO BAN ZHOU 【老板周】极简主义 秋冬新款复古卷边前短后长针织上衣 灰色 M（100-135斤） | S21: 灰色 M（100-135斤） | T21: 1 | W21: 219.00 | X21: 219.00 | Y21: 0.00 | Z21: 0.00 | AB21: 0.00 | AC21: 219.00 | AD21: 微信 | AE21: 4326602241202508159115746828 | AI21: 2025-08-15 19:30:40 | AK21: 0.000 | AL21: 0.00 | AM21: 中通速递 | AN21: 73568592670460 | AV21: 2025-08-15 19:30:33 | AY21: 2025-08-30 19:30:40 | AZ21: 2025-08-18 22:35:44 | BA21: 2025-08-25 22:35:44 | BB21: 第三方平台卖家电子库存 | BC21: 系统自动收货 | BD21: 否 | BF21: 蓝旗 | BG21: ;JDX042534359284(收） Z2365-灰色-M*1# | BI21: LAO BAN ZHOU的店 | BJ21: 5b15fe3ff7e8b96ea4ab300b | BK21: 公司店运费模版 | BL21: 小红书公司 | BQ21: Z2365-灰色-M | BR21: 689dee5baa1e7b00156ae7bb | BS21: 【老板周】极简主义 秋冬新款复古卷边前短后长针织上衣
A22: P770807071130358401 | B22: 已完成 | C22: 无售后 | D22: 预售订单 | F22: 邹* | G22: 182****1061 | H22: 江苏省 南京市 建邺区 *** | I22: 江苏省 | J22: 南京市 | K22: 建邺区 | L22: 320105001000 | M22: 689dee541ea4cb00155e6f95 | N22: XHS-3JY9BQCQQ0OW | O22: 689dee541ea4cb00155e6f94 | P22: 650d6e9f000000001603a6ac | Q22: 老板周. | R22: 【老板周】百搭气质 秋冬新款百搭造型感气质三角巾 黑色 | S22: 黑色 | T22: 1 | W22: 199.00 | X22: 199.00 | Y22: 0.00 | Z22: 0.00 | AB22: 0.00 | AC22: 199.00 | AD22: 微信 | AE22: 4327402459202508152067557130 | AI22: 2025-08-15 18:51:19 | AK22: 0.000 | AL22: 0.00 | AM22: 中通速递 | AN22: 73568735152201 | AV22: 2025-08-15 18:51:11 | AY22: 2025-08-30 18:51:19 | AZ22: 2025-08-19 23:52:01 | BA22: 2025-08-26 23:52:01 | BB22: 第三方平台卖家电子库存 | BC22: 系统自动收货 | BD22: 否 | BI22: LAO BAN ZHOU的店 | BJ22: 64a58eea000000001003691c | BK22: 公司店运费模版 | BL22: 小红书公司 | BQ22: Z2380-黑色 | BR22: 689dee541ea4cb00155e6f93 | BS22: 【老板周】百搭气质 秋冬新款百搭造型感气质三角巾
A23: P770802455479324851 | B23: 已完成 | C23: 无售后 | D23: 预售订单 | F23: 童 | G23: 186****5600 | H23: 浙江省 杭州市 萧山区 *** | I23: 浙江省 | J23: 杭州市 | K23: 萧山区 | L23: 330109110 | M23: XHS-3JFVUELM3W8W | N23: XHS-3JFVUELM3W8W | O23: 689720eeb6005400015a679b | P23: 650d6e9f000000001603a6ac | Q23: 老板周. | R23: 【老板周】气质经典 秋冬无缝一体半高领显瘦打底针织 黑色 L（100-120斤） | S23: 黑色 L（100-120斤） | T23: 1 | W23: 219.00 | X23: 219.00 | Y23: 0.00 | Z23: 0.00 | AB23: 0.00 | AC23: 219.00 | AD23: 微信 | AE23: 4329902477202508151518076766 | AI23: 2025-08-15 17:34:25 | AK23: 0.000 | AL23: 0.00 | AM23: 中通速递 | AN23: 73569144711713 | AV23: 2025-08-15 17:34:15 | AY23: 2025-08-30 17:34:25 | AZ23: 2025-08-22 20:56:19 | BA23: 2025-08-27 08:17:40 | BB23: 第三方平台卖家电子库存 | BC23: 用户确认收货 | BD23: 否 | BI23: LAO BAN ZHOU的店 | BJ23: 5d6148d8000000000100aeb9 | BK23: 公司店运费模版 | BL23: 小红书公司 | BQ23: Z2351-黑色-L | BR23: 689720eeb6005400015a6797 | BS23: 【老板周】气质经典 秋冬无缝一体半高领显瘦打底针织
A24: P770802417453059131 | B24: 已完成 | C24: 无售后 | D24: 预售订单 | F24: 党* | G24: 139****6606 | H24: 新疆维吾尔自治区 乌鲁木齐市 天山区 *** | I24: 新疆维吾尔自治区 | J24: 乌鲁木齐市 | K24: 天山区 | L24: 650102012 | M24: XHS-3JFVUELM3W8W | N24: XHS-3JFVUELM3W8W | O24: 689720eeb6005400015a679b | P24: 650d6e9f000000001603a6ac | Q24: 老板周. | R24: 【老板周】气质经典 秋冬无缝一体半高领显瘦打底针织 黑色 L（100-120斤） | S24: 黑色 L（100-120斤） | T24: 1 | W24: 219.00 | X24: 229.00 | Y24: 0.00 | Z24: 0.00 | AB24: 0.00 | AC24: 229.00 | AD24: 支付宝 | AE24: 2025081522001452271435125494 | AI24: 2025-08-15 17:35:16 | AK24: 0.000 | AL24: 10.00 | AM24: 中通速递 | AN24: 73569144711826 | AV24: 2025-08-15 17:33:37 | AY24: 2025-08-30 17:35:16 | AZ24: 2025-08-22 20:56:19 | BA24: 2025-08-26 22:26:55 | BB24: 第三方平台卖家电子库存 | BC24: 用户确认收货 | BD24: 否 | BI24: LAO BAN ZHOU的店 | BJ24: 5a221f7fdb2e6047a150b1e7 | BK24: 公司店运费模版 | BL24: 小红书公司 | BQ24: Z2351-黑色-L | BR24: 689720eeb6005400015a6797 | BS24: 【老板周】气质经典 秋冬无缝一体半高领显瘦打底针织
A25: P770801203180185471 | B25: 已完成 | C25: 无售后 | D25: 预售订单 | F25: 四*** | G25: 181****6065 | H25: 广东省 深圳市 宝安区 *** | I25: 广东省 | J25: 深圳市 | K25: 宝安区 | L25: 440306021000 | M25: 689dee65ae962f0015895c5e | N25: XHS-3JY9YVCTEBR4 | O25: 689dee65ae962f0015895c5d | P25: 650d6e9f000000001603a6ac | Q25: 老板周. | R25: LAO BAN ZHOU 【老板周】复古休闲 秋冬细腻柔软连帽单排扣针织上衣 灰色 S（80-100斤） | S25: 灰色 S（80-100斤） | T25: 1 | W25: 299.00 | X25: 299.00 | Y25: 0.00 | Z25: 0.00 | AB25: 0.00 | AC25: 299.00 | AD25: 支付宝 | AE25: 2025081523001435931400346554 | AI25: 2025-08-15 17:13:32 | AK25: 0.000 | AL25: 0.00 | AM25: 中通速递 | AN25: 73568731901762 | AV25: 2025-08-15 17:13:23 | AY25: 2025-08-30 17:13:32 | AZ25: 2025-08-19 22:39:49 | BA25: 2025-08-26 22:39:49 | BB25: 第三方平台卖家电子库存 | BC25: 系统自动收货 | BD25: 否 | BI25: LAO BAN ZHOU的店 | BJ25: 5c37daa6000000000502f411 | BK25: 公司店运费模版 | BL25: 小红书公司 | BQ25: Z2366-灰色-S | BR25: 689dee65ae962f0015895c58 | BS25: 【老板周】复古休闲 秋冬细腻柔软连帽单排扣针织上衣
A26: P770800342402378981 | B26: 已完成 | C26: 无售后 | D26: 预售订单 | F26: 法******** | G26: 183****4792 | H26: 广东省 惠州市 惠阳区 *** | I26: 广东省 | J26: 惠州市 | K26: 惠阳区 | L26: 441303008000 | M26: 689dee335cb635001516ec70 | N26: XHS-3JY7U8WB1P1C | O26: 689dee335cb635001516ec6f | P26: 650d6e9f000000001603a6ac | Q26: 老板周. | R26: LAO BAN ZHOU 【老板周】复古调性 秋冬新款百搭松紧腰分割线廓形九分裤 深藏青色 L（110-125斤） | S26: 深藏青色 L（110-125斤） | T26: 1 | W26: 299.00 | X26: 299.00 | Y26: 0.00 | Z26: 0.00 | AB26: 0.00 | AC26: 299.00 | AD26: 支付宝 | AE26: 2025081522001412281457345278 | AI26: 2025-08-15 16:59:08 | AK26: 0.000 | AL26: 0.00 | AM26: 中通速递 | AN26: 73568735152148 | AV26: 2025-08-15 16:59:02 | AY26: 2025-08-30 16:59:08 | AZ26: 2025-08-19 23:53:31 | BA26: 2025-08-26 23:53:32 | BB26: 第三方平台卖家电子库存 | BC26: 系统自动收货 | BD26: 否 | BI26: LAO BAN ZHOU的店 | BJ26: 5d0a54ca0000000011027781 | BK26: 公司店运费模版 | BL26: 小红书公司 | BQ26: Z2375-深藏青色-L | BR26: 689dee335cb635001516ec6a | BS26: 【老板周】复古调性 秋冬新款百搭松紧腰分割线廓形九分裤
A27: P770800341884471531 | B27: 已完成 | C27: 无售后 | D27: 预售订单 | F27: 飛* | G27: 189****4299 | H27: 福建省 厦门市 思明区 *** | I27: 福建省 | J27: 厦门市 | K27: 思明区 | L27: 350203008 | M27: 689dee335cb635001516ec72 | N27: XHS-3JY7U8WG1HQ8 | O27: 689dee335cb635001516ec71 | P27: 650d6e9f000000001603a6ac | Q27: 老板周. | R27: LAO BAN ZHOU 【老板周】复古调性 秋冬新款百搭松紧腰分割线廓形九分裤 深藏青色 XL（125-140斤） | S27: 深藏青色 XL（125-140斤） | T27: 1 | W27: 299.00 | X27: 299.00 | Y27: 0.00 | Z27: 0.00 | AB27: 0.00 | AC27: 299.00 | AD27: 支付宝 | AE27: 2025081522001420281447898668 | AI27: 2025-08-15 16:59:17 | AK27: 0.000 | AL27: 0.00 | AM27: 中通速递 | AN27: 73568735151749 | AV27: 2025-08-15 16:59:02 | AY27: 2025-08-30 16:59:17 | AZ27: 2025-08-19 23:50:59 | BA27: 2025-08-26 23:51:00 | BB27: 第三方平台卖家电子库存 | BC27: 系统自动收货 | BD27: 否 | BI27: LAO BAN ZHOU的店 | BJ27: 5b56f65411be1079cb320859 | BK27: 公司店运费模版 | BL27: 小红书公司 | BQ27: Z2375-黑色-XL | BR27: 689dee335cb635001516ec6a | BS27: 【老板周】复古调性 秋冬新款百搭松紧腰分割线廓形九分裤
A28: P770800349964423951 | B28: 已完成 | C28: 无售后 | D28: 预售订单 | F28: 洛********** | G28: 138****7815 | H28: 上海 上海市 松江区 *** | I28: 上海 | J28: 上海市 | K28: 松江区 | L28: 310117102 | M28: 689dee335cb635001516ec70 | N28: XHS-3JY7U8WB1P1C | O28: 689dee335cb635001516ec6f | P28: 650d6e9f000000001603a6ac | Q28: 老板周. | R28: LAO BAN ZHOU 【老板周】复古调性 秋冬新款百搭松紧腰分割线廓形九分裤 深藏青色 L（110-125斤） | S28: 深藏青色 L（110-125斤） | T28: 1 | W28: 299.00 | X28: 299.00 | Y28: 0.00 | Z28: 0.00 | AB28: 0.00 | AC28: 299.00 | AD28: 微信 | AE28: 4331702257202508151255946117 | AI28: 2025-08-15 16:59:17 | AK28: 0.000 | AL28: 0.00 | AM28: 中通速递 | AN28: 73568735152467 | AV28: 2025-08-15 16:59:10 | AY28: 2025-08-30 16:59:17 | AZ28: 2025-08-19 23:53:31 | BA28: 2025-08-26 23:53:32 | BB28: 第三方平台卖家电子库存 | BC28: 系统自动收货 | BD28: 否 | BI28: LAO BAN ZHOU的店 | BJ28: 59c7427f51783a624bf0c129 | BK28: 公司店运费模版 | BL28: 小红书公司 | BQ28: Z2375-深藏青色-L | BR28: 689dee335cb635001516ec6a | BS28: 【老板周】复古调性 秋冬新款百搭松紧腰分割线廓形九分裤
A29: P770800340656114071 | B29: 已完成 | C29: 无售后 | D29: 预售订单 | F29: 天******** | G29: 151****5145 | H29: 上海 上海市 青浦区 *** | I29: 上海 | J29: 上海市 | K29: 青浦区 | L29: 310118110 | M29: 689dee335cb635001516ec76 | N29: XHS-3JY7U8WQ1340 | O29: 689dee335cb635001516ec75 | P29: 650d6e9f000000001603a6ac | Q29: 老板周. | R29: LAO BAN ZHOU 【老板周】复古调性 秋冬新款百搭松紧腰分割线廓形九分裤 杏色 M（95-110斤） | S29: 杏色 M（95-110斤） | T29: 1 | W29: 299.00 | X29: 299.00 | Y29: 0.00 | Z29: 0.00 | AB29: 0.00 | AC29: 299.00 | AD29: 支付宝 | AE29: 2025081522001407191429949693 | AI29: 2025-08-15 16:59:07 | AK29: 0.000 | AL29: 0.00 | AM29: 中通速递 | AN29: 73568735151897 | AV29: 2025-08-15 16:59:00 | AY29: 2025-08-30 16:59:07 | AZ29: 2025-08-19 23:51:25 | BA29: 2025-08-26 23:51:25 | BB29: 第三方平台卖家电子库存 | BC29: 系统自动收货 | BD29: 否 | BI29: LAO BAN ZHOU的店 | BJ29: 5cf2ea8a0000000012014485 | BK29: 公司店运费模版 | BL29: 小红书公司 | BQ29: Z2375-杏色-M | BR29: 689dee335cb635001516ec6a | BS29: 【老板周】复古调性 秋冬新款百搭松紧腰分割线廓形九分裤
A30: P770800341731245681 | B30: 已完成 | C30: 无售后 | D30: 预售订单 | F30: 娜* | G30: 186****6007 | H30: 浙江省 宁波市 海曙区 *** | I30: 浙江省 | J30: 宁波市 | K30: 海曙区 | L30: 330203008 | M30: 689dee335cb635001516ec6e | N30: XHS-3JY7U8W8JSOW | O30: 689dee335cb635001516ec6d | P30: 650d6e9f000000001603a6ac | Q30: 老板周. | R30: LAO BAN ZHOU 【老板周】复古调性 秋冬新款百搭松紧腰分割线廓形九分裤 深藏青色 M（95-110斤） | S30: 深藏青色 M（95-110斤） | T30: 1 | W30: 299.00 | X30: 299.00 | Y30: 0.00 | Z30: 0.00 | AB30: 0.00 | AC30: 299.00 | AD30: 支付宝 | AE30: 2025081522001404551429034447 | AI30: 2025-08-15 16:59:10 | AK30: 0.000 | AL30: 0.00 | AM30: 中通速递 | AN30: 73568735152189 | AV30: 2025-08-15 16:59:01 | AY30: 2025-08-30 16:59:10 | AZ30: 2025-08-19 23:54:36 | BA30: 2025-08-26 23:54:36 | BB30: 第三方平台卖家电子库存 | BC30: 系统自动收货 | BD30: 否 | BI30: LAO BAN ZHOU的店 | BJ30: 575f9c7982ec395b0b158782 | BK30: 公司店运费模版 | BL30: 小红书公司 | BQ30: Z2375-深藏青色-M | BR30: 689dee335cb635001516ec6a | BS30: 【老板周】复古调性 秋冬新款百搭松紧腰分割线廓形九分裤
A31: P770800350927090411 | B31: 已完成 | C31: 无售后 | D31: 预售订单 | F31: 朱** | G31: 138****2102 | H31: 安徽省 宣城市 宣州区 *** | I31: 安徽省 | J31: 宣城市 | K31: 宣州区 | L31: 341802002 | M31: 689dee335cb635001516ec6e | N31: XHS-3JY7U8W8JSOW | O31: 689dee335cb635001516ec6d | P31: 650d6e9f000000001603a6ac | Q31: 老板周. | R31: LAO BAN ZHOU 【老板周】复古调性 秋冬新款百搭松紧腰分割线廓形九分裤 深藏青色 M（95-110斤） | S31: 深藏青色 M（95-110斤） | T31: 1 | W31: 299.00 | X31: 299.00 | Y31: 0.00 | Z31: 0.00 | AB31: 0.00 | AC31: 299.00 | AD31: 微信 | AE31: 4334302258202508158131147276 | AI31: 2025-08-15 16:59:15 | AK31: 0.000 | AL31: 0.00 | AM31: 中通速递 | AN31: 73568735152388 | AV31: 2025-08-15 16:59:11 | AY31: 2025-08-30 16:59:15 | AZ31: 2025-08-19 23:54:36 | BA31: 2025-08-26 23:54:36 | BB31: 第三方平台卖家电子库存 | BC31: 系统自动收货 | BD31: 否 | BI31: LAO BAN ZHOU的店 | BJ31: 57f103df50c4b44080876d63 | BK31: 公司店运费模版 | BL31: 小红书公司 | BQ31: Z2375-深藏青色-M | BR31: 689dee335cb635001516ec6a | BS31: 【老板周】复古调性 秋冬新款百搭松紧腰分割线廓形九分裤
A32: P770800347247449271 | B32: 已完成 | C32: 无售后 | D32: 预售订单 | F32: 1**** | G32: 186****0711 | H32: 广东省 深圳市 宝安区 *** | I32: 广东省 | J32: 深圳市 | K32: 宝安区 | L32: 440306003 | M32: 689dee335cb635001516ec6e | N32: XHS-3JY7U8W8JSOW | O32: 689dee335cb635001516ec6d | P32: 650d6e9f000000001603a6ac | Q32: 老板周. | R32: LAO BAN ZHOU 【老板周】复古调性 秋冬新款百搭松紧腰分割线廓形九分裤 深藏青色 M（95-110斤） | S32: 深藏青色 M（95-110斤） | T32: 1 | W32: 299.00 | X32: 299.00 | Y32: 0.00 | Z32: 0.00 | AB32: 0.00 | AC32: 299.00 | AD32: 微信先用后付 | AI32: 2025-08-15 16:59:08 | AK32: 0.000 | AL32: 0.00 | AM32: 中通速递 | AN32: 73568735152069 | AV32: 2025-08-15 16:59:07 | AY32: 2025-08-30 16:59:08 | AZ32: 2025-08-19 23:54:36 | BA32: 2025-08-26 23:54:36 | BB32: 第三方平台卖家电子库存 | BC32: 系统自动收货 | BD32: 否 | BI32: LAO BAN ZHOU的店 | BJ32: 5bd8468373bdbf0001982456 | BK32: 公司店运费模版 | BL32: 小红书公司 | BQ32: Z2375-深藏青色-M | BR32: 689dee335cb635001516ec6a | BS32: 【老板周】复古调性 秋冬新款百搭松紧腰分割线廓形九分裤
A33: P770800356297378821 | B33: 已完成 | C33: 无售后 | D33: 预售订单 | F33: 法******** | G33: 183****4792 | H33: 广东省 惠州市 惠阳区 *** | I33: 广东省 | J33: 惠州市 | K33: 惠阳区 | L33: 441303008000 | M33: 689dee335cb635001516ec78 | N33: XHS-3JY7U8WV0VSW | O33: 689dee335cb635001516ec77 | P33: 650d6e9f000000001603a6ac | Q33: 老板周. | R33: LAO BAN ZHOU 【老板周】复古调性 秋冬新款百搭松紧腰分割线廓形九分裤 杏色 L（110-125斤） | S33: 杏色 L（110-125斤） | T33: 1 | W33: 299.00 | X33: 299.00 | Y33: 0.00 | Z33: 0.00 | AB33: 0.00 | AC33: 299.00 | AD33: 支付宝 | AE33: 2025081523001412281458634745 | AI33: 2025-08-15 16:59:22 | AK33: 0.000 | AL33: 0.00 | AM33: 中通速递 | AN33: 73568735151922 | AV33: 2025-08-15 16:59:16 | AY33: 2025-08-30 16:59:22 | AZ33: 2025-08-19 23:55:20 | BA33: 2025-08-26 23:55:20 | BB33: 第三方平台卖家电子库存 | BC33: 系统自动收货 | BD33: 否 | BI33: LAO BAN ZHOU的店 | BJ33: 5d0a54ca0000000011027781 | BK33: 公司店运费模版 | BL33: 小红书公司 | BQ33: Z2375-杏色-L | BR33: 689dee335cb635001516ec6a | BS33: 【老板周】复古调性 秋冬新款百搭松紧腰分割线廓形九分裤
A34: P770799979667284611 | B34: 已关闭 | C34: 售后完成 | D34: 预售订单 | F34: 何 | G34: 135****0291 | H34: 湖南省 长沙市 岳麓区 *** | I34: 湖南省 | J34: 长沙市 | K34: 岳麓区 | L34: 430104005 | M34: 689dee541ea4cb00155e6f97 | N34: XHS-3JY9BQCVPTDS | O34: 689dee541ea4cb00155e6f96 | P34: 650d6e9f000000001603a6ac | Q34: 老板周. | R34: LAO BAN ZHOU 【老板周】百搭气质 秋冬新款百搭造型感气质三角巾 藏青色 | S34: 藏青色 | T34: 1 | W34: 199.00 | X34: 199.00 | Y34: 0.00 | Z34: 0.00 | AB34: 0.00 | AC34: 199.00 | AD34: 支付宝 | AE34: 2025081522001457781456515826 | AI34: 2025-08-15 16:53:07 | AK34: 0.000 | AL34: 0.00 | AM34: 中通速递 | AN34: 73568592670776 | AV34: 2025-08-15 16:52:59 | AY34: 2025-08-30 16:53:07 | AZ34: 2025-08-18 22:30:28 | BA34: 2025-08-25 22:30:29 | BB34: 第三方平台卖家电子库存 | BC34: 系统自动收货 | BD34: 否 | BF34: 蓝旗 | BG34: ;SF3289575962710(收） Z2380-藏青色*1# | BI34: LAO BAN ZHOU的店 | BJ34: 5c1a271e000000000703e641 | BK34: 公司店运费模版 | BL34: 小红书公司 | BQ34: Z2380-藏青色 | BR34: 689dee541ea4cb00155e6f93 | BS34: 【老板周】百搭气质 秋冬新款百搭造型感气质三角巾
A35: P770800038248138451 | B35: 已关闭 | C35: 售后完成 | D35: 预售订单 | F35: l** | G35: 183****6177 | H35: 四川省 绵阳市 涪城区 *** | I35: 四川省 | J35: 绵阳市 | K35: 涪城区 | L35: 510703 | M35: 689dee541ea4cb00155e6f95 | N35: XHS-3JY9BQCQQ0OW | O35: 689dee541ea4cb00155e6f94 | P35: 650d6e9f000000001603a6ac | Q35: 老板周. | R35: 【老板周】百搭气质 秋冬新款百搭造型感气质三角巾 黑色 | S35: 黑色 | T35: 1 | W35: 199.00 | X35: 199.00 | Y35: 0.00 | Z35: 0.00 | AB35: 0.00 | AC35: 199.00 | AD35: 微信 | AE35: 4309702285202508159958080728 | AI35: 2025-08-15 16:54:04 | AK35: 0.000 | AL35: 0.00 | AM35: 中通速递 | AN35: 73568592688365 | AV35: 2025-08-15 16:53:58 | AY35: 2025-08-30 16:54:04 | AZ35: 2025-08-18 22:31:19 | BA35: 2025-08-25 22:31:19 | BB35: 第三方平台卖家电子库存 | BC35: 系统自动收货 | BD35: 否 | BF35: 蓝旗 | BG35: ;SF3289877149275(收） Z2380-藏青色*1 Z2380-黑色*1# | BI35: LAO BAN ZHOU的店 | BJ35: 6067c578000000000100a225 | BK35: 公司店运费模版 | BL35: 小红书公司 | BQ35: Z2380-黑色 | BR35: 689dee541ea4cb00155e6f93 | BS35: 【老板周】百搭气质 秋冬新款百搭造型感气质三角巾
A36: P770800038248138451 | B36: 已关闭 | C36: 售后完成 | D36: 预售订单 | F36: l** | G36: 183****6177 | H36: 四川省 绵阳市 涪城区 *** | I36: 四川省 | J36: 绵阳市 | K36: 涪城区 | L36: 510703 | M36: 689dee541ea4cb00155e6f97 | N36: XHS-3JY9BQCVPTDS | O36: 689dee541ea4cb00155e6f96 | P36: 650d6e9f000000001603a6ac | Q36: 老板周. | R36: LAO BAN ZHOU 【老板周】百搭气质 秋冬新款百搭造型感气质三角巾 藏青色 | S36: 藏青色 | T36: 1 | W36: 199.00 | X36: 199.00 | Y36: 0.00 | Z36: 0.00 | AB36: 0.00 | AC36: 199.00 | AD36: 微信 | AE36: 4309702285202508159958080728 | AI36: 2025-08-15 16:54:04 | AK36: 0.000 | AL36: 0.00 | AM36: 中通速递 | AN36: 73568864925966 | AV36: 2025-08-15 16:53:58 | AY36: 2025-08-30 16:54:04 | AZ36: 2025-08-20 20:48:44 | BB36: 第三方平台卖家电子库存 | BD36: 否 | BF36: 蓝旗 | BG36: ;SF3289877149275(收） Z2380-藏青色*1 Z2380-黑色*1# | BI36: LAO BAN ZHOU的店 | BJ36: 6067c578000000000100a225 | BK36: 公司店运费模版 | BL36: 小红书公司 | BQ36: Z2380-藏青色 | BR36: 689dee541ea4cb00155e6f93 | BS36: 【老板周】百搭气质 秋冬新款百搭造型感气质三角巾
A37: P770799964547510201 | B37: 已完成 | C37: 售后完成 | D37: 预售订单 | F37: 段** | G37: 136****6258 | H37: 福建省 三明市 三元区 *** | I37: 福建省 | J37: 三明市 | K37: 三元区 | L37: 350403001 | M37: 689dee541ea4cb00155e6f95 | N37: XHS-3JY9BQCQQ0OW | O37: 689dee541ea4cb00155e6f94 | P37: 650d6e9f000000001603a6ac | Q37: 老板周. | R37: 【老板周】百搭气质 秋冬新款百搭造型感气质三角巾 黑色 | S37: 黑色 | T37: 1 | W37: 199.00 | X37: 199.00 | Y37: 0.00 | Z37: 0.00 | AB37: 0.00 | AC37: 199.00 | AD37: 支付宝 | AE37: 2025081522001439961455318841 | AI37: 2025-08-15 16:52:50 | AK37: 0.000 | AL37: 0.00 | AM37: 中通速递 | AN37: 73568592670842 | AV37: 2025-08-15 16:52:44 | AY37: 2025-08-30 16:52:50 | AZ37: 2025-08-18 22:31:19 | BA37: 2025-08-25 22:31:19 | BB37: 第三方平台卖家电子库存 | BC37: 系统自动收货 | BD37: 否 | BF37: 蓝旗 | BG37: ;SF3230365475335(收） Z2380-黑色*1# | BI37: LAO BAN ZHOU的店 | BJ37: 5bed014017885e0001f01556 | BK37: 公司店运费模版 | BL37: 小红书公司 | BQ37: Z2380-黑色 | BR37: 689dee541ea4cb00155e6f93 | BS37: 【老板周】百搭气质 秋冬新款百搭造型感气质三角巾
A38: P770798353781374661 | B38: 已关闭 | C38: 售后完成 | D38: 预售订单 | F38: 曹** | G38: 187****3097 | H38: 安徽省 合肥市 蜀山区 *** | I38: 安徽省 | J38: 合肥市 | K38: 蜀山区 | L38: 340104 | M38: 689dee45c34eef00157e1208 | N38: XHS-3JY8RM3UZL6O | O38: 689dee45c34eef00157e1207 | P38: 650d6e9f000000001603a6ac | Q38: 老板周. | R38: 【老板周】小众日系 秋冬叠穿时髦下摆不规则宽松马甲 灰色 S（80-100斤） | S38: 灰色 S（80-100斤） | T38: 1 | W38: 179.00 | X38: 179.00 | Y38: 0.00 | Z38: 0.00 | AB38: 0.00 | AC38: 179.00 | AD38: 微信 | AE38: 4316902246202508157348165609 | AI38: 2025-08-15 16:26:01 | AK38: 0.000 | AL38: 0.00 | AM38: 中通速递 | AN38: 73568735151828 | AV38: 2025-08-15 16:25:54 | AY38: 2025-08-30 16:26:01 | AZ38: 2025-08-19 23:36:17 | BA38: 2025-08-26 23:36:18 | BB38: 第三方平台卖家电子库存 | BC38: 系统自动收货 | BD38: 否 | BF38: 蓝旗 | BG38: ;JDX042487675994(收） Z2378-灰色-S*1# | BI38: LAO BAN ZHOU的店 | BJ38: 5a03262d4eacab7812d21919 | BK38: 公司店运费模版 | BL38: 小红书公司 | BQ38: Z2378-灰色-S | BR38: 689dee45c34eef00157e11fa | BS38: 【老板周】小众日系 秋冬叠穿时髦下摆不规则宽松马甲
A39: P770798387983284011 | B39: 已关闭 | C39: 售后完成 | D39: 预售订单 | F39: 何 | G39: 135****0291 | H39: 湖南省 长沙市 岳麓区 *** | I39: 湖南省 | J39: 长沙市 | K39: 岳麓区 | L39: 430104005 | M39: 689d92c8956aac0015f36639 | N39: XHS-2PMHDZ8YH728 | O39: 689d92c8956aac0015f36638 | P39: 650d6e9f000000001603a6ac | Q39: 老板周. | R39: 【老板周】舒适经典 新款柔软细腻无缝一体半高领打底衫 黑色 M（100-120斤） | S39: 黑色 M（100-120斤） | T39: 1 | W39: 199.00 | X39: 199.00 | Y39: 0.00 | Z39: 0.00 | AB39: 0.00 | AC39: 199.00 | AD39: 支付宝 | AE39: 2025081522001457781454758034 | AI39: 2025-08-15 16:26:34 | AK39: 0.000 | AL39: 0.00 | AM39: 中通速递 | AN39: 73568864925675 | AV39: 2025-08-15 16:26:28 | AY39: 2025-08-30 16:26:34 | AZ39: 2025-08-20 20:38:35 | BB39: 第三方平台卖家电子库存 | BD39: 否 | BF39: 蓝旗 | BG39: ;SF3289575962710(收） Z1248-黑色-M*1# | BI39: LAO BAN ZHOU的店 | BJ39: 5c1a271e000000000703e641 | BK39: 公司店运费模版 | BL39: 小红书公司 | BQ39: Z1248-黑色-M | BR39: 689d92c8956aac0015f3662f | BS39: 【老板周】舒适经典 新款柔软细腻无缝一体半高领打底衫
A40: P770798754835129721 | B40: 已完成 | C40: 无售后 | D40: 预售订单 | F40: 三* | G40: 177****6716 | H40: 宁夏回族自治区 银川市 兴庆区 *** | I40: 宁夏回族自治区 | J40: 银川市 | K40: 兴庆区 | L40: 640104 | M40: 689d92c8956aac0015f3663b | N40: XHS-2PMHE0F2J5DS | O40: 689d92c8956aac0015f3663a | P40: 650d6e9f000000001603a6ac | Q40: 老板周. | R40: 【老板周】舒适经典 新款柔软细腻无缝一体半高领打底衫 黑色 L（120-135斤） | S40: 黑色 L（120-135斤） | T40: 1 | W40: 199.00 | X40: 199.00 | Y40: 0.00 | Z40: 0.00 | AB40: 0.00 | AC40: 199.00 | AD40: 微信 | AE40: 4334002477202508159661676431 | AI40: 2025-08-15 16:32:40 | AK40: 0.000 | AL40: 0.00 | AM40: 中通速递 | AN40: 73568874677198 | AV40: 2025-08-15 16:32:35 | AY40: 2025-08-30 16:32:40 | AZ40: 2025-08-20 23:54:30 | BA40: 2025-08-27 10:54:57 | BB40: 第三方平台卖家电子库存 | BC40: 用户确认收货 | BD40: 否 | BI40: LAO BAN ZHOU的店 | BJ40: 5eb402c90000000001002da9 | BK40: 公司店运费模版 | BL40: 小红书公司 | BQ40: Z1248-黑色-L | BR40: 689d92c8956aac0015f3662f | BS40: 【老板周】舒适经典 新款柔软细腻无缝一体半高领打底衫
...

Sheet 结算明细
A1: 年 | B1: 月 | C1: 订单号 | D1: 订单行数 | E1: 订单序位 | F1: 商家编码 | G1: 财务核算编码 | H1: 销售数量 | I1: 应收客户 | J1: 应收平台 | K1: 收：价外收费 | L1: 扣：平台佣金用 | M1: 扣：分销佣金 | N1: 扣其它费用 | O1: 应到账金额 | P1: 备注1 | Q1: 备注2 | R1: 订单号 | S1: 售后单号 | T1: 下单时间 | U1: 完成时间 | V1: 结算时间 | W1: 交易类型 | X1: 结算账户 | Y1: 动账金额 | Z1: 商品名称 | AA1: 类目 | AB1: SKU条码 | AC1: 规格ID | AD1: 商品数量 | AE1: 计佣基数 | AF1: 商品实付/实退 | AG1: 优惠类型 | AH1: 商家优惠 | AI1: 平台优惠补贴 | AJ1: 平台运费补贴 | AK1: 佣金率 | AL1: 返利率 | AM1: 佣金总额 | AN1: 计税价格(含税) | AO1: 计税价格(未税) | AP1: 税率 | AQ1: 跨境税代缴 | AR1: 商品税金 | AS1: 卖家CPS佣金率 | AT1: 分销佣金 | AU1: _x0008__x0008_推广_x0008_达人ID | AV1: 达人昵称 | AW1: 带货类型 | AX1: 代运营服务商佣金 | AY1: 代开发服务商佣金 | AZ1: 运费 | BA1: 运费税金 | BB1: 支付渠道费 | BC1: 花呗分期手续费 | BD1: 国补订单毛保金额 | BE1: 备注
A2: =YEAR(V2) -> 2025 | B2: =MONTH(V2) -> 8 | C2: =R2 -> P770450992956407491 | D2: =COUNTIF(R:R,R2) -> 2 | E2: =COUNTIF($R$2:R2,R2) -> 1 | F2: {=INDEX(订单明细!BQ:BQ,MATCH(R2&AC2,订单明细!A:A&订单明细!O:O,0))} -> Z2183-黑色-XL | G2: =LEFT(F2,FIND("-",F2)-1) -> Z2183 | H2: {=_xlfn.IFS(C2=0,"",I2>0,AD2,AND(I2<0,I2>-30),0,I2<=-30,-1)} -> -1 | I2: =AF2 -> -129 | J2: =AI2+AJ2 -> 0 | K2: =IF(AZ2<=0,AZ2,AZ2/COUNTIFS(R:R,R2,AZ:AZ,">0")) -> 0 | L2: =AM2 -> 6.45 | M2: =AT2 -> 0.77 | O2: =SUM(I2:N2) -> -121.78 | R2: P770450992956407491 | S2: R5640749128652672 | T2: 2025-08-11 15:56:33 | U2: 2025-08-31 14:13:53 | V2: 2025-08-31 22:10:26 | W2: 退款 | X2: 店铺余额 | Y2: -121.78 | Z2: 【老板周】夏季轻盈 新品 · 【老板周】夏季轻盈 新品圆领气质轻薄不规则透气上衣 黑色 XL（120-135斤） | AA2: 女装/女士精品>T恤 | AB2: XHS-3EHYVMDISL4W | AC2: 6896fe0c6d08080015500896 | AD2: 0 | AE2: -129 | AF2: -129 | AG2: 0 | AH2: 0 | AI2: 0 | AJ2: 0 | AK2: 0 | AL2: 0 | AM2: 6.45 | AN2: 0 | AO2: 0 | AP2: 0 | AQ2: 否 | AR2: 0 | AS2: 0 | AT2: 0.77 | AU2: 650d6e9f000000001603a6ac | AV2: 老板周. | AW2: 达人带货 | AZ2: 0 | BA2: 0 | BB2: 0 | BC2: 0 | BD2: 0
A3: =YEAR(V3) -> 2025 | B3: =MONTH(V3) -> 8 | C3: =R3 -> P770450992956407491 | D3: =COUNTIF(R:R,R3) -> 2 | E3: =COUNTIF($R$2:R3,R3) -> 2 | F3: {=INDEX(订单明细!BQ:BQ,MATCH(R3&AC3,订单明细!A:A&订单明细!O:O,0))} -> Z2183-黑色-XL | G3: =LEFT(F3,FIND("-",F3)-1) -> Z2183 | H3: {=_xlfn.IFS(C3=0,"",I3>0,AD3,AND(I3<0,I3>-30),0,I3<=-30,-1)} -> 1 | I3: =AF3 -> 129 | J3: =AI3+AJ3 -> 0 | K3: =IF(AZ3<=0,AZ3,AZ3/COUNTIFS(R:R,R3,AZ:AZ,">0")) -> 0 | L3: =AM3 -> -6.45 | M3: =AT3 -> -0.77 | O3: =SUM(I3:N3) -> 121.78 | R3: P770450992956407491 | T3: 2025-08-11 15:56:33 | U3: 2025-08-25 21:22:41 | V3: 2025-08-31 22:10:26 | W3: 结算入账 | X3: 店铺余额 | Y3: 121.78 | Z3: 【老板周】夏季轻盈 新品 · 【老板周】夏季轻盈 新品圆领气质轻薄不规则透气上衣 黑色 XL（120-135斤） | AA3: 女装/女士精品>T恤 | AB3: XHS-3EHYVMDISL4W | AC3: 6896fe0c6d08080015500896 | AD3: 1 | AE3: 129 | AF3: 129 | AH3: 0 | AI3: 0 | AJ3: 0 | AK3: 0.05 | AL3: 0 | AM3: -6.45 | AN3: 129 | AO3: 129 | AP3: 0 | AQ3: 否 | AR3: 0 | AS3: 0.006 | AT3: -0.77 | AU3: 650d6e9f000000001603a6ac | AV3: 老板周. | AW3: 达人带货 | AZ3: 0 | BA3: 0 | BB3: 0 | BC3: 0 | BD3: 0
A4: =YEAR(V4) -> 2025 | B4: =MONTH(V4) -> 8 | C4: =R4 -> P770795407221086221 | D4: =COUNTIF(R:R,R4) -> 1 | E4: =COUNTIF($R$2:R4,R4) -> 1 | F4: {=INDEX(订单明细!BQ:BQ,MATCH(R4&AC4,订单明细!A:A&订单明细!O:O,0))} -> Z2363-灰色-M | G4: =LEFT(F4,FIND("-",F4)-1) -> Z2363 | H4: {=_xlfn.IFS(C4=0,"",I4>0,AD4,AND(I4<0,I4>-30),0,I4<=-30,-1)} -> 1 | I4: =AF4 -> 359 | J4: =AI4+AJ4 -> 0 | K4: =IF(AZ4<=0,AZ4,AZ4/COUNTIFS(R:R,R4,AZ:AZ,">0")) -> 0 | L4: =AM4 -> -17.95 | M4: =AT4 -> -2.15 | O4: =SUM(I4:N4) -> 338.9 | R4: P770795407221086221 | T4: 2025-08-15 15:36:47 | U4: 2025-08-27 17:23:23 | V4: 2025-08-31 17:54:09 | W4: 结算入账 | X4: 店铺余额 | Y4: 338.9 | Z4: 【老板周】通勤质感 秋冬 · 【老板周】通勤质感 秋冬重磅新品半松紧腰垂感口袋西裤 灰色 M（100-120斤） | AA4: 女装/女士精品>裤子>西装裤/正装裤 | AB4: XHS-3JY78059ZB40 | AC4: 689dee2db292580015c1974b | AD4: 1 | AE4: 359 | AF4: 359 | AH4: 0 | AI4: 0 | AJ4: 0 | AK4: 0.05 | AL4: 0 | AM4: -17.95 | AN4: 359 | AO4: 359 | AP4: 0 | AQ4: 否 | AR4: 0 | AS4: 0.006 | AT4: -2.15 | AU4: 650d6e9f000000001603a6ac | AV4: 老板周. | AW4: 达人带货 | AZ4: 0 | BA4: 0 | BB4: 0 | BC4: 0 | BD4: 0
A5: =YEAR(V5) -> 2025 | B5: =MONTH(V5) -> 8 | C5: =R5 -> P770821520016218311 | D5: =COUNTIF(R:R,R5) -> 1 | E5: =COUNTIF($R$2:R5,R5) -> 1 | F5: {=INDEX(订单明细!BQ:BQ,MATCH(R5&AC5,订单明细!A:A&订单明细!O:O,0))} -> Z2365-灰色-S | G5: =LEFT(F5,FIND("-",F5)-1) -> Z2365 | H5: {=_xlfn.IFS(C5=0,"",I5>0,AD5,AND(I5<0,I5>-30),0,I5<=-30,-1)} -> 1 | I5: =AF5 -> 219 | J5: =AI5+AJ5 -> 0 | K5: =IF(AZ5<=0,AZ5,AZ5/COUNTIFS(R:R,R5,AZ:AZ,">0")) -> 0 | L5: =AM5 -> -10.95 | M5: =AT5 -> -1.31 | O5: =SUM(I5:N5) -> 206.74 | R5: P770821520016218311 | T5: 2025-08-15 22:52:00 | U5: 2025-08-27 17:10:53 | V5: 2025-08-31 17:40:23 | W5: 结算入账 | X5: 店铺余额 | Y5: 206.74 | Z5: 【老板周】极简主义 秋冬 · 【老板周】极简主义 秋冬新款复古卷边前短后长针织上衣 灰色 S（80-100斤） | AA5: 女装/女士精品>毛针织衫 | AB5: XHS-3JY9LAG89YPS | AC5: 689dee5baa1e7b00156ae7c0 | AD5: 1 | AE5: 219 | AF5: 219 | AH5: 0 | AI5: 0 | AJ5: 0 | AK5: 0.05 | AL5: 0 | AM5: -10.95 | AN5: 219 | AO5: 219 | AP5: 0 | AQ5: 否 | AR5: 0 | AS5: 0.006 | AT5: -1.31 | AU5: 650d6e9f000000001603a6ac | AV5: 老板周. | AW5: 达人带货 | AZ5: 0 | BA5: 0 | BB5: 0 | BC5: 0 | BD5: 0
A6: =YEAR(V6) -> 2025 | B6: =MONTH(V6) -> 8 | C6: =R6 -> P771683143371443691 | D6: =COUNTIF(R:R,R6) -> 1 | E6: =COUNTIF($R$2:R6,R6) -> 1 | F6: {=INDEX(订单明细!BQ:BQ,MATCH(R6&AC6,订单明细!A:A&订单明细!O:O,0))} -> Z2338-花色-M | G6: =LEFT(F6,FIND("-",F6)-1) -> Z2338 | H6: {=_xlfn.IFS(C6=0,"",I6>0,AD6,AND(I6<0,I6>-30),0,I6<=-30,-1)} -> 1 | I6: =AF6 -> 249 | J6: =AI6+AJ6 -> 0 | K6: =IF(AZ6<=0,AZ6,AZ6/COUNTIFS(R:R,R6,AZ:AZ,">0")) -> 0 | L6: =AM6 -> -12.45 | M6: =AT6 -> 0 | O6: =SUM(I6:N6) -> 236.55 | R6: P771683143371443691 | T6: 2025-08-25 22:12:23 | U6: 2025-08-27 16:51:27 | V6: 2025-08-31 17:24:56 | W6: 结算入账 | X6: 店铺余额 | Y6: 236.55 | Z6: 【老板周】复古老钱 新品 · 【老板周】复古老钱 新品小众宽松时髦腰果花松紧腰休闲裤 花色 M（100-120斤） | AA6: 女装/女士精品>裤子>休闲裤 | AB6: XHS-3IRER6T45U68 | AC6: 6894ac11aa1e7b001555658e | AD6: 1 | AE6: 249 | AF6: 249 | AH6: 0 | AI6: 0 | AJ6: 0 | AK6: 0.05 | AL6: 0 | AM6: -12.45 | AN6: 249 | AO6: 249 | AP6: 0 | AQ6: 否 | AR6: 0 | AS6: 0 | AT6: 0 | AZ6: 0 | BA6: 0 | BB6: 0 | BC6: 0 | BD6: 0
A7: =YEAR(V7) -> 2025 | B7: =MONTH(V7) -> 8 | C7: =R7 -> P770795098086034121 | D7: =COUNTIF(R:R,R7) -> 2 | E7: =COUNTIF($R$2:R7,R7) -> 1 | F7: {=INDEX(订单明细!BQ:BQ,MATCH(R7&AC7,订单明细!A:A&订单明细!O:O,0))} -> Z2363-黑色-L | G7: =LEFT(F7,FIND("-",F7)-1) -> Z2363 | H7: {=_xlfn.IFS(C7=0,"",I7>0,AD7,AND(I7<0,I7>-30),0,I7<=-30,-1)} -> -1 | I7: =AF7 -> -359 | J7: =AI7+AJ7 -> 0 | K7: =IF(AZ7<=0,AZ7,AZ7/COUNTIFS(R:R,R7,AZ:AZ,">0")) -> 0 | L7: =AM7 -> 17.95 | M7: =AT7 -> 2.15 | O7: =SUM(I7:N7) -> -338.9 | R7: P770795098086034121 | S7: R8603412185555555 | T7: 2025-08-15 15:31:38 | U7: 2025-08-27 18:38:57 | V7: 2025-08-31 17:18:01 | W7: 退款 | X7: 店铺余额 | Y7: -338.9 | Z7: 【老板周】通勤质感 秋冬 · 【老板周】通勤质感 秋冬重磅新品半松紧腰垂感口袋西裤 黑色 L（120-135斤） | AA7: 女装/女士精品>裤子>西装裤/正装裤 | AB7: XHS-3JY78052HM2O | AC7: 689dee2db292580015c19747 | AD7: 0 | AE7: -359 | AF7: -359 | AG7: 0 | AH7: 0 | AI7: 0 | AJ7: 0 | AK7: 0 | AL7: 0 | AM7: 17.95 | AN7: 0 | AO7: 0 | AP7: 0 | AQ7: 否 | AR7: 0 | AS7: 0 | AT7: 2.15 | AU7: 650d6e9f000000001603a6ac | AV7: 老板周. | AW7: 达人带货 | AZ7: 0 | BA7: 0 | BB7: 0 | BC7: 0 | BD7: 0
A8: =YEAR(V8) -> 2025 | B8: =MONTH(V8) -> 8 | C8: =R8 -> P770984511919250241 | D8: =COUNTIF(R:R,R8) -> 2 | E8: =COUNTIF($R$2:R8,R8) -> 1 | F8: {=INDEX(订单明细!BQ:BQ,MATCH(R8&AC8,订单明细!A:A&订单明细!O:O,0))} -> Z2218-黑色-L | G8: =LEFT(F8,FIND("-",F8)-1) -> Z2218 | H8: {=_xlfn.IFS(C8=0,"",I8>0,AD8,AND(I8<0,I8>-30),0,I8<=-30,-1)} -> -1 | I8: =AF8 -> -229 | J8: =AI8+AJ8 -> 0 | K8: =IF(AZ8<=0,AZ8,AZ8/COUNTIFS(R:R,R8,AZ:AZ,">0")) -> 0 | L8: =AM8 -> 11.45 | M8: =AT8 -> 1.37 | O8: =SUM(I8:N8) -> -216.18 | R8: P770984511919250241 | S8: R1925024178435962 | T8: 2025-08-17 20:08:31 | U8: 2025-08-27 17:06:50 | V8: 2025-08-31 17:18:01 | W8: 退款 | X8: 店铺余额 | Y8: -216.18 | Z8: 【老板周】法式随性 夏季 · 【老板周】法式随性 夏季时髦叠门襟无袖设计感开叉马甲 黑色 L（120-135斤） | AA8: 女装/女士精品>马夹 | AB8: XHS-3FAGCOT6V0U8 | AC8: 689704bae53c1000157cfaa0 | AD8: 0 | AE8: -229 | AF8: -229 | AG8: 0 | AH8: 0 | AI8: 0 | AJ8: 0 | AK8: 0 | AL8: 0 | AM8: 11.45 | AN8: 0 | AO8: 0 | AP8: 0 | AQ8: 否 | AR8: 0 | AS8: 0 | AT8: 1.37 | AU8: 650d6e9f000000001603a6ac | AV8: 老板周. | AW8: 达人带货 | AZ8: 0 | BA8: 0 | BB8: 0 | BC8: 0 | BD8: 0
A9: =YEAR(V9) -> 2025 | B9: =MONTH(V9) -> 8 | C9: =R9 -> P770984511919250241 | D9: =COUNTIF(R:R,R9) -> 2 | E9: =COUNTIF($R$2:R9,R9) -> 2 | F9: {=INDEX(订单明细!BQ:BQ,MATCH(R9&AC9,订单明细!A:A&订单明细!O:O,0))} -> Z2218-黑色-L | G9: =LEFT(F9,FIND("-",F9)-1) -> Z2218 | H9: {=_xlfn.IFS(C9=0,"",I9>0,AD9,AND(I9<0,I9>-30),0,I9<=-30,-1)} -> 1 | I9: =AF9 -> 229 | J9: =AI9+AJ9 -> 0 | K9: =IF(AZ9<=0,AZ9,AZ9/COUNTIFS(R:R,R9,AZ:AZ,">0")) -> 0 | L9: =AM9 -> -11.45 | M9: =AT9 -> -1.37 | O9: =SUM(I9:N9) -> 216.18 | R9: P770984511919250241 | T9: 2025-08-17 20:08:31 | U9: 2025-08-27 17:06:50 | V9: 2025-08-31 17:18:01 | W9: 结算入账 | X9: 店铺余额 | Y9: 216.18 | Z9: 【老板周】法式随性 夏季 · 【老板周】法式随性 夏季时髦叠门襟无袖设计感开叉马甲 黑色 L（120-135斤） | AA9: 女装/女士精品>马夹 | AB9: XHS-3FAGCOT6V0U8 | AC9: 689704bae53c1000157cfaa0 | AD9: 1 | AE9: 229 | AF9: 229 | AH9: 0 | AI9: 0 | AJ9: 0 | AK9: 0.05 | AL9: 0 | AM9: -11.45 | AN9: 229 | AO9: 229 | AP9: 0 | AQ9: 否 | AR9: 0 | AS9: 0.006 | AT9: -1.37 | AU9: 650d6e9f000000001603a6ac | AV9: 老板周. | AW9: 达人带货 | AZ9: 0 | BA9: 0 | BB9: 0 | BC9: 0 | BD9: 0
A10: =YEAR(V10) -> 2025 | B10: =MONTH(V10) -> 8 | C10: =R10 -> P770795098086034121 | D10: =COUNTIF(R:R,R10) -> 2 | E10: =COUNTIF($R$2:R10,R10) -> 2 | F10: {=INDEX(订单明细!BQ:BQ,MATCH(R10&AC10,订单明细!A:A&订单明细!O:O,0))} -> Z2363-黑色-L | G10: =LEFT(F10,FIND("-",F10)-1) -> Z2363 | H10: {=_xlfn.IFS(C10=0,"",I10>0,AD10,AND(I10<0,I10>-30),0,I10<=-30,-1)} -> 1 | I10: =AF10 -> 359 | J10: =AI10+AJ10 -> 0 | K10: =IF(AZ10<=0,AZ10,AZ10/COUNTIFS(R:R,R10,AZ:AZ,">0")) -> 0 | L10: =AM10 -> -17.95 | M10: =AT10 -> -2.15 | O10: =SUM(I10:N10) -> 338.9 | R10: P770795098086034121 | T10: 2025-08-15 15:31:38 | U10: 2025-08-27 17:06:35 | V10: 2025-08-31 17:18:01 | W10: 结算入账 | X10: 店铺余额 | Y10: 338.9 | Z10: 【老板周】通勤质感 秋冬 · 【老板周】通勤质感 秋冬重磅新品半松紧腰垂感口袋西裤 黑色 L（120-135斤） | AA10: 女装/女士精品>裤子>西装裤/正装裤 | AB10: XHS-3JY78052HM2O | AC10: 689dee2db292580015c19747 | AD10: 1 | AE10: 359 | AF10: 359 | AH10: 0 | AI10: 0 | AJ10: 0 | AK10: 0.05 | AL10: 0 | AM10: -17.95 | AN10: 359 | AO10: 359 | AP10: 0 | AQ10: 否 | AR10: 0 | AS10: 0.006 | AT10: -2.15 | AU10: 650d6e9f000000001603a6ac | AV10: 老板周. | AW10: 达人带货 | AZ10: 0 | BA10: 0 | BB10: 0 | BC10: 0 | BD10: 0
A11: =YEAR(V11) -> 2025 | B11: =MONTH(V11) -> 8 | C11: =R11 -> P770381824712038751 | D11: =COUNTIF(R:R,R11) -> 2 | E11: =COUNTIF($R$2:R11,R11) -> 1 | F11: {=INDEX(订单明细!BQ:BQ,MATCH(R11&AC11,订单明细!A:A&订单明细!O:O,0))} -> Z1688-黑色-L | G11: =LEFT(F11,FIND("-",F11)-1) -> Z1688 | H11: {=_xlfn.IFS(C11=0,"",I11>0,AD11,AND(I11<0,I11>-30),0,I11<=-30,-1)} -> -1 | I11: =AF11 -> -499 | J11: =AI11+AJ11 -> 0 | K11: =IF(AZ11<=0,AZ11,AZ11/COUNTIFS(R:R,R11,AZ:AZ,">0")) -> 0 | L11: =AM11 -> 24.95 | M11: =AT11 -> 2.99 | O11: =SUM(I11:N11) -> -471.06 | R11: P770381824712038751 | S11: R1203875175623359 | T11: 2025-08-10 20:43:44 | U11: 2025-08-24 20:11:22 | V11: 2025-08-31 17:08:33 | W11: 退款 | X11: 店铺余额 | Y11: -471.06 | Z11: 【老板周】复古英伦 极简 · 【老板周】复古英伦 极简设计立体剪裁无领廓形外套 黑色 L（120-135斤） | AA11: 女装/女士精品>短外套 | AB11: XHS-31Z6WPZ8ZG1S | AC11: 68970ccdfe39ac0015b91515 | AD11: 0 | AE11: -499 | AF11: -499 | AG11: 0 | AH11: 0 | AI11: 0 | AJ11: 0 | AK11: 0 | AL11: 0 | AM11: 24.95 | AN11: 0 | AO11: 0 | AP11: 0 | AQ11: 否 | AR11: 0 | AS11: 0 | AT11: 2.99 | AU11: 650d6e9f000000001603a6ac | AV11: 老板周. | AW11: 达人带货 | AZ11: 0 | BA11: 0 | BB11: 0 | BC11: 0 | BD11: 0
A12: =YEAR(V12) -> 2025 | B12: =MONTH(V12) -> 8 | C12: =R12 -> P770381824712038751 | D12: =COUNTIF(R:R,R12) -> 2 | E12: =COUNTIF($R$2:R12,R12) -> 2 | F12: {=INDEX(订单明细!BQ:BQ,MATCH(R12&AC12,订单明细!A:A&订单明细!O:O,0))} -> Z1688-黑色-L | G12: =LEFT(F12,FIND("-",F12)-1) -> Z1688 | H12: {=_xlfn.IFS(C12=0,"",I12>0,AD12,AND(I12<0,I12>-30),0,I12<=-30,-1)} -> 1 | I12: =AF12 -> 499 | J12: =AI12+AJ12 -> 0 | K12: =IF(AZ12<=0,AZ12,AZ12/COUNTIFS(R:R,R12,AZ:AZ,">0")) -> 0 | L12: =AM12 -> -24.95 | M12: =AT12 -> -2.99 | O12: =SUM(I12:N12) -> 471.06 | R12: P770381824712038751 | T12: 2025-08-10 20:43:44 | U12: 2025-08-27 16:58:50 | V12: 2025-08-31 17:08:33 | W12: 结算入账 | X12: 店铺余额 | Y12: 471.06 | Z12: 【老板周】复古英伦 极简 · 【老板周】复古英伦 极简设计立体剪裁无领廓形外套 黑色 L（120-135斤） | AA12: 女装/女士精品>短外套 | AB12: XHS-31Z6WPZ8ZG1S | AC12: 68970ccdfe39ac0015b91515 | AD12: 1 | AE12: 499 | AF12: 499 | AH12: 0 | AI12: 0 | AJ12: 0 | AK12: 0.05 | AL12: 0 | AM12: -24.95 | AN12: 499 | AO12: 499 | AP12: 0 | AQ12: 否 | AR12: 0 | AS12: 0.006 | AT12: -2.99 | AU12: 650d6e9f000000001603a6ac | AV12: 老板周. | AW12: 达人带货 | AZ12: 0 | BA12: 0 | BB12: 0 | BC12: 0 | BD12: 0
A13: =YEAR(V13) -> 2025 | B13: =MONTH(V13) -> 8 | C13: =R13 -> P770818846205191671 | D13: =COUNTIF(R:R,R13) -> 1 | E13: =COUNTIF($R$2:R13,R13) -> 1 | F13: {=INDEX(订单明细!BQ:BQ,MATCH(R13&AC13,订单明细!A:A&订单明细!O:O,0))} -> Z1576-黑色-M | G13: =LEFT(F13,FIND("-",F13)-1) -> Z1576 | H13: {=_xlfn.IFS(C13=0,"",I13>0,AD13,AND(I13<0,I13>-30),0,I13<=-30,-1)} -> 1 | I13: =AF13 -> 199 | J13: =AI13+AJ13 -> 0 | K13: =IF(AZ13<=0,AZ13,AZ13/COUNTIFS(R:R,R13,AZ:AZ,">0")) -> 0 | L13: =AM13 -> -9.95 | M13: =AT13 -> -1.19 | O13: =SUM(I13:N13) -> 187.86 | R13: P770818846205191671 | T13: 2025-08-15 22:07:26 | U13: 2025-08-27 16:15:17 | V13: 2025-08-31 16:46:31 | W13: 结算入账 | X13: 店铺余额 | Y13: 187.86 | Z13: 【老板周】时髦撞色 春季 · 【老板周】时髦撞色 春季新款假两件显瘦长袖打底T恤上衣 黑色 M（100-120斤） | AA13: 女装/女士精品>T恤 | AB13: XHS-2Z0D3J1YAL8G | AC13: 6896fe48057f570015d29244 | AD13: 1 | AE13: 199 | AF13: 199 | AH13: 0 | AI13: 0 | AJ13: 0 | AK13: 0.05 | AL13: 0 | AM13: -9.95 | AN13: 199 | AO13: 199 | AP13: 0 | AQ13: 否 | AR13: 0 | AS13: 0.006 | AT13: -1.19 | AU13: 650d6e9f000000001603a6ac | AV13: 老板周. | AW13: 达人带货 | AZ13: 0 | BA13: 0 | BB13: 0 | BC13: 0 | BD13: 0
A14: =YEAR(V14) -> 2025 | B14: =MONTH(V14) -> 8 | C14: =R14 -> P770798117968454421 | D14: =COUNTIF(R:R,R14) -> 2 | E14: =COUNTIF($R$2:R14,R14) -> 1 | F14: {=INDEX(订单明细!BQ:BQ,MATCH(R14&AC14,订单明细!A:A&订单明细!O:O,0))} -> Z2365-灰色-S | G14: =LEFT(F14,FIND("-",F14)-1) -> Z2365 | H14: {=_xlfn.IFS(C14=0,"",I14>0,AD14,AND(I14<0,I14>-30),0,I14<=-30,-1)} -> -1 | I14: =AF14 -> -219 | J14: =AI14+AJ14 -> 0 | K14: =IF(AZ14<=0,AZ14,AZ14/COUNTIFS(R:R,R14,AZ:AZ,">0")) -> 0 | L14: =AM14 -> 10.95 | M14: =AT14 -> 1.31 | O14: =SUM(I14:N14) -> -206.74 | R14: P770798117968454421 | S14: R6845442155679510 | T14: 2025-08-15 16:21:58 | U14: 2025-08-24 10:33:34 | V14: 2025-08-31 16:38:40 | W14: 退款 | X14: 店铺余额 | Y14: -206.74 | Z14: 【老板周】极简主义 秋冬 · 【老板周】极简主义 秋冬新款复古卷边前短后长针织上衣 灰色 S（80-100斤） | AA14: 女装/女士精品>毛针织衫 | AB14: XHS-3JY9LAG89YPS | AC14: 689dee5baa1e7b00156ae7c0 | AD14: 0 | AE14: -219 | AF14: -219 | AG14: 0 | AH14: 0 | AI14: 0 | AJ14: 0 | AK14: 0 | AL14: 0 | AM14: 10.95 | AN14: 0 | AO14: 0 | AP14: 0 | AQ14: 否 | AR14: 0 | AS14: 0 | AT14: 1.31 | AU14: 650d6e9f000000001603a6ac | AV14: 老板周. | AW14: 达人带货 | AZ14: 0 | BA14: 0 | BB14: 0 | BC14: 0 | BD14: 0
A15: =YEAR(V15) -> 2025 | B15: =MONTH(V15) -> 8 | C15: =R15 -> P770986580251454261 | D15: =COUNTIF(R:R,R15) -> 2 | E15: =COUNTIF($R$2:R15,R15) -> 1 | F15: {=INDEX(订单明细!BQ:BQ,MATCH(R15&AC15,订单明细!A:A&订单明细!O:O,0))} -> Z2218-黑色-S | G15: =LEFT(F15,FIND("-",F15)-1) -> Z2218 | H15: {=_xlfn.IFS(C15=0,"",I15>0,AD15,AND(I15<0,I15>-30),0,I15<=-30,-1)} -> -1 | I15: =AF15 -> -229 | J15: =AI15+AJ15 -> 0 | K15: =IF(AZ15<=0,AZ15,AZ15/COUNTIFS(R:R,R15,AZ:AZ,">0")) -> 0 | L15: =AM15 -> 11.45 | M15: =AT15 -> 1.37 | O15: =SUM(I15:N15) -> -216.18 | R15: P770986580251454261 | S15: R5145426155617207 | T15: 2025-08-17 20:43:00 | U15: 2025-08-24 10:33:44 | V15: 2025-08-31 16:38:40 | W15: 退款 | X15: 店铺余额 | Y15: -216.18 | Z15: 【老板周】法式随性 夏季 · 【老板周】法式随性 夏季时髦叠门襟无袖设计感开叉马甲 黑色 S（80-100斤） | AA15: 女装/女士精品>马夹 | AB15: XHS-3FAGCOSWVFGG | AC15: 689704bae53c1000157cfa9c | AD15: 0 | AE15: -229 | AF15: -229 | AG15: 0 | AH15: 0 | AI15: 0 | AJ15: 0 | AK15: 0 | AL15: 0 | AM15: 11.45 | AN15: 0 | AO15: 0 | AP15: 0 | AQ15: 否 | AR15: 0 | AS15: 0 | AT15: 1.37 | AU15: 650d6e9f000000001603a6ac | AV15: 老板周. | AW15: 达人带货 | AZ15: 0 | BA15: 0 | BB15: 0 | BC15: 0 | BD15: 0
A16: =YEAR(V16) -> 2025 | B16: =MONTH(V16) -> 8 | C16: =R16 -> P770986580251454261 | D16: =COUNTIF(R:R,R16) -> 2 | E16: =COUNTIF($R$2:R16,R16) -> 2 | F16: {=INDEX(订单明细!BQ:BQ,MATCH(R16&AC16,订单明细!A:A&订单明细!O:O,0))} -> Z2218-黑色-S | G16: =LEFT(F16,FIND("-",F16)-1) -> Z2218 | H16: {=_xlfn.IFS(C16=0,"",I16>0,AD16,AND(I16<0,I16>-30),0,I16<=-30,-1)} -> 1 | I16: =AF16 -> 229 | J16: =AI16+AJ16 -> 0 | K16: =IF(AZ16<=0,AZ16,AZ16/COUNTIFS(R:R,R16,AZ:AZ,">0")) -> 0 | L16: =AM16 -> -11.45 | M16: =AT16 -> -1.37 | O16: =SUM(I16:N16) -> 216.18 | R16: P770986580251454261 | T16: 2025-08-17 20:43:00 | U16: 2025-08-27 16:24:28 | V16: 2025-08-31 16:38:40 | W16: 结算入账 | X16: 店铺余额 | Y16: 216.18 | Z16: 【老板周】法式随性 夏季 · 【老板周】法式随性 夏季时髦叠门襟无袖设计感开叉马甲 黑色 S（80-100斤） | AA16: 女装/女士精品>马夹 | AB16: XHS-3FAGCOSWVFGG | AC16: 689704bae53c1000157cfa9c | AD16: 1 | AE16: 229 | AF16: 229 | AH16: 0 | AI16: 0 | AJ16: 0 | AK16: 0.05 | AL16: 0 | AM16: -11.45 | AN16: 229 | AO16: 229 | AP16: 0 | AQ16: 否 | AR16: 0 | AS16: 0.006 | AT16: -1.37 | AU16: 650d6e9f000000001603a6ac | AV16: 老板周. | AW16: 达人带货 | AZ16: 0 | BA16: 0 | BB16: 0 | BC16: 0 | BD16: 0
A17: =YEAR(V17) -> 2025 | B17: =MONTH(V17) -> 8 | C17: =R17 -> P770798117968454421 | D17: =COUNTIF(R:R,R17) -> 2 | E17: =COUNTIF($R$2:R17,R17) -> 2 | F17: {=INDEX(订单明细!BQ:BQ,MATCH(R17&AC17,订单明细!A:A&订单明细!O:O,0))} -> Z2365-灰色-S | G17: =LEFT(F17,FIND("-",F17)-1) -> Z2365 | H17: {=_xlfn.IFS(C17=0,"",I17>0,AD17,AND(I17<0,I17>-30),0,I17<=-30,-1)} -> 1 | I17: =AF17 -> 219 | J17: =AI17+AJ17 -> 0 | K17: =IF(AZ17<=0,AZ17,AZ17/COUNTIFS(R:R,R17,AZ:AZ,">0")) -> 0 | L17: =AM17 -> -10.95 | M17: =AT17 -> -1.31 | O17: =SUM(I17:N17) -> 206.74 | R17: P770798117968454421 | T17: 2025-08-15 16:21:58 | U17: 2025-08-27 16:24:29 | V17: 2025-08-31 16:38:40 | W17: 结算入账 | X17: 店铺余额 | Y17: 206.74 | Z17: 【老板周】极简主义 秋冬 · 【老板周】极简主义 秋冬新款复古卷边前短后长针织上衣 灰色 S（80-100斤） | AA17: 女装/女士精品>毛针织衫 | AB17: XHS-3JY9LAG89YPS | AC17: 689dee5baa1e7b00156ae7c0 | AD17: 1 | AE17: 219 | AF17: 219 | AH17: 0 | AI17: 0 | AJ17: 0 | AK17: 0.05 | AL17: 0 | AM17: -10.95 | AN17: 219 | AO17: 219 | AP17: 0 | AQ17: 否 | AR17: 0 | AS17: 0.006 | AT17: -1.31 | AU17: 650d6e9f000000001603a6ac | AV17: 老板周. | AW17: 达人带货 | AZ17: 0 | BA17: 0 | BB17: 0 | BC17: 0 | BD17: 0
A18: =YEAR(V18) -> 2025 | B18: =MONTH(V18) -> 8 | C18: =R18 -> P770813889954234671 | D18: =COUNTIF(R:R,R18) -> 2 | E18: =COUNTIF($R$2:R18,R18) -> 1 | F18: {=INDEX(订单明细!BQ:BQ,MATCH(R18&AC18,订单明细!A:A&订单明细!O:O,0))} -> Z2365-黑色-S | G18: =LEFT(F18,FIND("-",F18)-1) -> Z2365 | H18: {=_xlfn.IFS(C18=0,"",I18>0,AD18,AND(I18<0,I18>-30),0,I18<=-30,-1)} -> -1 | I18: =AF18 -> -219 | J18: =AI18+AJ18 -> 0 | K18: =IF(AZ18<=0,AZ18,AZ18/COUNTIFS(R:R,R18,AZ:AZ,">0")) -> 0 | L18: =AM18 -> 10.95 | M18: =AT18 -> 1.31 | O18: =SUM(I18:N18) -> -206.74 | R18: P770813889954234671 | S18: R5423467132482381 | T18: 2025-08-15 20:44:49 | U18: 2025-08-25 17:13:43 | V18: 2025-08-31 16:38:36 | W18: 退款 | X18: 店铺余额 | Y18: -206.74 | Z18: 【老板周】极简主义 秋冬 · 【老板周】极简主义 秋冬新款复古卷边前短后长针织上衣 黑色 S（80-100斤） | AA18: 女装/女士精品>毛针织衫 | AB18: XHS-3JY9LAG0S9OG | AC18: 689dee5baa1e7b00156ae7bc | AD18: 0 | AE18: -219 | AF18: -219 | AG18: 0 | AH18: 0 | AI18: 0 | AJ18: 0 | AK18: 0 | AL18: 0 | AM18: 10.95 | AN18: 0 | AO18: 0 | AP18: 0 | AQ18: 否 | AR18: 0 | AS18: 0 | AT18: 1.31 | AU18: 650d6e9f000000001603a6ac | AV18: 老板周. | AW18: 达人带货 | AZ18: 0 | BA18: 0 | BB18: 0 | BC18: 0 | BD18: 0
A19: =YEAR(V19) -> 2025 | B19: =MONTH(V19) -> 8 | C19: =R19 -> P770813889954234671 | D19: =COUNTIF(R:R,R19) -> 2 | E19: =COUNTIF($R$2:R19,R19) -> 2 | F19: {=INDEX(订单明细!BQ:BQ,MATCH(R19&AC19,订单明细!A:A&订单明细!O:O,0))} -> Z2365-黑色-S | G19: =LEFT(F19,FIND("-",F19)-1) -> Z2365 | H19: {=_xlfn.IFS(C19=0,"",I19>0,AD19,AND(I19<0,I19>-30),0,I19<=-30,-1)} -> 1 | I19: =AF19 -> 219 | J19: =AI19+AJ19 -> 0 | K19: =IF(AZ19<=0,AZ19,AZ19/COUNTIFS(R:R,R19,AZ:AZ,">0")) -> 0 | L19: =AM19 -> -10.95 | M19: =AT19 -> -1.31 | O19: =SUM(I19:N19) -> 206.74 | R19: P770813889954234671 | T19: 2025-08-15 20:44:49 | U19: 2025-08-27 16:20:07 | V19: 2025-08-31 16:38:36 | W19: 结算入账 | X19: 店铺余额 | Y19: 206.74 | Z19: 【老板周】极简主义 秋冬 · 【老板周】极简主义 秋冬新款复古卷边前短后长针织上衣 黑色 S（80-100斤） | AA19: 女装/女士精品>毛针织衫 | AB19: XHS-3JY9LAG0S9OG | AC19: 689dee5baa1e7b00156ae7bc | AD19: 1 | AE19: 219 | AF19: 219 | AH19: 0 | AI19: 0 | AJ19: 0 | AK19: 0.05 | AL19: 0 | AM19: -10.95 | AN19: 219 | AO19: 219 | AP19: 0 | AQ19: 否 | AR19: 0 | AS19: 0.006 | AT19: -1.31 | AU19: 650d6e9f000000001603a6ac | AV19: 老板周. | AW19: 达人带货 | AZ19: 0 | BA19: 0 | BB19: 0 | BC19: 0 | BD19: 0
A20: =YEAR(V20) -> 2025 | B20: =MONTH(V20) -> 8 | C20: =R20 -> P770794018206458841 | D20: =COUNTIF(R:R,R20) -> 2 | E20: =COUNTIF($R$2:R20,R20) -> 1 | F20: {=INDEX(订单明细!BQ:BQ,MATCH(R20&AC20,订单明细!A:A&订单明细!O:O,0))} -> Z2378-花纱色-M | G20: =LEFT(F20,FIND("-",F20)-1) -> Z2378 | H20: {=_xlfn.IFS(C20=0,"",I20>0,AD20,AND(I20<0,I20>-30),0,I20<=-30,-1)} -> -1 | I20: =AF20 -> -179 | J20: =AI20+AJ20 -> 0 | K20: =IF(AZ20<=0,AZ20,AZ20/COUNTIFS(R:R,R20,AZ:AZ,">0")) -> 0 | L20: =AM20 -> 8.95 | M20: =AT20 -> 1.07 | O20: =SUM(I20:N20) -> -168.98 | R20: P770794018206458841 | S20: R0645884157385706 | T20: 2025-08-15 15:13:38 | U20: 2025-08-24 10:56:35 | V20: 2025-08-31 16:28:41 | W20: 退款 | X20: 店铺余额 | Y20: -168.98 | Z20: 【老板周】小众日系 秋冬 · 【老板周】小众日系 秋冬叠穿时髦下摆不规则宽松马甲 花纱色 M（100-135斤） | AA20: 女装/女士精品>马夹 | AB20: XHS-3JY8RM360LQ8 | AC20: 689dee45c34eef00157e11fd | AD20: 0 | AE20: -179 | AF20: -179 | AG20: 0 | AH20: 0 | AI20: 0 | AJ20: 0 | AK20: 0 | AL20: 0 | AM20: 8.95 | AN20: 0 | AO20: 0 | AP20: 0 | AQ20: 否 | AR20: 0 | AS20: 0 | AT20: 1.07 | AU20: 650d6e9f000000001603a6ac | AV20: 老板周. | AW20: 达人带货 | AZ20: 0 | BA20: 0 | BB20: 0 | BC20: 0 | BD20: 0
A21: =YEAR(V21) -> 2025 | B21: =MONTH(V21) -> 8 | C21: =R21 -> P770794018206458841 | D21: =COUNTIF(R:R,R21) -> 2 | E21: =COUNTIF($R$2:R21,R21) -> 2 | F21: {=INDEX(订单明细!BQ:BQ,MATCH(R21&AC21,订单明细!A:A&订单明细!O:O,0))} -> Z2378-花纱色-M | G21: =LEFT(F21,FIND("-",F21)-1) -> Z2378 | H21: {=_xlfn.IFS(C21=0,"",I21>0,AD21,AND(I21<0,I21>-30),0,I21<=-30,-1)} -> 1 | I21: =AF21 -> 179 | J21: =AI21+AJ21 -> 0 | K21: =IF(AZ21<=0,AZ21,AZ21/COUNTIFS(R:R,R21,AZ:AZ,">0")) -> 0 | L21: =AM21 -> -8.95 | M21: =AT21 -> -1.07 | O21: =SUM(I21:N21) -> 168.98 | R21: P770794018206458841 | T21: 2025-08-15 15:13:38 | U21: 2025-08-27 16:18:15 | V21: 2025-08-31 16:28:41 | W21: 结算入账 | X21: 店铺余额 | Y21: 168.98 | Z21: 【老板周】小众日系 秋冬 · 【老板周】小众日系 秋冬叠穿时髦下摆不规则宽松马甲 花纱色 M（100-135斤） | AA21: 女装/女士精品>马夹 | AB21: XHS-3JY8RM360LQ8 | AC21: 689dee45c34eef00157e11fd | AD21: 1 | AE21: 179 | AF21: 179 | AH21: 0 | AI21: 0 | AJ21: 0 | AK21: 0.05 | AL21: 0 | AM21: -8.95 | AN21: 179 | AO21: 179 | AP21: 0 | AQ21: 否 | AR21: 0 | AS21: 0.006 | AT21: -1.07 | AU21: 650d6e9f000000001603a6ac | AV21: 老板周. | AW21: 达人带货 | AZ21: 0 | BA21: 0 | BB21: 0 | BC21: 0 | BD21: 0
